Workbook

Sheet README
B2: China's National Climate Targets Database (v1.0.0) | S2: CC BY 4.0
B3: This dataset compiles quantified climate-related targets set by the Chinese central government from 2004 through mid-2026, drawn from official policy documents and government website entries, and organized into distinct thematic areas. | R3: Author | S3: Florian Wengel
B4: In China, targets have a directive character in practice and serve as important guidance for government bodies. | S4: SOAS University of London
B5: Last update | C5: 46272 | Q5: Disclaimer: All errors are the author's. | S5: 705404@soas.ac.uk
B6: 2026-09-07: Unified percentage notation across the English version ("X percent" → "X%").
B7: 2026-09-07: Added 1 target from the Implementation Plan for Promoting Coordinated Digital and Green Transformation (2026-2030) (IP2604): renewable electricity consumption level in computing facilities and other key areas reaching the provincial renewable electricity consumption responsibility weight (2030).
B8: 2026-09-07: Simplified target category names by removing the "target" suffix (e.g. "Renewable energy target" → "Renewable energy"), in sync with the Chinese version.
B9: 2026-09-04: Per the inclusion criteria (directly reducing GHG emissions, indirectly promoting mitigation, or significantly affecting the emission pathway), 62 indicators without a direct climate link were screened and removed (travel convenience, security screening procedures, vehicle technical parameters, employment/revenue, biodiversity, etc.). 2026-09-04: Added 169 targets from 17 new 2026 policy documents (98 new targets, 63 reiterated targets, 8 strengthened or loosened targets), and added 26 policy documents to the Sources sheet.
B10: Source information
B11: Climate targets are extracted from Chinese climate strategies issued by various agencies of the Chinese central government. These text documents were found on government agencies' websites, the online encyclopaedia Baidu Baike, Chinese state-owned media outlets, or other websites.
B13: Climate target definition
B14: For the purpose of compiling this data set, we define climate targets in a broad sense as quantified commitments aimed at directly reducing GHG emissions, contributing indirectly to emission reduction, or significantly influencing GHG emission pathways.
B15: The dataset includes both hard targets and softer indicative targets.
B17: Scope & coverage
B18: This dataset only covers national level climate targets. It does not provide information on targets set at the subnational level. Targets are extracted from policy documents that were issued since 2004.
B19: The dataset was compiled to be as comprehensive as possible, yet some targets may not have been captured.
B21: Dataset structure
B22: Sheet | C22: Explanation
B23: Overview | C23: Summary statistics
B24: GHG Emissions | C24: All targets addressing greenhouse gas emissions, economy-wide or for specific sectors, systems or processes
B25: Energy|Power | C25: All targets related to energy supply (including targets related to coal power) and consumption
B26: Industry | C26: All targets related to the industrial sector, particularly carbon-intensive industrial processes
B27: Buildings | C27: All targets related to buildings and infrastructure
B28: Transport | C28: All targets related to transportation and logistics
B29: LULUCF | C29: All targets related to land use, agriculture and forestry
B30: Circular Economy | C30: All targets related to waste and water management and recycling
B31: Pollution | C31: All targets addressing air or water pollutants, economy-wide or for specific sectors, systems or processes
B32: Finance | C32: All targets related to the financing to achieve decarbonisation goals
B33: Sources | C33: Code identifying climate policy document used to source target data. Codes and the corresponding full titles of policy documents can be found in the 'Sources' sheet.
B35: Column Descriptions
B36: Announcement_Year | C36: The year in which the source document in which the target was found was officially released or published.
B37: Metric | C37: The core indicator the target is about (what is being measured).
B38: Direction | C38: The intended direction or type of change expressed by the target
B39: Target_Magnitude | C39: The target level or change magnitude (the numeric value together with its unit)
C40: The level or year from which progress toward the target is measured, if specified in the source document. This is the starting reference year for the change magnitude.
C41: The year or period in which the target is meant to be achieved.
C42: A code indicating whether the target is new, repeated, strengthened, or loosened:
C43: n = New target (appears for the first time)
C44: r = Repeated target (same target level and same target year appears in multiple policy documents)
C45: s/l = Strengthened or loosened target (same target year or period, but target level is made more or less ambitious)
...

Sheet Overview
B2: Descriptive Statistics
B4: Number of Targets by Sector/Topic | E4: Number of "Energy/Power" Targets by Subtopic | H4: Number of Targets by Count | K4: Number of Targets by Announcement Year | N4: Number of Targets by Target Year | Q4: Number of Targets by Category | T4: Targets by Accountability
B6: GHG Emissions | C6: =COUNTIFS('GHG Emissions'!G:G, "n") + COUNTIFS('GHG Emissions'!G:G, "s/l-UNC") + COUNTIFS('GHG Emissions'!G:G, "s/l-POS") + COUNTIFS('GHG Emissions'!G:G, "s/l-NEG") | E6: Energy consumption | F6: =COUNTIFS('Energy|Power'!M:M, "Energy consumption") | H6: New target | I6: =COUNTIF('GHG Emissions'!G:G,"n") +COUNTIF(Pollution!G:G,"n") +COUNTIF('Energy|Power'!G:G,"n") +COUNTIF(Industry!G:G,"n") +COUNTIF(Buildings!G:G,"n") +COUNTIF(Transport!G:G,"n") +COUNTIF(LULUCF!G:G,"n") +COUNTIF('Circular Economy'!G:G,"n") +COUNTIF(Finance!G:G,"n") | K6: 2004 | L6: =COUNTIFS('GHG Emissions'!A:A, 2004, 'GHG Emissions'!G:G, "n") + COUNTIFS('GHG Emissions'!A:A, 2004, 'GHG Emissions'!G:G, "s/l-UNC") + COUNTIFS('GHG Emissions'!A:A, 2004, 'GHG Emissions'!G:G, "s/l-POS") + COUNTIFS('GHG Emissions'!A:A, 2004, 'GHG Emissions'!G:G, "s/l-NEG") + COUNTIFS(Pollution!A:A, 2004, Pollution!G:G, "n") + COUNTIFS(Pollution!A:A, 2004, Pollution!G:G, "s/l-UNC") + COUNTIFS(Pollution!A:A, 2004, Pollution!G:G, "s/l-POS") + COUNTIFS(Pollution!A:A, 2004, Pollution!G:G, "s/l-NEG") + COUNTIFS('Energy|Power'!A:A, 2004, 'Energy|Power'!G:G, "n") + COUNTIFS('Energy|Power'!A:A, 2004, 'Energy|Power'!G:G, "s/l-UNC") + COUNTIFS('Energy|Power'!A:A, 2004, 'Energy|Power'!G:G, "s/l-POS") + COUNTIFS('Energy|Power'!A:A, 2004, 'Energy|Power'!G:G, "s/l-NEG") + COUNTIFS(Industry!A:A, 2004, Industry!G:G, "n") + COUNTIFS(Industry!A:A, 2004, Industry!G:G, "s/l-UNC") + COUNTIFS(Industry!A:A, 2004, Industry!G:G, "s/l-POS") + COUNTIFS(Industry!A:A, 2004, Industry!G:G, "s/l-NEG") + COUNTIFS(Buildings!A:A, 2004, Buildings!G:G, "n") + COUNTIFS(Buildings!A:A, 2004, Buildings!G:G, "s/l-UNC") + COUNTIFS(Buildings!A:A, 2004, Buildings!G:G, "s/l-POS") + COUNTIFS(Buildings!A:A, 2004, Buildings!G:G, "s/l-NEG") + COUNTIFS(Transport!A:A, 2004, Transport!G:G, "n") + COUNTIFS(Transport!A:A, 2004, Transport!G:G, "s/l-UNC") + COUNTIFS(Transport!A:A, 2004, Transport!G:G, "s/l-POS") + COUNTIFS(Transport!A:A, 2004, Transport!G:G, "s/l-NEG") + COUNTIFS(LULUCF!A:A, 2004, LULUCF!G:G, "n") + COUNTIFS(LULUCF!A:A, 2004, LULUCF!G:G, "s/l-UNC") + COUNTIFS(LULUCF!A:A, 2004, LULUCF!G:G, "s/l-POS") + COUNTIFS(LULUCF!A:A, 2004, LULUCF!G:G, "s/l-NEG") + COUNTIFS('Circular Economy'!A:A, 2004, 'Circular Economy'!G:G, "n") + COUNTIFS('Circular Economy'!A:A, 2004, 'Circular Economy'!G:G, "s/l-UNC") + COUNTIFS('Circular Economy'!A:A, 2004, 'Circular Economy'!G:G, "s/l-POS") + COUNTIFS('Circular Economy'!A:A, 2004, 'Circular Economy'!G:G, "s/l-NEG") + COUNTIFS(Finance!A:A, 2004, Finance!G:G, "n") + COUNTIFS(Finance!A:A, 2004, Finance!G:G, "s/l-UNC") + COUNTIFS(Finance!A:A, 2004, Finance!G:G, "s/l-POS") + COUNTIFS(Finance!A:A, 2004, Finance!G:G, "s/l-NEG") | N6: 2007 | O6: =COUNTIFS('GHG Emissions'!F:F, 2007, 'GHG Emissions'!G:G, "n") + COUNTIFS('GHG Emissions'!F:F, 2007, 'GHG Emissions'!G:G, "s/l-UNC") + COUNTIFS('GHG Emissions'!F:F, 2007, 'GHG Emissions'!G:G, "s/l-POS") + COUNTIFS('GHG Emissions'!F:F, 2007, 'GHG Emissions'!G:G, "s/l-NEG") + COUNTIFS(Pollution!F:F, 2007, Pollution!G:G, "n") + COUNTIFS(Pollution!F:F, 2007, Pollution!G:G, "s/l-UNC") + COUNTIFS(Pollution!F:F, 2007, Pollution!G:G, "s/l-POS") + COUNTIFS(Pollution!F:F, 2007, Pollution!G:G, "s/l-NEG") + COUNTIFS('Energy|Power'!F:F, 2007, 'Energy|Power'!G:G, "n") + COUNTIFS('Energy|Power'!F:F, 2007, 'Energy|Power'!G:G, "s/l-UNC") + COUNTIFS('Energy|Power'!F:F, 2007, 'Energy|Power'!G:G, "s/l-POS") + COUNTIFS('Energy|Power'!F:F, 2007, 'Energy|Power'!G:G, "s/l-NEG") + COUNTIFS(Industry!F:F, 2007, Industry!G:G, "n") + COUNTIFS(Industry!F:F, 2007, Industry!G:G, "s/l-UNC") + COUNTIFS(Industry!F:F, 2007, Industry!G:G, "s/l-POS") + COUNTIFS(Industry!F:F, 2007, Industry!G:G, "s/l-NEG") + COUNTIFS(Buildings!F:F, 2007, Buildings!G:G, "n") + COUNTIFS(Buildings!F:F, 2007, Buildings!G:G, "s/l-UNC") + COUNTIFS(Buildings!F:F, 2007, Buildings!G:G, "s/l-POS") + COUNTIFS(Buildings!F:F, 2007, Buildings!G:G, "s/l-NEG") + COUNTIFS(Transport!F:F, 2007, Transport!G:G, "n") + COUNTIFS(Transport!F:F, 2007, Transport!G:G, "s/l-UNC") + COUNTIFS(Transport!F:F, 2007, Transport!G:G, "s/l-POS") + COUNTIFS(Transport!F:F, 2007, Transport!G:G, "s/l-NEG") + COUNTIFS(LULUCF!F:F, 2007, LULUCF!G:G, "n") + COUNTIFS(LULUCF!F:F, 2007, LULUCF!G:G, "s/l-UNC") + COUNTIFS(LULUCF!F:F, 2007, LULUCF!G:G, "s/l-POS") + COUNTIFS(LULUCF!F:F, 2007, LULUCF!G:G, "s/l-NEG") + COUNTIFS('Circular Economy'!F:F, 2007, 'Circular Economy'!G:G, "n") + COUNTIFS('Circular Economy'!F:F, 2007, 'Circular Economy'!G:G, "s/l-UNC") + COUNTIFS('Circular Economy'!F:F, 2007, 'Circular Economy'!G:G, "s/l-POS") + COUNTIFS('Circular Economy'!F:F, 2007, 'Circular Economy'!G:G, "s/l-NEG") + COUNTIFS(Finance!F:F, 2007, Finance!G:G, "n") + COUNTIFS(Finance!F:F, 2007, Finance!G:G, "s/l-UNC") + COUNTIFS(Finance!F:F, 2007, Finance!G:G, "s/l-POS") + COUNTIFS(Finance!F:F, 2007, Finance!G:G, "s/l-NEG") | Q6: Carbon reduction | R6: =COUNTIFS('GHG Emissions'!H:H, "Carbon reduction", 'GHG Emissions'!G:G, "n") + COUNTIFS('GHG Emissions'!H:H, "Carbon reduction", 'GHG Emissions'!G:G, "s/l-UNC") + COUNTIFS('GHG Emissions'!H:H, "Carbon reduction", 'GHG Emissions'!G:G, "s/l-POS") + COUNTIFS('GHG Emissions'!H:H, "Carbon reduction", 'GHG Emissions'!G:G, "s/l-NEG") + COUNTIFS(Pollution!H:H, "Carbon reduction", Pollution!G:G, "n") + COUNTIFS(Pollution!H:H, "Carbon reduction", Pollution!G:G, "s/l-UNC") + COUNTIFS(Pollution!H:H, "Carbon reduction", Pollution!G:G, "s/l-POS") + COUNTIFS(Pollution!H:H, "Carbon reduction", Pollution!G:G, "s/l-NEG") + COUNTIFS('Energy|Power'!H:H, "Carbon reduction", 'Energy|Power'!G:G, "n") + COUNTIFS('Energy|Power'!H:H, "Carbon reduction", 'Energy|Power'!G:G, "s/l-UNC") + COUNTIFS('Energy|Power'!H:H, "Carbon reduction", 'Energy|Power'!G:G, "s/l-POS") + COUNTIFS('Energy|Power'!H:H, "Carbon reduction", 'Energy|Power'!G:G, "s/l-NEG") + COUNTIFS(Industry!H:H, "Carbon reduction", Industry!G:G, "n") + COUNTIFS(Industry!H:H, "Carbon reduction", Industry!G:G, "s/l-UNC") + COUNTIFS(Industry!H:H, "Carbon reduction", Industry!G:G, "s/l-POS") + COUNTIFS(Industry!H:H, "Carbon reduction", Industry!G:G, "s/l-NEG") + COUNTIFS(Buildings!H:H, "Carbon reduction", Buildings!G:G, "n") + COUNTIFS(Buildings!H:H, "Carbon reduction", Buildings!G:G, "s/l-UNC") + COUNTIFS(Buildings!H:H, "Carbon reduction", Buildings!G:G, "s/l-POS") + COUNTIFS(Buildings!H:H, "Carbon reduction", Buildings!G:G, "s/l-NEG") + COUNTIFS(Transport!H:H, "Carbon reduction", Transport!G:G, "n") + COUNTIFS(Transport!H:H, "Carbon reduction", Transport!G:G, "s/l-UNC") + COUNTIFS(Transport!H:H, "Carbon reduction", Transport!G:G, "s/l-POS") + COUNTIFS(Transport!H:H, "Carbon reduction", Transport!G:G, "s/l-NEG") + COUNTIFS(LULUCF!H:H, "Carbon reduction", LULUCF!G:G, "n") + COUNTIFS(LULUCF!H:H, "Carbon reduction", LULUCF!G:G, "s/l-UNC") + COUNTIFS(LULUCF!H:H, "Carbon reduction", LULUCF!G:G, "s/l-POS") + COUNTIFS(LULUCF!H:H, "Carbon reduction", LULUCF!G:G, "s/l-NEG") + COUNTIFS('Circular Economy'!H:H, "Carbon reduction", 'Circular Economy'!G:G, "n") + COUNTIFS('Circular Economy'!H:H, "Carbon reduction", 'Circular Economy'!G:G, "s/l-UNC") + COUNTIFS('Circular Economy'!H:H, "Carbon reduction", 'Circular Economy'!G:G, "s/l-POS") + COUNTIFS('Circular Economy'!H:H, "Carbon reduction", 'Circular Economy'!G:G, "s/l-NEG") + COUNTIFS(Finance!H:H, "Carbon reduction", Finance!G:G, "n") + COUNTIFS(Finance!H:H, "Carbon reduction", Finance!G:G, "s/l-UNC") + COUNTIFS(Finance!H:H, "Carbon reduction", Finance!G:G, "s/l-POS") + COUNTIFS(Finance!H:H, "Carbon reduction", Finance!G:G, "s/l-NEG") | T6: Enterprises & institutions | U6: =COUNTIFS('GHG Emissions'!I:I,"enterprises",'GHG Emissions'!G:G,"n") +COUNTIFS('GHG Emissions'!I:I,"enterprises",'GHG Emissions'!G:G,"s/l-UNC") +COUNTIFS('GHG Emissions'!I:I,"enterprises",'GHG Emissions'!G:G,"s/l-POS") +COUNTIFS('GHG Emissions'!I:I,"enterprises",'GHG Emissions'!G:G,"s/l-NEG") +COUNTIFS(Pollution!I:I,"enterprises",Pollution!G:G,"n") +COUNTIFS(Pollution!I:I,"enterprises",Pollution!G:G,"s/l-UNC") +COUNTIFS(Pollution!I:I,"enterprises",Pollution!G:G,"s/l-POS") +COUNTIFS(Pollution!I:I,"enterprises",Pollution!G:G,"s/l-NEG") +COUNTIFS('Energy|Power'!I:I,"enterprises",'Energy|Power'!G:G,"n") +COUNTIFS('Energy|Power'!I:I,"enterprises",'Energy|Power'!G:G,"s/l-UNC") +COUNTIFS('Energy|Power'!I:I,"enterprises",'Energy|Power'!G:G,"s/l-POS") +COUNTIFS('Energy|Power'!I:I,"enterprises",'Energy|Power'!G:G,"s/l-NEG") +COUNTIFS(Industry!I:I,"enterprises",Industry!G:G,"n") +COUNTIFS(Industry!I:I,"enterprises",Industry!G:G,"s/l-UNC") +COUNTIFS(Industry!I:I,"enterprises",Industry!G:G,"s/l-POS") +COUNTIFS(Industry!I:I,"enterprises",Industry!G:G,"s/l-NEG") +COUNTIFS(Buildings!I:I,"enterprises",Buildings!G:G,"n") +COUNTIFS(Buildings!I:I,"enterprises",Buildings!G:G,"s/l-UNC") +COUNTIFS(Buildings!I:I,"enterprises",Buildings!G:G,"s/l-POS") +COUNTIFS(Buildings!I:I,"enterprises",Buildings!G:G,"s/l-NEG") +COUNTIFS(Transport!I:I,"enterprises",Transport!G:G,"n") +COUNTIFS(Transport!I:I,"enterprises",Transport!G:G,"s/l-UNC") +COUNTIFS(Transport!I:I,"enterprises",Transport!G:G,"s/l-POS") +COUNTIFS(Transport!I:I,"enterprises",Transport!G:G,"s/l-NEG") +COUNTIFS(LULUCF!I:I,"enterprises",LULUCF!G:G,"n") +COUNTIFS(LULUCF!I:I,"enterprises",LULUCF!G:G,"s/l-UNC") +COUNTIFS(LULUCF!I:I,"enterprises",LULUCF!G:G,"s/l-POS") +COUNTIFS(LULUCF!I:I,"enterprises",LULUCF!G:G,"s/l-NEG") +COUNTIFS('Circular Economy'!I:I,"enterprises",'Circular Economy'!G:G,"n") +COUNTIFS('Circular Economy'!I:I,"enterprises",'Circular Economy'!G:G,"s/l-UNC") +COUNTIFS('Circular Economy'!I:I,"enterprises",'Circular Economy'!G:G,"s/l-POS") +COUNTIFS('Circular Economy'!I:I,"enterprises",'Circular Economy'!G:G,"s/l-NEG") +COUNTIFS(Finance!I:I,"enterprises",Finance!G:G,"n") +COUNTIFS(Finance!I:I,"enterprises",Finance!G:G,"s/l-UNC") +COUNTIFS(Finance!I:I,"enterprises",Finance!G:G,"s/l-POS") +COUNTIFS(Finance!I:I,"enterprises",Finance!G:G,"s/l-NEG")
B7: Pollution | C7: =COUNTIFS(Pollution!G:G, "n") + COUNTIFS(Pollution!G:G, "s/l-UNC") + COUNTIFS(Pollution!G:G, "s/l-POS") + COUNTIFS(Pollution!G:G, "s/l-NEG") | E7: Power supply | F7: =COUNTIFS('Energy|Power'!M:M, "Power supply") | H7: Strengthened or loosened target with unclear climate impact | I7: =COUNTIF('GHG Emissions'!G:G,"s/l-UNC") +COUNTIF(Pollution!G:G,"s/l-UNC") +COUNTIF('Energy|Power'!G:G,"s/l-UNC") +COUNTIF(Industry!G:G,"s/l-UNC") +COUNTIF(Buildings!G:G,"s/l-UNC") +COUNTIF(Transport!G:G,"s/l-UNC") +COUNTIF(LULUCF!G:G,"s/l-UNC") +COUNTIF('Circular Economy'!G:G,"s/l-UNC") +COUNTIF(Finance!G:G,"s/l-UNC") | K7: 2005 | L7: =COUNTIFS('GHG Emissions'!A:A, 2005, 'GHG Emissions'!G:G, "n") + COUNTIFS('GHG Emissions'!A:A, 2005, 'GHG Emissions'!G:G, "s/l-UNC") + COUNTIFS('GHG Emissions'!A:A, 2005, 'GHG Emissions'!G:G, "s/l-POS") + COUNTIFS('GHG Emissions'!A:A, 2005, 'GHG Emissions'!G:G, "s/l-NEG") + COUNTIFS(Pollution!A:A, 2005, Pollution!G:G, "n") + COUNTIFS(Pollution!A:A, 2005, Pollution!G:G, "s/l-UNC") + COUNTIFS(Pollution!A:A, 2005, Pollution!G:G, "s/l-POS") + COUNTIFS(Pollution!A:A, 2005, Pollution!G:G, "s/l-NEG") + COUNTIFS('Energy|Power'!A:A, 2005, 'Energy|Power'!G:G, "n") + COUNTIFS('Energy|Power'!A:A, 2005, 'Energy|Power'!G:G, "s/l-UNC") + COUNTIFS('Energy|Power'!A:A, 2005, 'Energy|Power'!G:G, "s/l-POS") + COUNTIFS('Energy|Power'!A:A, 2005, 'Energy|Power'!G:G, "s/l-NEG") + COUNTIFS(Industry!A:A, 2005, Industry!G:G, "n") + COUNTIFS(Industry!A:A, 2005, Industry!G:G, "s/l-UNC") + COUNTIFS(Industry!A:A, 2005, Industry!G:G, "s/l-POS") + COUNTIFS(Industry!A:A, 2005, Industry!G:G, "s/l-NEG") + COUNTIFS(Buildings!A:A, 2005, Buildings!G:G, "n") + COUNTIFS(Buildings!A:A, 2005, Buildings!G:G, "s/l-UNC") + COUNTIFS(Buildings!A:A, 2005, Buildings!G:G, "s/l-POS") + COUNTIFS(Buildings!A:A, 2005, Buildings!G:G, "s/l-NEG") + COUNTIFS(Transport!A:A, 2005, Transport!G:G, "n") + COUNTIFS(Transport!A:A, 2005, Transport!G:G, "s/l-UNC") + COUNTIFS(Transport!A:A, 2005, Transport!G:G, "s/l-POS") + COUNTIFS(Transport!A:A, 2005, Transport!G:G, "s/l-NEG") + COUNTIFS(LULUCF!A:A, 2005, LULUCF!G:G, "n") + COUNTIFS(LULUCF!A:A, 2005, LULUCF!G:G, "s/l-UNC") + COUNTIFS(LULUCF!A:A, 2005, LULUCF!G:G, "s/l-POS") + COUNTIFS(LULUCF!A:A, 2005, LULUCF!G:G, "s/l-NEG") + COUNTIFS('Circular Economy'!A:A, 2005, 'Circular Economy'!G:G, "n") + COUNTIFS('Circular Economy'!A:A, 2005, 'Circular Economy'!G:G, "s/l-UNC") + COUNTIFS('Circular Economy'!A:A, 2005, 'Circular Economy'!G:G, "s/l-POS") + COUNTIFS('Circular Economy'!A:A, 2005, 'Circular Economy'!G:G, "s/l-NEG") + COUNTIFS(Finance!A:A, 2005, Finance!G:G, "n") + COUNTIFS(Finance!A:A, 2005, Finance!G:G, "s/l-UNC") + COUNTIFS(Finance!A:A, 2005, Finance!G:G, "s/l-POS") + COUNTIFS(Finance!A:A, 2005, Finance!G:G, "s/l-NEG") | N7: 2008 | O7: =COUNTIFS('GHG Emissions'!F:F, 2008, 'GHG Emissions'!G:G, "n") + COUNTIFS('GHG Emissions'!F:F, 2008, 'GHG Emissions'!G:G, "s/l-UNC") + COUNTIFS('GHG Emissions'!F:F, 2008, 'GHG Emissions'!G:G, "s/l-POS") + COUNTIFS('GHG Emissions'!F:F, 2008, 'GHG Emissions'!G:G, "s/l-NEG") + COUNTIFS(Pollution!F:F, 2008, Pollution!G:G, "n") + COUNTIFS(Pollution!F:F, 2008, Pollution!G:G, "s/l-UNC") + COUNTIFS(Pollution!F:F, 2008, Pollution!G:G, "s/l-POS") + COUNTIFS(Pollution!F:F, 2008, Pollution!G:G, "s/l-NEG") + COUNTIFS('Energy|Power'!F:F, 2008, 'Energy|Power'!G:G, "n") + COUNTIFS('Energy|Power'!F:F, 2008, 'Energy|Power'!G:G, "s/l-UNC") + COUNTIFS('Energy|Power'!F:F, 2008, 'Energy|Power'!G:G, "s/l-POS") + COUNTIFS('Energy|Power'!F:F, 2008, 'Energy|Power'!G:G, "s/l-NEG") + COUNTIFS(Industry!F:F, 2008, Industry!G:G, "n") + COUNTIFS(Industry!F:F, 2008, Industry!G:G, "s/l-UNC") + COUNTIFS(Industry!F:F, 2008, Industry!G:G, "s/l-POS") + COUNTIFS(Industry!F:F, 2008, Industry!G:G, "s/l-NEG") + COUNTIFS(Buildings!F:F, 2008, Buildings!G:G, "n") + COUNTIFS(Buildings!F:F, 2008, Buildings!G:G, "s/l-UNC") + COUNTIFS(Buildings!F:F, 2008, Buildings!G:G, "s/l-POS") + COUNTIFS(Buildings!F:F, 2008, Buildings!G:G, "s/l-NEG") + COUNTIFS(Transport!F:F, 2008, Transport!G:G, "n") + COUNTIFS(Transport!F:F, 2008, Transport!G:G, "s/l-UNC") + COUNTIFS(Transport!F:F, 2008, Transport!G:G, "s/l-POS") + COUNTIFS(Transport!F:F, 2008, Transport!G:G, "s/l-NEG") + COUNTIFS(LULUCF!F:F, 2008, LULUCF!G:G, "n") + COUNTIFS(LULUCF!F:F, 2008, LULUCF!G:G, "s/l-UNC") + COUNTIFS(LULUCF!F:F, 2008, LULUCF!G:G, "s/l-POS") + COUNTIFS(LULUCF!F:F, 2008, LULUCF!G:G, "s/l-NEG") + COUNTIFS('Circular Economy'!F:F, 2008, 'Circular Economy'!G:G, "n") + COUNTIFS('Circular Economy'!F:F, 2008, 'Circular Economy'!G:G, "s/l-UNC") + COUNTIFS('Circular Economy'!F:F, 2008, 'Circular Economy'!G:G, "s/l-POS") + COUNTIFS('Circular Economy'!F:F, 2008, 'Circular Economy'!G:G, "s/l-NEG") + COUNTIFS(Finance!F:F, 2008, Finance!G:G, "n") + COUNTIFS(Finance!F:F, 2008, Finance!G:G, "s/l-UNC") + COUNTIFS(Finance!F:F, 2008, Finance!G:G, "s/l-POS") + COUNTIFS(Finance!F:F, 2008, Finance!G:G, "s/l-NEG") | Q7: Carbon intensity | R7: =COUNTIFS('GHG Emissions'!H:H, "Carbon intensity", 'GHG Emissions'!G:G, "n") + COUNTIFS('GHG Emissions'!H:H, "Carbon intensity", 'GHG Emissions'!G:G, "s/l-UNC") + COUNTIFS('GHG Emissions'!H:H, "Carbon intensity", 'GHG Emissions'!G:G, "s/l-POS") + COUNTIFS('GHG Emissions'!H:H, "Carbon intensity", 'GHG Emissions'!G:G, "s/l-NEG") + COUNTIFS(Pollution!H:H, "Carbon intensity", Pollution!G:G, "n") + COUNTIFS(Pollution!H:H, "Carbon intensity", Pollution!G:G, "s/l-UNC") + COUNTIFS(Pollution!H:H, "Carbon intensity", Pollution!G:G, "s/l-POS") + COUNTIFS(Pollution!H:H, "Carbon intensity", Pollution!G:G, "s/l-NEG") + COUNTIFS('Energy|Power'!H:H, "Carbon intensity", 'Energy|Power'!G:G, "n") + COUNTIFS('Energy|Power'!H:H, "Carbon intensity", 'Energy|Power'!G:G, "s/l-UNC") + COUNTIFS('Energy|Power'!H:H, "Carbon intensity", 'Energy|Power'!G:G, "s/l-POS") + COUNTIFS('Energy|Power'!H:H, "Carbon intensity", 'Energy|Power'!G:G, "s/l-NEG") + COUNTIFS(Industry!H:H, "Carbon intensity", Industry!G:G, "n") + COUNTIFS(Industry!H:H, "Carbon intensity", Industry!G:G, "s/l-UNC") + COUNTIFS(Industry!H:H, "Carbon intensity", Industry!G:G, "s/l-POS") + COUNTIFS(Industry!H:H, "Carbon intensity", Industry!G:G, "s/l-NEG") + COUNTIFS(Buildings!H:H, "Carbon intensity", Buildings!G:G, "n") + COUNTIFS(Buildings!H:H, "Carbon intensity", Buildings!G:G, "s/l-UNC") + COUNTIFS(Buildings!H:H, "Carbon intensity", Buildings!G:G, "s/l-POS") + COUNTIFS(Buildings!H:H, "Carbon intensity", Buildings!G:G, "s/l-NEG") + COUNTIFS(Transport!H:H, "Carbon intensity", Transport!G:G, "n") + COUNTIFS(Transport!H:H, "Carbon intensity", Transport!G:G, "s/l-UNC") + COUNTIFS(Transport!H:H, "Carbon intensity", Transport!G:G, "s/l-POS") + COUNTIFS(Transport!H:H, "Carbon intensity", Transport!G:G, "s/l-NEG") + COUNTIFS(LULUCF!H:H, "Carbon intensity", LULUCF!G:G, "n") + COUNTIFS(LULUCF!H:H, "Carbon intensity", LULUCF!G:G, "s/l-UNC") + COUNTIFS(LULUCF!H:H, "Carbon intensity", LULUCF!G:G, "s/l-POS") + COUNTIFS(LULUCF!H:H, "Carbon intensity", LULUCF!G:G, "s/l-NEG") + COUNTIFS('Circular Economy'!H:H, "Carbon intensity", 'Circular Economy'!G:G, "n") + COUNTIFS('Circular Economy'!H:H, "Carbon intensity", 'Circular Economy'!G:G, "s/l-UNC") + COUNTIFS('Circular Economy'!H:H, "Carbon intensity", 'Circular Economy'!G:G, "s/l-POS") + COUNTIFS('Circular Economy'!H:H, "Carbon intensity", 'Circular Economy'!G:G, "s/l-NEG") + COUNTIFS(Finance!H:H, "Carbon intensity", Finance!G:G, "n") + COUNTIFS(Finance!H:H, "Carbon intensity", Finance!G:G, "s/l-UNC") + COUNTIFS(Finance!H:H, "Carbon intensity", Finance!G:G, "s/l-POS") + COUNTIFS(Finance!H:H, "Carbon intensity", Finance!G:G, "s/l-NEG") | T7: Cities & areas | U7: =COUNTIFS('GHG Emissions'!I:I,"areas",'GHG Emissions'!G:G,"n") +COUNTIFS('GHG Emissions'!I:I,"areas",'GHG Emissions'!G:G,"s/l-UNC") +COUNTIFS('GHG Emissions'!I:I,"areas",'GHG Emissions'!G:G,"s/l-POS") +COUNTIFS('GHG Emissions'!I:I,"areas",'GHG Emissions'!G:G,"s/l-NEG") +COUNTIFS(Pollution!I:I,"areas",Pollution!G:G,"n") +COUNTIFS(Pollution!I:I,"areas",Pollution!G:G,"s/l-UNC") +COUNTIFS(Pollution!I:I,"areas",Pollution!G:G,"s/l-POS") +COUNTIFS(Pollution!I:I,"areas",Pollution!G:G,"s/l-NEG") +COUNTIFS('Energy|Power'!I:I,"areas",'Energy|Power'!G:G,"n") +COUNTIFS('Energy|Power'!I:I,"areas",'Energy|Power'!G:G,"s/l-UNC") +COUNTIFS('Energy|Power'!I:I,"areas",'Energy|Power'!G:G,"s/l-POS") +COUNTIFS('Energy|Power'!I:I,"areas",'Energy|Power'!G:G,"s/l-NEG") +COUNTIFS(Industry!I:I,"areas",Industry!G:G,"n") +COUNTIFS(Industry!I:I,"areas",Industry!G:G,"s/l-UNC") +COUNTIFS(Industry!I:I,"areas",Industry!G:G,"s/l-POS") +COUNTIFS(Industry!I:I,"areas",Industry!G:G,"s/l-NEG") +COUNTIFS(Buildings!I:I,"areas",Buildings!G:G,"n") +COUNTIFS(Buildings!I:I,"areas",Buildings!G:G,"s/l-UNC") +COUNTIFS(Buildings!I:I,"areas",Buildings!G:G,"s/l-POS") +COUNTIFS(Buildings!I:I,"areas",Buildings!G:G,"s/l-NEG") +COUNTIFS(Transport!I:I,"areas",Transport!G:G,"n") +COUNTIFS(Transport!I:I,"areas",Transport!G:G,"s/l-UNC") +COUNTIFS(Transport!I:I,"areas",Transport!G:G,"s/l-POS") +COUNTIFS(Transport!I:I,"areas",Transport!G:G,"s/l-NEG") +COUNTIFS(LULUCF!I:I,"areas",LULUCF!G:G,"n") +COUNTIFS(LULUCF!I:I,"areas",LULUCF!G:G,"s/l-UNC") +COUNTIFS(LULUCF!I:I,"areas",LULUCF!G:G,"s/l-POS") +COUNTIFS(LULUCF!I:I,"areas",LULUCF!G:G,"s/l-NEG") +COUNTIFS('Circular Economy'!I:I,"areas",'Circular Economy'!G:G,"n") +COUNTIFS('Circular Economy'!I:I,"areas",'Circular Economy'!G:G,"s/l-UNC") +COUNTIFS('Circular Economy'!I:I,"areas",'Circular Economy'!G:G,"s/l-POS") +COUNTIFS('Circular Economy'!I:I,"areas",'Circular Economy'!G:G,"s/l-NEG") +COUNTIFS(Finance!I:I,"areas",Finance!G:G,"n") +COUNTIFS(Finance!I:I,"areas",Finance!G:G,"s/l-UNC") +COUNTIFS(Finance!I:I,"areas",Finance!G:G,"s/l-POS") +COUNTIFS(Finance!I:I,"areas",Finance!G:G,"s/l-NEG")
B8: Energy/Power | C8: =COUNTIFS('Energy|Power'!G:G, "n") + COUNTIFS('Energy|Power'!G:G, "s/l-UNC") + COUNTIFS('Energy|Power'!G:G, "s/l-POS") + COUNTIFS('Energy|Power'!G:G, "s/l-NEG") | E8: Power transmission/Energy transportation | F8: =COUNTIFS('Energy|Power'!M:M, "Power transmission/Energy transportation") | H8: Strengthened or loosened target with positive climate impact | I8: =COUNTIF('GHG Emissions'!G:G,"s/l-POS") +COUNTIF(Pollution!G:G,"s/l-POS") +COUNTIF('Energy|Power'!G:G,"s/l-POS") +COUNTIF(Industry!G:G,"s/l-POS") +COUNTIF(Buildings!G:G,"s/l-POS") +COUNTIF(Transport!G:G,"s/l-POS") +COUNTIF(LULUCF!G:G,"s/l-POS") +COUNTIF('Circular Economy'!G:G,"s/l-POS") +COUNTIF(Finance!G:G,"s/l-POS") | K8: 2006 | L8: =COUNTIFS('GHG Emissions'!A:A, 2006, 'GHG Emissions'!G:G, "n") + COUNTIFS('GHG Emissions'!A:A, 2006, 'GHG Emissions'!G:G, "s/l-UNC") + COUNTIFS('GHG Emissions'!A:A, 2006, 'GHG Emissions'!G:G, "s/l-POS") + COUNTIFS('GHG Emissions'!A:A, 2006, 'GHG Emissions'!G:G, "s/l-NEG") + COUNTIFS(Pollution!A:A, 2006, Pollution!G:G, "n") + COUNTIFS(Pollution!A:A, 2006, Pollution!G:G, "s/l-UNC") + COUNTIFS(Pollution!A:A, 2006, Pollution!G:G, "s/l-POS") + COUNTIFS(Pollution!A:A, 2006, Pollution!G:G, "s/l-NEG") + COUNTIFS('Energy|Power'!A:A, 2006, 'Energy|Power'!G:G, "n") + COUNTIFS('Energy|Power'!A:A, 2006, 'Energy|Power'!G:G, "s/l-UNC") + COUNTIFS('Energy|Power'!A:A, 2006, 'Energy|Power'!G:G, "s/l-POS") + COUNTIFS('Energy|Power'!A:A, 2006, 'Energy|Power'!G:G, "s/l-NEG") + COUNTIFS(Industry!A:A, 2006, Industry!G:G, "n") + COUNTIFS(Industry!A:A, 2006, Industry!G:G, "s/l-UNC") + COUNTIFS(Industry!A:A, 2006, Industry!G:G, "s/l-POS") + COUNTIFS(Industry!A:A, 2006, Industry!G:G, "s/l-NEG") + COUNTIFS(Buildings!A:A, 2006, Buildings!G:G, "n") + COUNTIFS(Buildings!A:A, 2006, Buildings!G:G, "s/l-UNC") + COUNTIFS(Buildings!A:A, 2006, Buildings!G:G, "s/l-POS") + COUNTIFS(Buildings!A:A, 2006, Buildings!G:G, "s/l-NEG") + COUNTIFS(Transport!A:A, 2006, Transport!G:G, "n") + COUNTIFS(Transport!A:A, 2006, Transport!G:G, "s/l-UNC") + COUNTIFS(Transport!A:A, 2006, Transport!G:G, "s/l-POS") + COUNTIFS(Transport!A:A, 2006, Transport!G:G, "s/l-NEG") + COUNTIFS(LULUCF!A:A, 2006, LULUCF!G:G, "n") + COUNTIFS(LULUCF!A:A, 2006, LULUCF!G:G, "s/l-UNC") + COUNTIFS(LULUCF!A:A, 2006, LULUCF!G:G, "s/l-POS") + COUNTIFS(LULUCF!A:A, 2006, LULUCF!G:G, "s/l-NEG") + COUNTIFS('Circular Economy'!A:A, 2006, 'Circular Economy'!G:G, "n") + COUNTIFS('Circular Economy'!A:A, 2006, 'Circular Economy'!G:G, "s/l-UNC") + COUNTIFS('Circular Economy'!A:A, 2006, 'Circular Economy'!G:G, "s/l-POS") + COUNTIFS('Circular Economy'!A:A, 2006, 'Circular Economy'!G:G, "s/l-NEG") + COUNTIFS(Finance!A:A, 2006, Finance!G:G, "n") + COUNTIFS(Finance!A:A, 2006, Finance!G:G, "s/l-UNC") + COUNTIFS(Finance!A:A, 2006, Finance!G:G, "s/l-POS") + COUNTIFS(Finance!A:A, 2006, Finance!G:G, "s/l-NEG") | N8: 2010 | O8: =COUNTIFS('GHG Emissions'!F:F, 2010, 'GHG Emissions'!G:G, "n") + COUNTIFS('GHG Emissions'!F:F, 2010, 'GHG Emissions'!G:G, "s/l-UNC") + COUNTIFS('GHG Emissions'!F:F, 2010, 'GHG Emissions'!G:G, "s/l-POS") + COUNTIFS('GHG Emissions'!F:F, 2010, 'GHG Emissions'!G:G, "s/l-NEG") + COUNTIFS(Pollution!F:F, 2010, Pollution!G:G, "n") + COUNTIFS(Pollution!F:F, 2010, Pollution!G:G, "s/l-UNC") + COUNTIFS(Pollution!F:F, 2010, Pollution!G:G, "s/l-POS") + COUNTIFS(Pollution!F:F, 2010, Pollution!G:G, "s/l-NEG") + COUNTIFS('Energy|Power'!F:F, 2010, 'Energy|Power'!G:G, "n") + COUNTIFS('Energy|Power'!F:F, 2010, 'Energy|Power'!G:G, "s/l-UNC") + COUNTIFS('Energy|Power'!F:F, 2010, 'Energy|Power'!G:G, "s/l-POS") + COUNTIFS('Energy|Power'!F:F, 2010, 'Energy|Power'!G:G, "s/l-NEG") + COUNTIFS(Industry!F:F, 2010, Industry!G:G, "n") + COUNTIFS(Industry!F:F, 2010, Industry!G:G, "s/l-UNC") + COUNTIFS(Industry!F:F, 2010, Industry!G:G, "s/l-POS") + COUNTIFS(Industry!F:F, 2010, Industry!G:G, "s/l-NEG") + COUNTIFS(Buildings!F:F, 2010, Buildings!G:G, "n") + COUNTIFS(Buildings!F:F, 2010, Buildings!G:G, "s/l-UNC") + COUNTIFS(Buildings!F:F, 2010, Buildings!G:G, "s/l-POS") + COUNTIFS(Buildings!F:F, 2010, Buildings!G:G, "s/l-NEG") + COUNTIFS(Transport!F:F, 2010, Transport!G:G, "n") + COUNTIFS(Transport!F:F, 2010, Transport!G:G, "s/l-UNC") + COUNTIFS(Transport!F:F, 2010, Transport!G:G, "s/l-POS") + COUNTIFS(Transport!F:F, 2010, Transport!G:G, "s/l-NEG") + COUNTIFS(LULUCF!F:F, 2010, LULUCF!G:G, "n") + COUNTIFS(LULUCF!F:F, 2010, LULUCF!G:G, "s/l-UNC") + COUNTIFS(LULUCF!F:F, 2010, LULUCF!G:G, "s/l-POS") + COUNTIFS(LULUCF!F:F, 2010, LULUCF!G:G, "s/l-NEG") + COUNTIFS('Circular Economy'!F:F, 2010, 'Circular Economy'!G:G, "n") + COUNTIFS('Circular Economy'!F:F, 2010, 'Circular Economy'!G:G, "s/l-UNC") + COUNTIFS('Circular Economy'!F:F, 2010, 'Circular Economy'!G:G, "s/l-POS") + COUNTIFS('Circular Economy'!F:F, 2010, 'Circular Economy'!G:G, "s/l-NEG") + COUNTIFS(Finance!F:F, 2010, Finance!G:G, "n") + COUNTIFS(Finance!F:F, 2010, Finance!G:G, "s/l-UNC") + COUNTIFS(Finance!F:F, 2010, Finance!G:G, "s/l-POS") + COUNTIFS(Finance!F:F, 2010, Finance!G:G, "s/l-NEG") | Q8: Carbon sink | R8: =COUNTIFS('GHG Emissions'!H:H, "Carbon sink", 'GHG Emissions'!G:G, "n") + COUNTIFS('GHG Emissions'!H:H, "Carbon sink", 'GHG Emissions'!G:G, "s/l-UNC") + COUNTIFS('GHG Emissions'!H:H, "Carbon sink", 'GHG Emissions'!G:G, "s/l-POS") + COUNTIFS('GHG Emissions'!H:H, "Carbon sink", 'GHG Emissions'!G:G, "s/l-NEG") + COUNTIFS(Pollution!H:H, "Carbon sink", Pollution!G:G, "n") + COUNTIFS(Pollution!H:H, "Carbon sink", Pollution!G:G, "s/l-UNC") + COUNTIFS(Pollution!H:H, "Carbon sink", Pollution!G:G, "s/l-POS") + COUNTIFS(Pollution!H:H, "Carbon sink", Pollution!G:G, "s/l-NEG") + COUNTIFS('Energy|Power'!H:H, "Carbon sink", 'Energy|Power'!G:G, "n") + COUNTIFS('Energy|Power'!H:H, "Carbon sink", 'Energy|Power'!G:G, "s/l-UNC") + COUNTIFS('Energy|Power'!H:H, "Carbon sink", 'Energy|Power'!G:G, "s/l-POS") + COUNTIFS('Energy|Power'!H:H, "Carbon sink", 'Energy|Power'!G:G, "s/l-NEG") + COUNTIFS(Industry!H:H, "Carbon sink", Industry!G:G, "n") + COUNTIFS(Industry!H:H, "Carbon sink", Industry!G:G, "s/l-UNC") + COUNTIFS(Industry!H:H, "Carbon sink", Industry!G:G, "s/l-POS") + COUNTIFS(Industry!H:H, "Carbon sink", Industry!G:G, "s/l-NEG") + COUNTIFS(Buildings!H:H, "Carbon sink", Buildings!G:G, "n") + COUNTIFS(Buildings!H:H, "Carbon sink", Buildings!G:G, "s/l-UNC") + COUNTIFS(Buildings!H:H, "Carbon sink", Buildings!G:G, "s/l-POS") + COUNTIFS(Buildings!H:H, "Carbon sink", Buildings!G:G, "s/l-NEG") + COUNTIFS(Transport!H:H, "Carbon sink", Transport!G:G, "n") + COUNTIFS(Transport!H:H, "Carbon sink", Transport!G:G, "s/l-UNC") + COUNTIFS(Transport!H:H, "Carbon sink", Transport!G:G, "s/l-POS") + COUNTIFS(Transport!H:H, "Carbon sink", Transport!G:G, "s/l-NEG") + COUNTIFS(LULUCF!H:H, "Carbon sink", LULUCF!G:G, "n") + COUNTIFS(LULUCF!H:H, "Carbon sink", LULUCF!G:G, "s/l-UNC") + COUNTIFS(LULUCF!H:H, "Carbon sink", LULUCF!G:G, "s/l-POS") + COUNTIFS(LULUCF!H:H, "Carbon sink", LULUCF!G:G, "s/l-NEG") + COUNTIFS('Circular Economy'!H:H, "Carbon sink", 'Circular Economy'!G:G, "n") + COUNTIFS('Circular Economy'!H:H, "Carbon sink", 'Circular Economy'!G:G, "s/l-UNC") + COUNTIFS('Circular Economy'!H:H, "Carbon sink", 'Circular Economy'!G:G, "s/l-POS") + COUNTIFS('Circular Economy'!H:H, "Carbon sink", 'Circular Economy'!G:G, "s/l-NEG") + COUNTIFS(Finance!H:H, "Carbon sink", Finance!G:G, "n") + COUNTIFS(Finance!H:H, "Carbon sink", Finance!G:G, "s/l-UNC") + COUNTIFS(Finance!H:H, "Carbon sink", Finance!G:G, "s/l-POS") + COUNTIFS(Finance!H:H, "Carbon sink", Finance!G:G, "s/l-NEG") | T8: Sectors | U8: =COUNTIFS('GHG Emissions'!I:I,"sectors",'GHG Emissions'!G:G,"n") +COUNTIFS('GHG Emissions'!I:I,"sectors",'GHG Emissions'!G:G,"s/l-UNC") +COUNTIFS('GHG Emissions'!I:I,"sectors",'GHG Emissions'!G:G,"s/l-POS") +COUNTIFS('GHG Emissions'!I:I,"sectors",'GHG Emissions'!G:G,"s/l-NEG") +COUNTIFS(Pollution!I:I,"sectors",Pollution!G:G,"n") +COUNTIFS(Pollution!I:I,"sectors",Pollution!G:G,"s/l-UNC") +COUNTIFS(Pollution!I:I,"sectors",Pollution!G:G,"s/l-POS") +COUNTIFS(Pollution!I:I,"sectors",Pollution!G:G,"s/l-NEG") +COUNTIFS('Energy|Power'!I:I,"sectors",'Energy|Power'!G:G,"n") +COUNTIFS('Energy|Power'!I:I,"sectors",'Energy|Power'!G:G,"s/l-UNC") +COUNTIFS('Energy|Power'!I:I,"sectors",'Energy|Power'!G:G,"s/l-POS") +COUNTIFS('Energy|Power'!I:I,"sectors",'Energy|Power'!G:G,"s/l-NEG") +COUNTIFS(Industry!I:I,"sectors",Industry!G:G,"n") +COUNTIFS(Industry!I:I,"sectors",Industry!G:G,"s/l-UNC") +COUNTIFS(Industry!I:I,"sectors",Industry!G:G,"s/l-POS") +COUNTIFS(Industry!I:I,"sectors",Industry!G:G,"s/l-NEG") +COUNTIFS(Buildings!I:I,"sectors",Buildings!G:G,"n") +COUNTIFS(Buildings!I:I,"sectors",Buildings!G:G,"s/l-UNC") +COUNTIFS(Buildings!I:I,"sectors",Buildings!G:G,"s/l-POS") +COUNTIFS(Buildings!I:I,"sectors",Buildings!G:G,"s/l-NEG") +COUNTIFS(Transport!I:I,"sectors",Transport!G:G,"n") +COUNTIFS(Transport!I:I,"sectors",Transport!G:G,"s/l-UNC") +COUNTIFS(Transport!I:I,"sectors",Transport!G:G,"s/l-POS") +COUNTIFS(Transport!I:I,"sectors",Transport!G:G,"s/l-NEG") +COUNTIFS(LULUCF!I:I,"sectors",LULUCF!G:G,"n") +COUNTIFS(LULUCF!I:I,"sectors",LULUCF!G:G,"s/l-UNC") +COUNTIFS(LULUCF!I:I,"sectors",LULUCF!G:G,"s/l-POS") +COUNTIFS(LULUCF!I:I,"sectors",LULUCF!G:G,"s/l-NEG") +COUNTIFS('Circular Economy'!I:I,"sectors",'Circular Economy'!G:G,"n") +COUNTIFS('Circular Economy'!I:I,"sectors",'Circular Economy'!G:G,"s/l-UNC") +COUNTIFS('Circular Economy'!I:I,"sectors",'Circular Economy'!G:G,"s/l-POS") +COUNTIFS('Circular Economy'!I:I,"sectors",'Circular Economy'!G:G,"s/l-NEG") +COUNTIFS(Finance!I:I,"sectors",Finance!G:G,"n") +COUNTIFS(Finance!I:I,"sectors",Finance!G:G,"s/l-UNC") +COUNTIFS(Finance!I:I,"sectors",Finance!G:G,"s/l-POS") +COUNTIFS(Finance!I:I,"sectors",Finance!G:G,"s/l-NEG")
B9: Industry | C9: =COUNTIFS(Industry!G:G, "n") + COUNTIFS(Industry!G:G, "s/l-UNC") + COUNTIFS(Industry!G:G, "s/l-POS") + COUNTIFS(Industry!G:G, "s/l-NEG") | E9: Coal power | F9: =COUNTIFS('Energy|Power'!M:M, "Coal power") | H9: Strengthened or loosened target with negative climate impact | I9: =COUNTIF('GHG Emissions'!G:G,"s/l-NEG") +COUNTIF(Pollution!G:G,"s/l-NEG") +COUNTIF('Energy|Power'!G:G,"s/l-NEG") +COUNTIF(Industry!G:G,"s/l-NEG") +COUNTIF(Buildings!G:G,"s/l-NEG") +COUNTIF(Transport!G:G,"s/l-NEG") +COUNTIF(LULUCF!G:G,"s/l-NEG") +COUNTIF('Circular Economy'!G:G,"s/l-NEG") +COUNTIF(Finance!G:G,"s/l-NEG") | K9: 2007 | L9: =COUNTIFS('GHG Emissions'!A:A, 2007, 'GHG Emissions'!G:G, "n") + COUNTIFS('GHG Emissions'!A:A, 2007, 'GHG Emissions'!G:G, "s/l-UNC") + COUNTIFS('GHG Emissions'!A:A, 2007, 'GHG Emissions'!G:G, "s/l-POS") + COUNTIFS('GHG Emissions'!A:A, 2007, 'GHG Emissions'!G:G, "s/l-NEG") + COUNTIFS(Pollution!A:A, 2007, Pollution!G:G, "n") + COUNTIFS(Pollution!A:A, 2007, Pollution!G:G, "s/l-UNC") + COUNTIFS(Pollution!A:A, 2007, Pollution!G:G, "s/l-POS") + COUNTIFS(Pollution!A:A, 2007, Pollution!G:G, "s/l-NEG") + COUNTIFS('Energy|Power'!A:A, 2007, 'Energy|Power'!G:G, "n") + COUNTIFS('Energy|Power'!A:A, 2007, 'Energy|Power'!G:G, "s/l-UNC") + COUNTIFS('Energy|Power'!A:A, 2007, 'Energy|Power'!G:G, "s/l-POS") + COUNTIFS('Energy|Power'!A:A, 2007, 'Energy|Power'!G:G, "s/l-NEG") + COUNTIFS(Industry!A:A, 2007, Industry!G:G, "n") + COUNTIFS(Industry!A:A, 2007, Industry!G:G, "s/l-UNC") + COUNTIFS(Industry!A:A, 2007, Industry!G:G, "s/l-POS") + COUNTIFS(Industry!A:A, 2007, Industry!G:G, "s/l-NEG") + COUNTIFS(Buildings!A:A, 2007, Buildings!G:G, "n") + COUNTIFS(Buildings!A:A, 2007, Buildings!G:G, "s/l-UNC") + COUNTIFS(Buildings!A:A, 2007, Buildings!G:G, "s/l-POS") + COUNTIFS(Buildings!A:A, 2007, Buildings!G:G, "s/l-NEG") + COUNTIFS(Transport!A:A, 2007, Transport!G:G, "n") + COUNTIFS(Transport!A:A, 2007, Transport!G:G, "s/l-UNC") + COUNTIFS(Transport!A:A, 2007, Transport!G:G, "s/l-POS") + COUNTIFS(Transport!A:A, 2007, Transport!G:G, "s/l-NEG") + COUNTIFS(LULUCF!A:A, 2007, LULUCF!G:G, "n") + COUNTIFS(LULUCF!A:A, 2007, LULUCF!G:G, "s/l-UNC") + COUNTIFS(LULUCF!A:A, 2007, LULUCF!G:G, "s/l-POS") + COUNTIFS(LULUCF!A:A, 2007, LULUCF!G:G, "s/l-NEG") + COUNTIFS('Circular Economy'!A:A, 2007, 'Circular Economy'!G:G, "n") + COUNTIFS('Circular Economy'!A:A, 2007, 'Circular Economy'!G:G, "s/l-UNC") + COUNTIFS('Circular Economy'!A:A, 2007, 'Circular Economy'!G:G, "s/l-POS") + COUNTIFS('Circular Economy'!A:A, 2007, 'Circular Economy'!G:G, "s/l-NEG") + COUNTIFS(Finance!A:A, 2007, Finance!G:G, "n") + COUNTIFS(Finance!A:A, 2007, Finance!G:G, "s/l-UNC") + COUNTIFS(Finance!A:A, 2007, Finance!G:G, "s/l-POS") + COUNTIFS(Finance!A:A, 2007, Finance!G:G, "s/l-NEG") | N9: 11th FYP | O9: =COUNTIFS('GHG Emissions'!F:F, "11th FYP", 'GHG Emissions'!G:G, "n") + COUNTIFS('GHG Emissions'!F:F, "11th FYP", 'GHG Emissions'!G:G, "s/l-UNC") + COUNTIFS('GHG Emissions'!F:F, "11th FYP", 'GHG Emissions'!G:G, "s/l-POS") + COUNTIFS('GHG Emissions'!F:F, "11th FYP", 'GHG Emissions'!G:G, "s/l-NEG") + COUNTIFS(Pollution!F:F, "11th FYP", Pollution!G:G, "n") + COUNTIFS(Pollution!F:F, "11th FYP", Pollution!G:G, "s/l-UNC") + COUNTIFS(Pollution!F:F, "11th FYP", Pollution!G:G, "s/l-POS") + COUNTIFS(Pollution!F:F, "11th FYP", Pollution!G:G, "s/l-NEG") + COUNTIFS('Energy|Power'!F:F, "11th FYP", 'Energy|Power'!G:G, "n") + COUNTIFS('Energy|Power'!F:F, "11th FYP", 'Energy|Power'!G:G, "s/l-UNC") + COUNTIFS('Energy|Power'!F:F, "11th FYP", 'Energy|Power'!G:G, "s/l-POS") + COUNTIFS('Energy|Power'!F:F, "11th FYP", 'Energy|Power'!G:G, "s/l-NEG") + COUNTIFS(Industry!F:F, "11th FYP", Industry!G:G, "n") + COUNTIFS(Industry!F:F, "11th FYP", Industry!G:G, "s/l-UNC") + COUNTIFS(Industry!F:F, "11th FYP", Industry!G:G, "s/l-POS") + COUNTIFS(Industry!F:F, "11th FYP", Industry!G:G, "s/l-NEG") + COUNTIFS(Buildings!F:F, "11th FYP", Buildings!G:G, "n") + COUNTIFS(Buildings!F:F, "11th FYP", Buildings!G:G, "s/l-UNC") + COUNTIFS(Buildings!F:F, "11th FYP", Buildings!G:G, "s/l-POS") + COUNTIFS(Buildings!F:F, "11th FYP", Buildings!G:G, "s/l-NEG") + COUNTIFS(Transport!F:F, "11th FYP", Transport!G:G, "n") + COUNTIFS(Transport!F:F, "11th FYP", Transport!G:G, "s/l-UNC") + COUNTIFS(Transport!F:F, "11th FYP", Transport!G:G, "s/l-POS") + COUNTIFS(Transport!F:F, "11th FYP", Transport!G:G, "s/l-NEG") + COUNTIFS(LULUCF!F:F, "11th FYP", LULUCF!G:G, "n") + COUNTIFS(LULUCF!F:F, "11th FYP", LULUCF!G:G, "s/l-UNC") + COUNTIFS(LULUCF!F:F, "11th FYP", LULUCF!G:G, "s/l-POS") + COUNTIFS(LULUCF!F:F, "11th FYP", LULUCF!G:G, "s/l-NEG") + COUNTIFS('Circular Economy'!F:F, "11th FYP", 'Circular Economy'!G:G, "n") + COUNTIFS('Circular Economy'!F:F, "11th FYP", 'Circular Economy'!G:G, "s/l-UNC") + COUNTIFS('Circular Economy'!F:F, "11th FYP", 'Circular Economy'!G:G, "s/l-POS") + COUNTIFS('Circular Economy'!F:F, "11th FYP", 'Circular Economy'!G:G, "s/l-NEG") + COUNTIFS(Finance!F:F, "11th FYP", Finance!G:G, "n") + COUNTIFS(Finance!F:F, "11th FYP", Finance!G:G, "s/l-UNC") + COUNTIFS(Finance!F:F, "11th FYP", Finance!G:G, "s/l-POS") + COUNTIFS(Finance!F:F, "11th FYP", Finance!G:G, "s/l-NEG") | Q9: Pollution control | R9: =COUNTIFS('GHG Emissions'!H:H, "Pollution control", 'GHG Emissions'!G:G, "n") + COUNTIFS('GHG Emissions'!H:H, "Pollution control", 'GHG Emissions'!G:G, "s/l-UNC") + COUNTIFS('GHG Emissions'!H:H, "Pollution control", 'GHG Emissions'!G:G, "s/l-POS") + COUNTIFS('GHG Emissions'!H:H, "Pollution control", 'GHG Emissions'!G:G, "s/l-NEG") + COUNTIFS(Pollution!H:H, "Pollution control", Pollution!G:G, "n") + COUNTIFS(Pollution!H:H, "Pollution control", Pollution!G:G, "s/l-UNC") + COUNTIFS(Pollution!H:H, "Pollution control", Pollution!G:G, "s/l-POS") + COUNTIFS(Pollution!H:H, "Pollution control", Pollution!G:G, "s/l-NEG") + COUNTIFS('Energy|Power'!H:H, "Pollution control", 'Energy|Power'!G:G, "n") + COUNTIFS('Energy|Power'!H:H, "Pollution control", 'Energy|Power'!G:G, "s/l-UNC") + COUNTIFS('Energy|Power'!H:H, "Pollution control", 'Energy|Power'!G:G, "s/l-POS") + COUNTIFS('Energy|Power'!H:H, "Pollution control", 'Energy|Power'!G:G, "s/l-NEG") + COUNTIFS(Industry!H:H, "Pollution control", Industry!G:G, "n") + COUNTIFS(Industry!H:H, "Pollution control", Industry!G:G, "s/l-UNC") + COUNTIFS(Industry!H:H, "Pollution control", Industry!G:G, "s/l-POS") + COUNTIFS(Industry!H:H, "Pollution control", Industry!G:G, "s/l-NEG") + COUNTIFS(Buildings!H:H, "Pollution control", Buildings!G:G, "n") + COUNTIFS(Buildings!H:H, "Pollution control", Buildings!G:G, "s/l-UNC") + COUNTIFS(Buildings!H:H, "Pollution control", Buildings!G:G, "s/l-POS") + COUNTIFS(Buildings!H:H, "Pollution control", Buildings!G:G, "s/l-NEG") + COUNTIFS(Transport!H:H, "Pollution control", Transport!G:G, "n") + COUNTIFS(Transport!H:H, "Pollution control", Transport!G:G, "s/l-UNC") + COUNTIFS(Transport!H:H, "Pollution control", Transport!G:G, "s/l-POS") + COUNTIFS(Transport!H:H, "Pollution control", Transport!G:G, "s/l-NEG") + COUNTIFS(LULUCF!H:H, "Pollution control", LULUCF!G:G, "n") + COUNTIFS(LULUCF!H:H, "Pollution control", LULUCF!G:G, "s/l-UNC") + COUNTIFS(LULUCF!H:H, "Pollution control", LULUCF!G:G, "s/l-POS") + COUNTIFS(LULUCF!H:H, "Pollution control", LULUCF!G:G, "s/l-NEG") + COUNTIFS('Circular Economy'!H:H, "Pollution control", 'Circular Economy'!G:G, "n") + COUNTIFS('Circular Economy'!H:H, "Pollution control", 'Circular Economy'!G:G, "s/l-UNC") + COUNTIFS('Circular Economy'!H:H, "Pollution control", 'Circular Economy'!G:G, "s/l-POS") + COUNTIFS('Circular Economy'!H:H, "Pollution control", 'Circular Economy'!G:G, "s/l-NEG") + COUNTIFS(Finance!H:H, "Pollution control", Finance!G:G, "n") + COUNTIFS(Finance!H:H, "Pollution control", Finance!G:G, "s/l-UNC") + COUNTIFS(Finance!H:H, "Pollution control", Finance!G:G, "s/l-POS") + COUNTIFS(Finance!H:H, "Pollution control", Finance!G:G, "s/l-NEG") | T9: Whole economy | U9: =COUNTIFS('GHG Emissions'!I:I,"whole economy",'GHG Emissions'!G:G,"n") +COUNTIFS('GHG Emissions'!I:I,"whole economy",'GHG Emissions'!G:G,"s/l-UNC") +COUNTIFS('GHG Emissions'!I:I,"whole economy",'GHG Emissions'!G:G,"s/l-POS") +COUNTIFS('GHG Emissions'!I:I,"whole economy",'GHG Emissions'!G:G,"s/l-NEG") +COUNTIFS(Pollution!I:I,"whole economy",Pollution!G:G,"n") +COUNTIFS(Pollution!I:I,"whole economy",Pollution!G:G,"s/l-UNC") +COUNTIFS(Pollution!I:I,"whole economy",Pollution!G:G,"s/l-POS") +COUNTIFS(Pollution!I:I,"whole economy",Pollution!G:G,"s/l-NEG") +COUNTIFS('Energy|Power'!I:I,"whole economy",'Energy|Power'!G:G,"n") +COUNTIFS('Energy|Power'!I:I,"whole economy",'Energy|Power'!G:G,"s/l-UNC") +COUNTIFS('Energy|Power'!I:I,"whole economy",'Energy|Power'!G:G,"s/l-POS") +COUNTIFS('Energy|Power'!I:I,"whole economy",'Energy|Power'!G:G,"s/l-NEG") +COUNTIFS(Industry!I:I,"whole economy",Industry!G:G,"n") +COUNTIFS(Industry!I:I,"whole economy",Industry!G:G,"s/l-UNC") +COUNTIFS(Industry!I:I,"whole economy",Industry!G:G,"s/l-POS") +COUNTIFS(Industry!I:I,"whole economy",Industry!G:G,"s/l-NEG") +COUNTIFS(Buildings!I:I,"whole economy",Buildings!G:G,"n") +COUNTIFS(Buildings!I:I,"whole economy",Buildings!G:G,"s/l-UNC") +COUNTIFS(Buildings!I:I,"whole economy",Buildings!G:G,"s/l-POS") +COUNTIFS(Buildings!I:I,"whole economy",Buildings!G:G,"s/l-NEG") +COUNTIFS(Transport!I:I,"whole economy",Transport!G:G,"n") +COUNTIFS(Transport!I:I,"whole economy",Transport!G:G,"s/l-UNC") +COUNTIFS(Transport!I:I,"whole economy",Transport!G:G,"s/l-POS") +COUNTIFS(Transport!I:I,"whole economy",Transport!G:G,"s/l-NEG") +COUNTIFS(LULUCF!I:I,"whole economy",LULUCF!G:G,"n") +COUNTIFS(LULUCF!I:I,"whole economy",LULUCF!G:G,"s/l-UNC") +COUNTIFS(LULUCF!I:I,"whole economy",LULUCF!G:G,"s/l-POS") +COUNTIFS(LULUCF!I:I,"whole economy",LULUCF!G:G,"s/l-NEG") +COUNTIFS('Circular Economy'!I:I,"whole economy",'Circular Economy'!G:G,"n") +COUNTIFS('Circular Economy'!I:I,"whole economy",'Circular Economy'!G:G,"s/l-UNC") +COUNTIFS('Circular Economy'!I:I,"whole economy",'Circular Economy'!G:G,"s/l-POS") +COUNTIFS('Circular Economy'!I:I,"whole economy",'Circular Economy'!G:G,"s/l-NEG") +COUNTIFS(Finance!I:I,"whole economy",Finance!G:G,"n") +COUNTIFS(Finance!I:I,"whole economy",Finance!G:G,"s/l-UNC") +COUNTIFS(Finance!I:I,"whole economy",Finance!G:G,"s/l-POS") +COUNTIFS(Finance!I:I,"whole economy",Finance!G:G,"s/l-NEG")
B10: Buildings | C10: =COUNTIFS(Buildings!G:G, "n") + COUNTIFS(Buildings!G:G, "s/l-UNC") + COUNTIFS(Buildings!G:G, "s/l-POS") + COUNTIFS(Buildings!G:G, "s/l-NEG") | E10: Fossil fuel reserves | F10: =COUNTIFS('Energy|Power'!M:M, "Reserves") | K10: 2008 | L10: =COUNTIFS('GHG Emissions'!A:A, 2008, 'GHG Emissions'!G:G, "n") + COUNTIFS('GHG Emissions'!A:A, 2008, 'GHG Emissions'!G:G, "s/l-UNC") + COUNTIFS('GHG Emissions'!A:A, 2008, 'GHG Emissions'!G:G, "s/l-POS") + COUNTIFS('GHG Emissions'!A:A, 2008, 'GHG Emissions'!G:G, "s/l-NEG") + COUNTIFS(Pollution!A:A, 2008, Pollution!G:G, "n") + COUNTIFS(Pollution!A:A, 2008, Pollution!G:G, "s/l-UNC") + COUNTIFS(Pollution!A:A, 2008, Pollution!G:G, "s/l-POS") + COUNTIFS(Pollution!A:A, 2008, Pollution!G:G, "s/l-NEG") + COUNTIFS('Energy|Power'!A:A, 2008, 'Energy|Power'!G:G, "n") + COUNTIFS('Energy|Power'!A:A, 2008, 'Energy|Power'!G:G, "s/l-UNC") + COUNTIFS('Energy|Power'!A:A, 2008, 'Energy|Power'!G:G, "s/l-POS") + COUNTIFS('Energy|Power'!A:A, 2008, 'Energy|Power'!G:G, "s/l-NEG") + COUNTIFS(Industry!A:A, 2008, Industry!G:G, "n") + COUNTIFS(Industry!A:A, 2008, Industry!G:G, "s/l-UNC") + COUNTIFS(Industry!A:A, 2008, Industry!G:G, "s/l-POS") + COUNTIFS(Industry!A:A, 2008, Industry!G:G, "s/l-NEG") + COUNTIFS(Buildings!A:A, 2008, Buildings!G:G, "n") + COUNTIFS(Buildings!A:A, 2008, Buildings!G:G, "s/l-UNC") + COUNTIFS(Buildings!A:A, 2008, Buildings!G:G, "s/l-POS") + COUNTIFS(Buildings!A:A, 2008, Buildings!G:G, "s/l-NEG") + COUNTIFS(Transport!A:A, 2008, Transport!G:G, "n") + COUNTIFS(Transport!A:A, 2008, Transport!G:G, "s/l-UNC") + COUNTIFS(Transport!A:A, 2008, Transport!G:G, "s/l-POS") + COUNTIFS(Transport!A:A, 2008, Transport!G:G, "s/l-NEG") + COUNTIFS(LULUCF!A:A, 2008, LULUCF!G:G, "n") + COUNTIFS(LULUCF!A:A, 2008, LULUCF!G:G, "s/l-UNC") + COUNTIFS(LULUCF!A:A, 2008, LULUCF!G:G, "s/l-POS") + COUNTIFS(LULUCF!A:A, 2008, LULUCF!G:G, "s/l-NEG") + COUNTIFS('Circular Economy'!A:A, 2008, 'Circular Economy'!G:G, "n") + COUNTIFS('Circular Economy'!A:A, 2008, 'Circular Economy'!G:G, "s/l-UNC") + COUNTIFS('Circular Economy'!A:A, 2008, 'Circular Economy'!G:G, "s/l-POS") + COUNTIFS('Circular Economy'!A:A, 2008, 'Circular Economy'!G:G, "s/l-NEG") + COUNTIFS(Finance!A:A, 2008, Finance!G:G, "n") + COUNTIFS(Finance!A:A, 2008, Finance!G:G, "s/l-UNC") + COUNTIFS(Finance!A:A, 2008, Finance!G:G, "s/l-POS") + COUNTIFS(Finance!A:A, 2008, Finance!G:G, "s/l-NEG") | N10: 2011 | O10: =COUNTIFS('GHG Emissions'!F:F, 2011, 'GHG Emissions'!G:G, "n") + COUNTIFS('GHG Emissions'!F:F, 2011, 'GHG Emissions'!G:G, "s/l-UNC") + COUNTIFS('GHG Emissions'!F:F, 2011, 'GHG Emissions'!G:G, "s/l-POS") + COUNTIFS('GHG Emissions'!F:F, 2011, 'GHG Emissions'!G:G, "s/l-NEG") + COUNTIFS(Pollution!F:F, 2011, Pollution!G:G, "n") + COUNTIFS(Pollution!F:F, 2011, Pollution!G:G, "s/l-UNC") + COUNTIFS(Pollution!F:F, 2011, Pollution!G:G, "s/l-POS") + COUNTIFS(Pollution!F:F, 2011, Pollution!G:G, "s/l-NEG") + COUNTIFS('Energy|Power'!F:F, 2011, 'Energy|Power'!G:G, "n") + COUNTIFS('Energy|Power'!F:F, 2011, 'Energy|Power'!G:G, "s/l-UNC") + COUNTIFS('Energy|Power'!F:F, 2011, 'Energy|Power'!G:G, "s/l-POS") + COUNTIFS('Energy|Power'!F:F, 2011, 'Energy|Power'!G:G, "s/l-NEG") + COUNTIFS(Industry!F:F, 2011, Industry!G:G, "n") + COUNTIFS(Industry!F:F, 2011, Industry!G:G, "s/l-UNC") + COUNTIFS(Industry!F:F, 2011, Industry!G:G, "s/l-POS") + COUNTIFS(Industry!F:F, 2011, Industry!G:G, "s/l-NEG") + COUNTIFS(Buildings!F:F, 2011, Buildings!G:G, "n") + COUNTIFS(Buildings!F:F, 2011, Buildings!G:G, "s/l-UNC") + COUNTIFS(Buildings!F:F, 2011, Buildings!G:G, "s/l-POS") + COUNTIFS(Buildings!F:F, 2011, Buildings!G:G, "s/l-NEG") + COUNTIFS(Transport!F:F, 2011, Transport!G:G, "n") + COUNTIFS(Transport!F:F, 2011, Transport!G:G, "s/l-UNC") + COUNTIFS(Transport!F:F, 2011, Transport!G:G, "s/l-POS") + COUNTIFS(Transport!F:F, 2011, Transport!G:G, "s/l-NEG") + COUNTIFS(LULUCF!F:F, 2011, LULUCF!G:G, "n") + COUNTIFS(LULUCF!F:F, 2011, LULUCF!G:G, "s/l-UNC") + COUNTIFS(LULUCF!F:F, 2011, LULUCF!G:G, "s/l-POS") + COUNTIFS(LULUCF!F:F, 2011, LULUCF!G:G, "s/l-NEG") + COUNTIFS('Circular Economy'!F:F, 2011, 'Circular Economy'!G:G, "n") + COUNTIFS('Circular Economy'!F:F, 2011, 'Circular Economy'!G:G, "s/l-UNC") + COUNTIFS('Circular Economy'!F:F, 2011, 'Circular Economy'!G:G, "s/l-POS") + COUNTIFS('Circular Economy'!F:F, 2011, 'Circular Economy'!G:G, "s/l-NEG") + COUNTIFS(Finance!F:F, 2011, Finance!G:G, "n") + COUNTIFS(Finance!F:F, 2011, Finance!G:G, "s/l-UNC") + COUNTIFS(Finance!F:F, 2011, Finance!G:G, "s/l-POS") + COUNTIFS(Finance!F:F, 2011, Finance!G:G, "s/l-NEG") | Q10: Energy saving | R10: =COUNTIFS('GHG Emissions'!H:H, "Energy saving", 'GHG Emissions'!G:G, "n") + COUNTIFS('GHG Emissions'!H:H, "Energy saving", 'GHG Emissions'!G:G, "s/l-UNC") + COUNTIFS('GHG Emissions'!H:H, "Energy saving", 'GHG Emissions'!G:G, "s/l-POS") + COUNTIFS('GHG Emissions'!H:H, "Energy saving", 'GHG Emissions'!G:G, "s/l-NEG") + COUNTIFS(Pollution!H:H, "Energy saving", Pollution!G:G, "n") + COUNTIFS(Pollution!H:H, "Energy saving", Pollution!G:G, "s/l-UNC") + COUNTIFS(Pollution!H:H, "Energy saving", Pollution!G:G, "s/l-POS") + COUNTIFS(Pollution!H:H, "Energy saving", Pollution!G:G, "s/l-NEG") + COUNTIFS('Energy|Power'!H:H, "Energy saving", 'Energy|Power'!G:G, "n") + COUNTIFS('Energy|Power'!H:H, "Energy saving", 'Energy|Power'!G:G, "s/l-UNC") + COUNTIFS('Energy|Power'!H:H, "Energy saving", 'Energy|Power'!G:G, "s/l-POS") + COUNTIFS('Energy|Power'!H:H, "Energy saving", 'Energy|Power'!G:G, "s/l-NEG") + COUNTIFS(Industry!H:H, "Energy saving", Industry!G:G, "n") + COUNTIFS(Industry!H:H, "Energy saving", Industry!G:G, "s/l-UNC") + COUNTIFS(Industry!H:H, "Energy saving", Industry!G:G, "s/l-POS") + COUNTIFS(Industry!H:H, "Energy saving", Industry!G:G, "s/l-NEG") + COUNTIFS(Buildings!H:H, "Energy saving", Buildings!G:G, "n") + COUNTIFS(Buildings!H:H, "Energy saving", Buildings!G:G, "s/l-UNC") + COUNTIFS(Buildings!H:H, "Energy saving", Buildings!G:G, "s/l-POS") + COUNTIFS(Buildings!H:H, "Energy saving", Buildings!G:G, "s/l-NEG") + COUNTIFS(Transport!H:H, "Energy saving", Transport!G:G, "n") + COUNTIFS(Transport!H:H, "Energy saving", Transport!G:G, "s/l-UNC") + COUNTIFS(Transport!H:H, "Energy saving", Transport!G:G, "s/l-POS") + COUNTIFS(Transport!H:H, "Energy saving", Transport!G:G, "s/l-NEG") + COUNTIFS(LULUCF!H:H, "Energy saving", LULUCF!G:G, "n") + COUNTIFS(LULUCF!H:H, "Energy saving", LULUCF!G:G, "s/l-UNC") + COUNTIFS(LULUCF!H:H, "Energy saving", LULUCF!G:G, "s/l-POS") + COUNTIFS(LULUCF!H:H, "Energy saving", LULUCF!G:G, "s/l-NEG") + COUNTIFS('Circular Economy'!H:H, "Energy saving", 'Circular Economy'!G:G, "n") + COUNTIFS('Circular Economy'!H:H, "Energy saving", 'Circular Economy'!G:G, "s/l-UNC") + COUNTIFS('Circular Economy'!H:H, "Energy saving", 'Circular Economy'!G:G, "s/l-POS") + COUNTIFS('Circular Economy'!H:H, "Energy saving", 'Circular Economy'!G:G, "s/l-NEG") + COUNTIFS(Finance!H:H, "Energy saving", Finance!G:G, "n") + COUNTIFS(Finance!H:H, "Energy saving", Finance!G:G, "s/l-UNC") + COUNTIFS(Finance!H:H, "Energy saving", Finance!G:G, "s/l-POS") + COUNTIFS(Finance!H:H, "Energy saving", Finance!G:G, "s/l-NEG") | T10: Unclear | U10: =COUNTIFS('GHG Emissions'!I:I,"unclear",'GHG Emissions'!G:G,"n") +COUNTIFS('GHG Emissions'!I:I,"unclear",'GHG Emissions'!G:G,"s/l-UNC") +COUNTIFS('GHG Emissions'!I:I,"unclear",'GHG Emissions'!G:G,"s/l-POS") +COUNTIFS('GHG Emissions'!I:I,"unclear",'GHG Emissions'!G:G,"s/l-NEG") +COUNTIFS(Pollution!I:I,"unclear",Pollution!G:G,"n") +COUNTIFS(Pollution!I:I,"unclear",Pollution!G:G,"s/l-UNC") +COUNTIFS(Pollution!I:I,"unclear",Pollution!G:G,"s/l-POS") +COUNTIFS(Pollution!I:I,"unclear",Pollution!G:G,"s/l-NEG") +COUNTIFS('Energy|Power'!I:I,"unclear",'Energy|Power'!G:G,"n") +COUNTIFS('Energy|Power'!I:I,"unclear",'Energy|Power'!G:G,"s/l-UNC") +COUNTIFS('Energy|Power'!I:I,"unclear",'Energy|Power'!G:G,"s/l-POS") +COUNTIFS('Energy|Power'!I:I,"unclear",'Energy|Power'!G:G,"s/l-NEG") +COUNTIFS(Industry!I:I,"unclear",Industry!G:G,"n") +COUNTIFS(Industry!I:I,"unclear",Industry!G:G,"s/l-UNC") +COUNTIFS(Industry!I:I,"unclear",Industry!G:G,"s/l-POS") +COUNTIFS(Industry!I:I,"unclear",Industry!G:G,"s/l-NEG") +COUNTIFS(Buildings!I:I,"unclear",Buildings!G:G,"n") +COUNTIFS(Buildings!I:I,"unclear",Buildings!G:G,"s/l-UNC") +COUNTIFS(Buildings!I:I,"unclear",Buildings!G:G,"s/l-POS") +COUNTIFS(Buildings!I:I,"unclear",Buildings!G:G,"s/l-NEG") +COUNTIFS(Transport!I:I,"unclear",Transport!G:G,"n") +COUNTIFS(Transport!I:I,"unclear",Transport!G:G,"s/l-UNC") +COUNTIFS(Transport!I:I,"unclear",Transport!G:G,"s/l-POS") +COUNTIFS(Transport!I:I,"unclear",Transport!G:G,"s/l-NEG") +COUNTIFS(LULUCF!I:I,"unclear",LULUCF!G:G,"n") +COUNTIFS(LULUCF!I:I,"unclear",LULUCF!G:G,"s/l-UNC") +COUNTIFS(LULUCF!I:I,"unclear",LULUCF!G:G,"s/l-POS") +COUNTIFS(LULUCF!I:I,"unclear",LULUCF!G:G,"s/l-NEG") +COUNTIFS('Circular Economy'!I:I,"unclear",'Circular Economy'!G:G,"n") +COUNTIFS('Circular Economy'!I:I,"unclear",'Circular Economy'!G:G,"s/l-UNC") +COUNTIFS('Circular Economy'!I:I,"unclear",'Circular Economy'!G:G,"s/l-POS") +COUNTIFS('Circular Economy'!I:I,"unclear",'Circular Economy'!G:G,"s/l-NEG") +COUNTIFS(Finance!I:I,"unclear",Finance!G:G,"n") +COUNTIFS(Finance!I:I,"unclear",Finance!G:G,"s/l-UNC") +COUNTIFS(Finance!I:I,"unclear",Finance!G:G,"s/l-POS") +COUNTIFS(Finance!I:I,"unclear",Finance!G:G,"s/l-NEG")
