Workbook

Sheet 说明
B2: 中国国家气候目标数据库 (v1.0.0) | S2: CC BY 4.0
B3: 本数据集汇编了中国中央政府自2004年至2026年年中制定的量化气候相关目标，这些目标源自官方政策文件和政府网站条目，并按不同主题领域进行整理。 | R3: 作者 | S3: Florian Wengel
B4: 在中国，目标在实践中具有指令性质，是政府机构的重要工作指引。 | S4: 伦敦大学亚非学院
B5: 最后更新 | C5: 46272 | Q5: 免责声明：所有错误均由作者承担。 | S5: 705404@soas.ac.uk
B6: 2026-09-07：根据《促进数字化绿色化协同转型发展实施方案（2026-2030年）》（IP2604）新增1条目标：算力设施等重点领域可再生能源电力消费水平达到所在省份可再生能源电力消纳责任权重水平（2030）。
B7: 2026-09-07：简化目标类别名称，删除“目标”后缀（如“可再生能源目标”→“可再生能源”），中英文同步。
B8: 2026-09-04：按收录口径（直接减排/间接促进减排/显著影响排放路径）筛查，删除62条与气候无直接关联的指标（出行便利、安检流程、车辆技术参数、就业营收、生物多样性等）。 2026-09-04：新增17份2026年政策文件的169条目标（新目标98条、重申目标63条、强化或放宽目标8条），并在「来源」表新增26份政策文件。
B9: 数据来源说明
B10: 目标摘录自中国中央政府各部门发布的中国气候相关文件。这些文本文件来源于政府机构网站、在线百科全书百度百科、中国官方媒体或其他网站。
B12: 气候目标定义
B13: 为编制本数据集之目的，我们将气候目标广义地定义为旨在直接减少温室气体排放、间接促进减排、或对温室气体排放路径产生重大影响的量化承诺。
B14: 本数据集既包括硬性目标，也包括较为软性的指导性目标。
B16: 范围与覆盖
B17: 本数据集仅涵盖国家级气候目标，不提供次国家级目标的信息。目标摘录自2004年以来发布的政策文件。
B18: 本数据集力求尽可能全面，但仍可能有部分目标未能收录。
B20: 数据集结构
B21: 工作表 | C21: 说明
B22: 概览 | C22: 汇总统计
B23: 温室气体排放 | C23: 所有涉及温室气体排放的目标，涵盖全社会经济或特定行业、系统或过程
B24: 能源|电力 | C24: 所有与能源供应（包括煤电相关目标）和消费相关的目标
B25: 工业 | C25: 所有与工业部门相关的目标，特别是高碳工业过程
B26: 建筑 | C26: 所有与建筑和基础设施相关的目标
B27: 交通 | C27: 所有与交通运输和物流相关的目标
B28: 土地利用、土地利用变化和林业 | C28: 所有与土地利用、农业和林业相关的目标
B29: 循环经济 | C29: 所有与废弃物和水资源管理及循环利用相关的目标
B30: 污染 | C30: 所有涉及空气或水污染物排放的目标，涵盖全社会经济或特定行业、系统或过程
B31: 金融 | C31: 所有与实现脱碳目标融资相关的目标
B32: 来源 | C32: 用于标识目标数据来源的政策文件代码。代码及其对应的政策文件完整标题可在「来源」工作表中找到。
B34: 列说明
B35: 发布年份 | C35: 目标所在源文件正式发布或出版的年份。
B36: 指标 | C36: 目标所涉及的核心指标（衡量的内容）。
B37: 方向 | C37: 目标所表达的预期变化方向或类型
B38: 目标值 | C38: 目标水平或变化幅度（数值及其单位）
B39: 基线 | C39: 衡量目标进展的基准水平或年份（如源文件中有说明）。这是变化幅度的起始参考年份。
C40: 目标预定实现的年份或时期。
C41: 表示目标是新增、重复、强化或放宽的代码：
C42: n = 新目标（首次出现）
C43: r = 重复目标（同一目标水平和目标年份在多个政策文件中出现）
C44: s/l = 强化或放宽目标（相同目标年份或时期，但目标水平有所提高或降低）
D45: s/l-UNC | E45: 气候影响不明确的强化或放宽目标
...

Sheet 概览
B2: 描述性统计
B4: 按行业/主题分列的目标数量 | E4: 按子主题分列的"能源|电力"目标数量 | H4: 按目标类型分列的目标数量 | K4: 按公布年份分列的目标数量 | N4: 按目标年份分列的目标数量 | Q4: 按类别分列的目标数量 | T4: 按责任主体分列的目标
B6: 温室气体排放 | C6: =COUNTIFS(温室气体排放!G:G, "新目标") + COUNTIFS(温室气体排放!G:G, "强化或放宽目标（气候影响不明确）") + COUNTIFS(温室气体排放!G:G, "强化或放宽目标（积极气候影响）") + COUNTIFS(温室气体排放!G:G, "强化或放宽目标（消极气候影响）") | E6: 能源消费 | F6: =COUNTIFS('能源|电力'!M:M, "能源消费") | H6: 新目标 | I6: =COUNTIF(温室气体排放!G:G,"新目标") +COUNTIF(污染!G:G,"新目标") +COUNTIF('能源|电力'!G:G,"新目标") +COUNTIF(工业!G:G,"新目标") +COUNTIF(建筑!G:G,"新目标") +COUNTIF(交通!G:G,"新目标") +COUNTIF('土地利用、土地利用变化和林业'!G:G,"新目标") +COUNTIF(循环经济!G:G,"新目标") +COUNTIF(金融!G:G,"新目标") | K6: 2004 | L6: =COUNTIFS(温室气体排放!A:A, 2004, 温室气体排放!G:G, "新目标") + COUNTIFS(温室气体排放!A:A, 2004, 温室气体排放!G:G, "强化或放宽目标（气候影响不明确）") + COUNTIFS(温室气体排放!A:A, 2004, 温室气体排放!G:G, "强化或放宽目标（积极气候影响）") + COUNTIFS(温室气体排放!A:A, 2004, 温室气体排放!G:G, "强化或放宽目标（消极气候影响）") + COUNTIFS(污染!A:A, 2004, 污染!G:G, "新目标") + COUNTIFS(污染!A:A, 2004, 污染!G:G, "强化或放宽目标（气候影响不明确）") + COUNTIFS(污染!A:A, 2004, 污染!G:G, "强化或放宽目标（积极气候影响）") + COUNTIFS(污染!A:A, 2004, 污染!G:G, "强化或放宽目标（消极气候影响）") + COUNTIFS('能源|电力'!A:A, 2004, '能源|电力'!G:G, "新目标") + COUNTIFS('能源|电力'!A:A, 2004, '能源|电力'!G:G, "强化或放宽目标（气候影响不明确）") + COUNTIFS('能源|电力'!A:A, 2004, '能源|电力'!G:G, "强化或放宽目标（积极气候影响）") + COUNTIFS('能源|电力'!A:A, 2004, '能源|电力'!G:G, "强化或放宽目标（消极气候影响）") + COUNTIFS(工业!A:A, 2004, 工业!G:G, "新目标") + COUNTIFS(工业!A:A, 2004, 工业!G:G, "强化或放宽目标（气候影响不明确）") + COUNTIFS(工业!A:A, 2004, 工业!G:G, "强化或放宽目标（积极气候影响）") + COUNTIFS(工业!A:A, 2004, 工业!G:G, "强化或放宽目标（消极气候影响）") + COUNTIFS(建筑!A:A, 2004, 建筑!G:G, "新目标") + COUNTIFS(建筑!A:A, 2004, 建筑!G:G, "强化或放宽目标（气候影响不明确）") + COUNTIFS(建筑!A:A, 2004, 建筑!G:G, "强化或放宽目标（积极气候影响）") + COUNTIFS(建筑!A:A, 2004, 建筑!G:G, "强化或放宽目标（消极气候影响）") + COUNTIFS(交通!A:A, 2004, 交通!G:G, "新目标") + COUNTIFS(交通!A:A, 2004, 交通!G:G, "强化或放宽目标（气候影响不明确）") + COUNTIFS(交通!A:A, 2004, 交通!G:G, "强化或放宽目标（积极气候影响）") + COUNTIFS(交通!A:A, 2004, 交通!G:G, "强化或放宽目标（消极气候影响）") + COUNTIFS('土地利用、土地利用变化和林业'!A:A, 2004, '土地利用、土地利用变化和林业'!G:G, "新目标") + COUNTIFS('土地利用、土地利用变化和林业'!A:A, 2004, '土地利用、土地利用变化和林业'!G:G, "强化或放宽目标（气候影响不明确）") + COUNTIFS('土地利用、土地利用变化和林业'!A:A, 2004, '土地利用、土地利用变化和林业'!G:G, "强化或放宽目标（积极气候影响）") + COUNTIFS('土地利用、土地利用变化和林业'!A:A, 2004, '土地利用、土地利用变化和林业'!G:G, "强化或放宽目标（消极气候影响）") + COUNTIFS(循环经济!A:A, 2004, 循环经济!G:G, "新目标") + COUNTIFS(循环经济!A:A, 2004, 循环经济!G:G, "强化或放宽目标（气候影响不明确）") + COUNTIFS(循环经济!A:A, 2004, 循环经济!G:G, "强化或放宽目标（积极气候影响）") + COUNTIFS(循环经济!A:A, 2004, 循环经济!G:G, "强化或放宽目标（消极气候影响）") + COUNTIFS(金融!A:A, 2004, 金融!G:G, "新目标") + COUNTIFS(金融!A:A, 2004, 金融!G:G, "强化或放宽目标（气候影响不明确）") + COUNTIFS(金融!A:A, 2004, 金融!G:G, "强化或放宽目标（积极气候影响）") + COUNTIFS(金融!A:A, 2004, 金融!G:G, "强化或放宽目标（消极气候影响）") | N6: 2007 | O6: =COUNTIFS(温室气体排放!F:F, 2007, 温室气体排放!G:G, "新目标") + COUNTIFS(温室气体排放!F:F, 2007, 温室气体排放!G:G, "强化或放宽目标（气候影响不明确）") + COUNTIFS(温室气体排放!F:F, 2007, 温室气体排放!G:G, "强化或放宽目标（积极气候影响）") + COUNTIFS(温室气体排放!F:F, 2007, 温室气体排放!G:G, "强化或放宽目标（消极气候影响）") + COUNTIFS(污染!F:F, 2007, 污染!G:G, "新目标") + COUNTIFS(污染!F:F, 2007, 污染!G:G, "强化或放宽目标（气候影响不明确）") + COUNTIFS(污染!F:F, 2007, 污染!G:G, "强化或放宽目标（积极气候影响）") + COUNTIFS(污染!F:F, 2007, 污染!G:G, "强化或放宽目标（消极气候影响）") + COUNTIFS('能源|电力'!F:F, 2007, '能源|电力'!G:G, "新目标") + COUNTIFS('能源|电力'!F:F, 2007, '能源|电力'!G:G, "强化或放宽目标（气候影响不明确）") + COUNTIFS('能源|电力'!F:F, 2007, '能源|电力'!G:G, "强化或放宽目标（积极气候影响）") + COUNTIFS('能源|电力'!F:F, 2007, '能源|电力'!G:G, "强化或放宽目标（消极气候影响）") + COUNTIFS(工业!F:F, 2007, 工业!G:G, "新目标") + COUNTIFS(工业!F:F, 2007, 工业!G:G, "强化或放宽目标（气候影响不明确）") + COUNTIFS(工业!F:F, 2007, 工业!G:G, "强化或放宽目标（积极气候影响）") + COUNTIFS(工业!F:F, 2007, 工业!G:G, "强化或放宽目标（消极气候影响）") + COUNTIFS(建筑!F:F, 2007, 建筑!G:G, "新目标") + COUNTIFS(建筑!F:F, 2007, 建筑!G:G, "强化或放宽目标（气候影响不明确）") + COUNTIFS(建筑!F:F, 2007, 建筑!G:G, "强化或放宽目标（积极气候影响）") + COUNTIFS(建筑!F:F, 2007, 建筑!G:G, "强化或放宽目标（消极气候影响）") + COUNTIFS(交通!F:F, 2007, 交通!G:G, "新目标") + COUNTIFS(交通!F:F, 2007, 交通!G:G, "强化或放宽目标（气候影响不明确）") + COUNTIFS(交通!F:F, 2007, 交通!G:G, "强化或放宽目标（积极气候影响）") + COUNTIFS(交通!F:F, 2007, 交通!G:G, "强化或放宽目标（消极气候影响）") + COUNTIFS('土地利用、土地利用变化和林业'!F:F, 2007, '土地利用、土地利用变化和林业'!G:G, "新目标") + COUNTIFS('土地利用、土地利用变化和林业'!F:F, 2007, '土地利用、土地利用变化和林业'!G:G, "强化或放宽目标（气候影响不明确）") + COUNTIFS('土地利用、土地利用变化和林业'!F:F, 2007, '土地利用、土地利用变化和林业'!G:G, "强化或放宽目标（积极气候影响）") + COUNTIFS('土地利用、土地利用变化和林业'!F:F, 2007, '土地利用、土地利用变化和林业'!G:G, "强化或放宽目标（消极气候影响）") + COUNTIFS(循环经济!F:F, 2007, 循环经济!G:G, "新目标") + COUNTIFS(循环经济!F:F, 2007, 循环经济!G:G, "强化或放宽目标（气候影响不明确）") + COUNTIFS(循环经济!F:F, 2007, 循环经济!G:G, "强化或放宽目标（积极气候影响）") + COUNTIFS(循环经济!F:F, 2007, 循环经济!G:G, "强化或放宽目标（消极气候影响）") + COUNTIFS(金融!F:F, 2007, 金融!G:G, "新目标") + COUNTIFS(金融!F:F, 2007, 金融!G:G, "强化或放宽目标（气候影响不明确）") + COUNTIFS(金融!F:F, 2007, 金融!G:G, "强化或放宽目标（积极气候影响）") + COUNTIFS(金融!F:F, 2007, 金融!G:G, "强化或放宽目标（消极气候影响）") | Q6: 碳减排 | R6: =COUNTIFS(温室气体排放!H:H, "碳减排", 温室气体排放!G:G, "新目标") + COUNTIFS(温室气体排放!H:H, "碳减排", 温室气体排放!G:G, "强化或放宽目标（气候影响不明确）") + COUNTIFS(温室气体排放!H:H, "碳减排", 温室气体排放!G:G, "强化或放宽目标（积极气候影响）") + COUNTIFS(温室气体排放!H:H, "碳减排", 温室气体排放!G:G, "强化或放宽目标（消极气候影响）") + COUNTIFS(污染!H:H, "碳减排", 污染!G:G, "新目标") + COUNTIFS(污染!H:H, "碳减排", 污染!G:G, "强化或放宽目标（气候影响不明确）") + COUNTIFS(污染!H:H, "碳减排", 污染!G:G, "强化或放宽目标（积极气候影响）") + COUNTIFS(污染!H:H, "碳减排", 污染!G:G, "强化或放宽目标（消极气候影响）") + COUNTIFS('能源|电力'!H:H, "碳减排", '能源|电力'!G:G, "新目标") + COUNTIFS('能源|电力'!H:H, "碳减排", '能源|电力'!G:G, "强化或放宽目标（气候影响不明确）") + COUNTIFS('能源|电力'!H:H, "碳减排", '能源|电力'!G:G, "强化或放宽目标（积极气候影响）") + COUNTIFS('能源|电力'!H:H, "碳减排", '能源|电力'!G:G, "强化或放宽目标（消极气候影响）") + COUNTIFS(工业!H:H, "碳减排", 工业!G:G, "新目标") + COUNTIFS(工业!H:H, "碳减排", 工业!G:G, "强化或放宽目标（气候影响不明确）") + COUNTIFS(工业!H:H, "碳减排", 工业!G:G, "强化或放宽目标（积极气候影响）") + COUNTIFS(工业!H:H, "碳减排", 工业!G:G, "强化或放宽目标（消极气候影响）") + COUNTIFS(建筑!H:H, "碳减排", 建筑!G:G, "新目标") + COUNTIFS(建筑!H:H, "碳减排", 建筑!G:G, "强化或放宽目标（气候影响不明确）") + COUNTIFS(建筑!H:H, "碳减排", 建筑!G:G, "强化或放宽目标（积极气候影响）") + COUNTIFS(建筑!H:H, "碳减排", 建筑!G:G, "强化或放宽目标（消极气候影响）") + COUNTIFS(交通!H:H, "碳减排", 交通!G:G, "新目标") + COUNTIFS(交通!H:H, "碳减排", 交通!G:G, "强化或放宽目标（气候影响不明确）") + COUNTIFS(交通!H:H, "碳减排", 交通!G:G, "强化或放宽目标（积极气候影响）") + COUNTIFS(交通!H:H, "碳减排", 交通!G:G, "强化或放宽目标（消极气候影响）") + COUNTIFS('土地利用、土地利用变化和林业'!H:H, "碳减排", '土地利用、土地利用变化和林业'!G:G, "新目标") + COUNTIFS('土地利用、土地利用变化和林业'!H:H, "碳减排", '土地利用、土地利用变化和林业'!G:G, "强化或放宽目标（气候影响不明确）") + COUNTIFS('土地利用、土地利用变化和林业'!H:H, "碳减排", '土地利用、土地利用变化和林业'!G:G, "强化或放宽目标（积极气候影响）") + COUNTIFS('土地利用、土地利用变化和林业'!H:H, "碳减排", '土地利用、土地利用变化和林业'!G:G, "强化或放宽目标（消极气候影响）") + COUNTIFS(循环经济!H:H, "碳减排", 循环经济!G:G, "新目标") + COUNTIFS(循环经济!H:H, "碳减排", 循环经济!G:G, "强化或放宽目标（气候影响不明确）") + COUNTIFS(循环经济!H:H, "碳减排", 循环经济!G:G, "强化或放宽目标（积极气候影响）") + COUNTIFS(循环经济!H:H, "碳减排", 循环经济!G:G, "强化或放宽目标（消极气候影响）") + COUNTIFS(金融!H:H, "碳减排", 金融!G:G, "新目标") + COUNTIFS(金融!H:H, "碳减排", 金融!G:G, "强化或放宽目标（气候影响不明确）") + COUNTIFS(金融!H:H, "碳减排", 金融!G:G, "强化或放宽目标（积极气候影响）") + COUNTIFS(金融!H:H, "碳减排", 金融!G:G, "强化或放宽目标（消极气候影响）") | T6: 企事业单位 | U6: =COUNTIFS(温室气体排放!I:I,"企业",温室气体排放!G:G,"新目标") +COUNTIFS(温室气体排放!I:I,"企业",温室气体排放!G:G,"强化或放宽目标（气候影响不明确）") +COUNTIFS(温室气体排放!I:I,"企业",温室气体排放!G:G,"强化或放宽目标（积极气候影响）") +COUNTIFS(温室气体排放!I:I,"企业",温室气体排放!G:G,"强化或放宽目标（消极气候影响）") +COUNTIFS(污染!I:I,"企业",污染!G:G,"新目标") +COUNTIFS(污染!I:I,"企业",污染!G:G,"强化或放宽目标（气候影响不明确）") +COUNTIFS(污染!I:I,"企业",污染!G:G,"强化或放宽目标（积极气候影响）") +COUNTIFS(污染!I:I,"企业",污染!G:G,"强化或放宽目标（消极气候影响）") +COUNTIFS('能源|电力'!I:I,"企业",'能源|电力'!G:G,"新目标") +COUNTIFS('能源|电力'!I:I,"企业",'能源|电力'!G:G,"强化或放宽目标（气候影响不明确）") +COUNTIFS('能源|电力'!I:I,"企业",'能源|电力'!G:G,"强化或放宽目标（积极气候影响）") +COUNTIFS('能源|电力'!I:I,"企业",'能源|电力'!G:G,"强化或放宽目标（消极气候影响）") +COUNTIFS(工业!I:I,"企业",工业!G:G,"新目标") +COUNTIFS(工业!I:I,"企业",工业!G:G,"强化或放宽目标（气候影响不明确）") +COUNTIFS(工业!I:I,"企业",工业!G:G,"强化或放宽目标（积极气候影响）") +COUNTIFS(工业!I:I,"企业",工业!G:G,"强化或放宽目标（消极气候影响）") +COUNTIFS(建筑!I:I,"企业",建筑!G:G,"新目标") +COUNTIFS(建筑!I:I,"企业",建筑!G:G,"强化或放宽目标（气候影响不明确）") +COUNTIFS(建筑!I:I,"企业",建筑!G:G,"强化或放宽目标（积极气候影响）") +COUNTIFS(建筑!I:I,"企业",建筑!G:G,"强化或放宽目标（消极气候影响）") +COUNTIFS(交通!I:I,"企业",交通!G:G,"新目标") +COUNTIFS(交通!I:I,"企业",交通!G:G,"强化或放宽目标（气候影响不明确）") +COUNTIFS(交通!I:I,"企业",交通!G:G,"强化或放宽目标（积极气候影响）") +COUNTIFS(交通!I:I,"企业",交通!G:G,"强化或放宽目标（消极气候影响）") +COUNTIFS('土地利用、土地利用变化和林业'!I:I,"企业",'土地利用、土地利用变化和林业'!G:G,"新目标") +COUNTIFS('土地利用、土地利用变化和林业'!I:I,"企业",'土地利用、土地利用变化和林业'!G:G,"强化或放宽目标（气候影响不明确）") +COUNTIFS('土地利用、土地利用变化和林业'!I:I,"企业",'土地利用、土地利用变化和林业'!G:G,"强化或放宽目标（积极气候影响）") +COUNTIFS('土地利用、土地利用变化和林业'!I:I,"企业",'土地利用、土地利用变化和林业'!G:G,"强化或放宽目标（消极气候影响）") +COUNTIFS(循环经济!I:I,"企业",循环经济!G:G,"新目标") +COUNTIFS(循环经济!I:I,"企业",循环经济!G:G,"强化或放宽目标（气候影响不明确）") +COUNTIFS(循环经济!I:I,"企业",循环经济!G:G,"强化或放宽目标（积极气候影响）") +COUNTIFS(循环经济!I:I,"企业",循环经济!G:G,"强化或放宽目标（消极气候影响）") +COUNTIFS(金融!I:I,"企业",金融!G:G,"新目标") +COUNTIFS(金融!I:I,"企业",金融!G:G,"强化或放宽目标（气候影响不明确）") +COUNTIFS(金融!I:I,"企业",金融!G:G,"强化或放宽目标（积极气候影响）") +COUNTIFS(金融!I:I,"企业",金融!G:G,"强化或放宽目标（消极气候影响）")
B7: 污染 | C7: =COUNTIFS(污染!G:G, "新目标") + COUNTIFS(污染!G:G, "强化或放宽目标（气候影响不明确）") + COUNTIFS(污染!G:G, "强化或放宽目标（积极气候影响）") + COUNTIFS(污染!G:G, "强化或放宽目标（消极气候影响）") | E7: 电力供应 | F7: =COUNTIFS('能源|电力'!M:M, "电力供应") | H7: 气候影响不明确的强化或放宽目标 | I7: =COUNTIF(温室气体排放!G:G,"强化或放宽目标（气候影响不明确）") +COUNTIF(污染!G:G,"强化或放宽目标（气候影响不明确）") +COUNTIF('能源|电力'!G:G,"强化或放宽目标（气候影响不明确）") +COUNTIF(工业!G:G,"强化或放宽目标（气候影响不明确）") +COUNTIF(建筑!G:G,"强化或放宽目标（气候影响不明确）") +COUNTIF(交通!G:G,"强化或放宽目标（气候影响不明确）") +COUNTIF('土地利用、土地利用变化和林业'!G:G,"强化或放宽目标（气候影响不明确）") +COUNTIF(循环经济!G:G,"强化或放宽目标（气候影响不明确）") +COUNTIF(金融!G:G,"强化或放宽目标（气候影响不明确）") | K7: 2005 | L7: =COUNTIFS(温室气体排放!A:A, 2005, 温室气体排放!G:G, "新目标") + COUNTIFS(温室气体排放!A:A, 2005, 温室气体排放!G:G, "强化或放宽目标（气候影响不明确）") + COUNTIFS(温室气体排放!A:A, 2005, 温室气体排放!G:G, "强化或放宽目标（积极气候影响）") + COUNTIFS(温室气体排放!A:A, 2005, 温室气体排放!G:G, "强化或放宽目标（消极气候影响）") + COUNTIFS(污染!A:A, 2005, 污染!G:G, "新目标") + COUNTIFS(污染!A:A, 2005, 污染!G:G, "强化或放宽目标（气候影响不明确）") + COUNTIFS(污染!A:A, 2005, 污染!G:G, "强化或放宽目标（积极气候影响）") + COUNTIFS(污染!A:A, 2005, 污染!G:G, "强化或放宽目标（消极气候影响）") + COUNTIFS('能源|电力'!A:A, 2005, '能源|电力'!G:G, "新目标") + COUNTIFS('能源|电力'!A:A, 2005, '能源|电力'!G:G, "强化或放宽目标（气候影响不明确）") + COUNTIFS('能源|电力'!A:A, 2005, '能源|电力'!G:G, "强化或放宽目标（积极气候影响）") + COUNTIFS('能源|电力'!A:A, 2005, '能源|电力'!G:G, "强化或放宽目标（消极气候影响）") + COUNTIFS(工业!A:A, 2005, 工业!G:G, "新目标") + COUNTIFS(工业!A:A, 2005, 工业!G:G, "强化或放宽目标（气候影响不明确）") + COUNTIFS(工业!A:A, 2005, 工业!G:G, "强化或放宽目标（积极气候影响）") + COUNTIFS(工业!A:A, 2005, 工业!G:G, "强化或放宽目标（消极气候影响）") + COUNTIFS(建筑!A:A, 2005, 建筑!G:G, "新目标") + COUNTIFS(建筑!A:A, 2005, 建筑!G:G, "强化或放宽目标（气候影响不明确）") + COUNTIFS(建筑!A:A, 2005, 建筑!G:G, "强化或放宽目标（积极气候影响）") + COUNTIFS(建筑!A:A, 2005, 建筑!G:G, "强化或放宽目标（消极气候影响）") + COUNTIFS(交通!A:A, 2005, 交通!G:G, "新目标") + COUNTIFS(交通!A:A, 2005, 交通!G:G, "强化或放宽目标（气候影响不明确）") + COUNTIFS(交通!A:A, 2005, 交通!G:G, "强化或放宽目标（积极气候影响）") + COUNTIFS(交通!A:A, 2005, 交通!G:G, "强化或放宽目标（消极气候影响）") + COUNTIFS('土地利用、土地利用变化和林业'!A:A, 2005, '土地利用、土地利用变化和林业'!G:G, "新目标") + COUNTIFS('土地利用、土地利用变化和林业'!A:A, 2005, '土地利用、土地利用变化和林业'!G:G, "强化或放宽目标（气候影响不明确）") + COUNTIFS('土地利用、土地利用变化和林业'!A:A, 2005, '土地利用、土地利用变化和林业'!G:G, "强化或放宽目标（积极气候影响）") + COUNTIFS('土地利用、土地利用变化和林业'!A:A, 2005, '土地利用、土地利用变化和林业'!G:G, "强化或放宽目标（消极气候影响）") + COUNTIFS(循环经济!A:A, 2005, 循环经济!G:G, "新目标") + COUNTIFS(循环经济!A:A, 2005, 循环经济!G:G, "强化或放宽目标（气候影响不明确）") + COUNTIFS(循环经济!A:A, 2005, 循环经济!G:G, "强化或放宽目标（积极气候影响）") + COUNTIFS(循环经济!A:A, 2005, 循环经济!G:G, "强化或放宽目标（消极气候影响）") + COUNTIFS(金融!A:A, 2005, 金融!G:G, "新目标") + COUNTIFS(金融!A:A, 2005, 金融!G:G, "强化或放宽目标（气候影响不明确）") + COUNTIFS(金融!A:A, 2005, 金融!G:G, "强化或放宽目标（积极气候影响）") + COUNTIFS(金融!A:A, 2005, 金融!G:G, "强化或放宽目标（消极气候影响）") | N7: 2008 | O7: =COUNTIFS(温室气体排放!F:F, 2008, 温室气体排放!G:G, "新目标") + COUNTIFS(温室气体排放!F:F, 2008, 温室气体排放!G:G, "强化或放宽目标（气候影响不明确）") + COUNTIFS(温室气体排放!F:F, 2008, 温室气体排放!G:G, "强化或放宽目标（积极气候影响）") + COUNTIFS(温室气体排放!F:F, 2008, 温室气体排放!G:G, "强化或放宽目标（消极气候影响）") + COUNTIFS(污染!F:F, 2008, 污染!G:G, "新目标") + COUNTIFS(污染!F:F, 2008, 污染!G:G, "强化或放宽目标（气候影响不明确）") + COUNTIFS(污染!F:F, 2008, 污染!G:G, "强化或放宽目标（积极气候影响）") + COUNTIFS(污染!F:F, 2008, 污染!G:G, "强化或放宽目标（消极气候影响）") + COUNTIFS('能源|电力'!F:F, 2008, '能源|电力'!G:G, "新目标") + COUNTIFS('能源|电力'!F:F, 2008, '能源|电力'!G:G, "强化或放宽目标（气候影响不明确）") + COUNTIFS('能源|电力'!F:F, 2008, '能源|电力'!G:G, "强化或放宽目标（积极气候影响）") + COUNTIFS('能源|电力'!F:F, 2008, '能源|电力'!G:G, "强化或放宽目标（消极气候影响）") + COUNTIFS(工业!F:F, 2008, 工业!G:G, "新目标") + COUNTIFS(工业!F:F, 2008, 工业!G:G, "强化或放宽目标（气候影响不明确）") + COUNTIFS(工业!F:F, 2008, 工业!G:G, "强化或放宽目标（积极气候影响）") + COUNTIFS(工业!F:F, 2008, 工业!G:G, "强化或放宽目标（消极气候影响）") + COUNTIFS(建筑!F:F, 2008, 建筑!G:G, "新目标") + COUNTIFS(建筑!F:F, 2008, 建筑!G:G, "强化或放宽目标（气候影响不明确）") + COUNTIFS(建筑!F:F, 2008, 建筑!G:G, "强化或放宽目标（积极气候影响）") + COUNTIFS(建筑!F:F, 2008, 建筑!G:G, "强化或放宽目标（消极气候影响）") + COUNTIFS(交通!F:F, 2008, 交通!G:G, "新目标") + COUNTIFS(交通!F:F, 2008, 交通!G:G, "强化或放宽目标（气候影响不明确）") + COUNTIFS(交通!F:F, 2008, 交通!G:G, "强化或放宽目标（积极气候影响）") + COUNTIFS(交通!F:F, 2008, 交通!G:G, "强化或放宽目标（消极气候影响）") + COUNTIFS('土地利用、土地利用变化和林业'!F:F, 2008, '土地利用、土地利用变化和林业'!G:G, "新目标") + COUNTIFS('土地利用、土地利用变化和林业'!F:F, 2008, '土地利用、土地利用变化和林业'!G:G, "强化或放宽目标（气候影响不明确）") + COUNTIFS('土地利用、土地利用变化和林业'!F:F, 2008, '土地利用、土地利用变化和林业'!G:G, "强化或放宽目标（积极气候影响）") + COUNTIFS('土地利用、土地利用变化和林业'!F:F, 2008, '土地利用、土地利用变化和林业'!G:G, "强化或放宽目标（消极气候影响）") + COUNTIFS(循环经济!F:F, 2008, 循环经济!G:G, "新目标") + COUNTIFS(循环经济!F:F, 2008, 循环经济!G:G, "强化或放宽目标（气候影响不明确）") + COUNTIFS(循环经济!F:F, 2008, 循环经济!G:G, "强化或放宽目标（积极气候影响）") + COUNTIFS(循环经济!F:F, 2008, 循环经济!G:G, "强化或放宽目标（消极气候影响）") + COUNTIFS(金融!F:F, 2008, 金融!G:G, "新目标") + COUNTIFS(金融!F:F, 2008, 金融!G:G, "强化或放宽目标（气候影响不明确）") + COUNTIFS(金融!F:F, 2008, 金融!G:G, "强化或放宽目标（积极气候影响）") + COUNTIFS(金融!F:F, 2008, 金融!G:G, "强化或放宽目标（消极气候影响）") | Q7: 碳强度 | R7: =COUNTIFS(温室气体排放!H:H, "碳强度", 温室气体排放!G:G, "新目标") + COUNTIFS(温室气体排放!H:H, "碳强度", 温室气体排放!G:G, "强化或放宽目标（气候影响不明确）") + COUNTIFS(温室气体排放!H:H, "碳强度", 温室气体排放!G:G, "强化或放宽目标（积极气候影响）") + COUNTIFS(温室气体排放!H:H, "碳强度", 温室气体排放!G:G, "强化或放宽目标（消极气候影响）") + COUNTIFS(污染!H:H, "碳强度", 污染!G:G, "新目标") + COUNTIFS(污染!H:H, "碳强度", 污染!G:G, "强化或放宽目标（气候影响不明确）") + COUNTIFS(污染!H:H, "碳强度", 污染!G:G, "强化或放宽目标（积极气候影响）") + COUNTIFS(污染!H:H, "碳强度", 污染!G:G, "强化或放宽目标（消极气候影响）") + COUNTIFS('能源|电力'!H:H, "碳强度", '能源|电力'!G:G, "新目标") + COUNTIFS('能源|电力'!H:H, "碳强度", '能源|电力'!G:G, "强化或放宽目标（气候影响不明确）") + COUNTIFS('能源|电力'!H:H, "碳强度", '能源|电力'!G:G, "强化或放宽目标（积极气候影响）") + COUNTIFS('能源|电力'!H:H, "碳强度", '能源|电力'!G:G, "强化或放宽目标（消极气候影响）") + COUNTIFS(工业!H:H, "碳强度", 工业!G:G, "新目标") + COUNTIFS(工业!H:H, "碳强度", 工业!G:G, "强化或放宽目标（气候影响不明确）") + COUNTIFS(工业!H:H, "碳强度", 工业!G:G, "强化或放宽目标（积极气候影响）") + COUNTIFS(工业!H:H, "碳强度", 工业!G:G, "强化或放宽目标（消极气候影响）") + COUNTIFS(建筑!H:H, "碳强度", 建筑!G:G, "新目标") + COUNTIFS(建筑!H:H, "碳强度", 建筑!G:G, "强化或放宽目标（气候影响不明确）") + COUNTIFS(建筑!H:H, "碳强度", 建筑!G:G, "强化或放宽目标（积极气候影响）") + COUNTIFS(建筑!H:H, "碳强度", 建筑!G:G, "强化或放宽目标（消极气候影响）") + COUNTIFS(交通!H:H, "碳强度", 交通!G:G, "新目标") + COUNTIFS(交通!H:H, "碳强度", 交通!G:G, "强化或放宽目标（气候影响不明确）") + COUNTIFS(交通!H:H, "碳强度", 交通!G:G, "强化或放宽目标（积极气候影响）") + COUNTIFS(交通!H:H, "碳强度", 交通!G:G, "强化或放宽目标（消极气候影响）") + COUNTIFS('土地利用、土地利用变化和林业'!H:H, "碳强度", '土地利用、土地利用变化和林业'!G:G, "新目标") + COUNTIFS('土地利用、土地利用变化和林业'!H:H, "碳强度", '土地利用、土地利用变化和林业'!G:G, "强化或放宽目标（气候影响不明确）") + COUNTIFS('土地利用、土地利用变化和林业'!H:H, "碳强度", '土地利用、土地利用变化和林业'!G:G, "强化或放宽目标（积极气候影响）") + COUNTIFS('土地利用、土地利用变化和林业'!H:H, "碳强度", '土地利用、土地利用变化和林业'!G:G, "强化或放宽目标（消极气候影响）") + COUNTIFS(循环经济!H:H, "碳强度", 循环经济!G:G, "新目标") + COUNTIFS(循环经济!H:H, "碳强度", 循环经济!G:G, "强化或放宽目标（气候影响不明确）") + COUNTIFS(循环经济!H:H, "碳强度", 循环经济!G:G, "强化或放宽目标（积极气候影响）") + COUNTIFS(循环经济!H:H, "碳强度", 循环经济!G:G, "强化或放宽目标（消极气候影响）") + COUNTIFS(金融!H:H, "碳强度", 金融!G:G, "新目标") + COUNTIFS(金融!H:H, "碳强度", 金融!G:G, "强化或放宽目标（气候影响不明确）") + COUNTIFS(金融!H:H, "碳强度", 金融!G:G, "强化或放宽目标（积极气候影响）") + COUNTIFS(金融!H:H, "碳强度", 金融!G:G, "强化或放宽目标（消极气候影响）") | T7: 城市与地区 | U7: =COUNTIFS(温室气体排放!I:I,"地区",温室气体排放!G:G,"新目标") +COUNTIFS(温室气体排放!I:I,"地区",温室气体排放!G:G,"强化或放宽目标（气候影响不明确）") +COUNTIFS(温室气体排放!I:I,"地区",温室气体排放!G:G,"强化或放宽目标（积极气候影响）") +COUNTIFS(温室气体排放!I:I,"地区",温室气体排放!G:G,"强化或放宽目标（消极气候影响）") +COUNTIFS(污染!I:I,"地区",污染!G:G,"新目标") +COUNTIFS(污染!I:I,"地区",污染!G:G,"强化或放宽目标（气候影响不明确）") +COUNTIFS(污染!I:I,"地区",污染!G:G,"强化或放宽目标（积极气候影响）") +COUNTIFS(污染!I:I,"地区",污染!G:G,"强化或放宽目标（消极气候影响）") +COUNTIFS('能源|电力'!I:I,"地区",'能源|电力'!G:G,"新目标") +COUNTIFS('能源|电力'!I:I,"地区",'能源|电力'!G:G,"强化或放宽目标（气候影响不明确）") +COUNTIFS('能源|电力'!I:I,"地区",'能源|电力'!G:G,"强化或放宽目标（积极气候影响）") +COUNTIFS('能源|电力'!I:I,"地区",'能源|电力'!G:G,"强化或放宽目标（消极气候影响）") +COUNTIFS(工业!I:I,"地区",工业!G:G,"新目标") +COUNTIFS(工业!I:I,"地区",工业!G:G,"强化或放宽目标（气候影响不明确）") +COUNTIFS(工业!I:I,"地区",工业!G:G,"强化或放宽目标（积极气候影响）") +COUNTIFS(工业!I:I,"地区",工业!G:G,"强化或放宽目标（消极气候影响）") +COUNTIFS(建筑!I:I,"地区",建筑!G:G,"新目标") +COUNTIFS(建筑!I:I,"地区",建筑!G:G,"强化或放宽目标（气候影响不明确）") +COUNTIFS(建筑!I:I,"地区",建筑!G:G,"强化或放宽目标（积极气候影响）") +COUNTIFS(建筑!I:I,"地区",建筑!G:G,"强化或放宽目标（消极气候影响）") +COUNTIFS(交通!I:I,"地区",交通!G:G,"新目标") +COUNTIFS(交通!I:I,"地区",交通!G:G,"强化或放宽目标（气候影响不明确）") +COUNTIFS(交通!I:I,"地区",交通!G:G,"强化或放宽目标（积极气候影响）") +COUNTIFS(交通!I:I,"地区",交通!G:G,"强化或放宽目标（消极气候影响）") +COUNTIFS('土地利用、土地利用变化和林业'!I:I,"地区",'土地利用、土地利用变化和林业'!G:G,"新目标") +COUNTIFS('土地利用、土地利用变化和林业'!I:I,"地区",'土地利用、土地利用变化和林业'!G:G,"强化或放宽目标（气候影响不明确）") +COUNTIFS('土地利用、土地利用变化和林业'!I:I,"地区",'土地利用、土地利用变化和林业'!G:G,"强化或放宽目标（积极气候影响）") +COUNTIFS('土地利用、土地利用变化和林业'!I:I,"地区",'土地利用、土地利用变化和林业'!G:G,"强化或放宽目标（消极气候影响）") +COUNTIFS(循环经济!I:I,"地区",循环经济!G:G,"新目标") +COUNTIFS(循环经济!I:I,"地区",循环经济!G:G,"强化或放宽目标（气候影响不明确）") +COUNTIFS(循环经济!I:I,"地区",循环经济!G:G,"强化或放宽目标（积极气候影响）") +COUNTIFS(循环经济!I:I,"地区",循环经济!G:G,"强化或放宽目标（消极气候影响）") +COUNTIFS(金融!I:I,"地区",金融!G:G,"新目标") +COUNTIFS(金融!I:I,"地区",金融!G:G,"强化或放宽目标（气候影响不明确）") +COUNTIFS(金融!I:I,"地区",金融!G:G,"强化或放宽目标（积极气候影响）") +COUNTIFS(金融!I:I,"地区",金融!G:G,"强化或放宽目标（消极气候影响）")
B8: 能源|电力 | C8: =COUNTIFS('能源|电力'!G:G, "新目标") + COUNTIFS('能源|电力'!G:G, "强化或放宽目标（气候影响不明确）") + COUNTIFS('能源|电力'!G:G, "强化或放宽目标（积极气候影响）") + COUNTIFS('能源|电力'!G:G, "强化或放宽目标（消极气候影响）") | E8: 电力传输/能源运输 | F8: =COUNTIFS('能源|电力'!M:M, "电力传输/能源运输") | H8: 具有积极气候影响的强化或放宽目标 | I8: =COUNTIF(温室气体排放!G:G,"强化或放宽目标（积极气候影响）") +COUNTIF(污染!G:G,"强化或放宽目标（积极气候影响）") +COUNTIF('能源|电力'!G:G,"强化或放宽目标（积极气候影响）") +COUNTIF(工业!G:G,"强化或放宽目标（积极气候影响）") +COUNTIF(建筑!G:G,"强化或放宽目标（积极气候影响）") +COUNTIF(交通!G:G,"强化或放宽目标（积极气候影响）") +COUNTIF('土地利用、土地利用变化和林业'!G:G,"强化或放宽目标（积极气候影响）") +COUNTIF(循环经济!G:G,"强化或放宽目标（积极气候影响）") +COUNTIF(金融!G:G,"强化或放宽目标（积极气候影响）") | K8: 2006 | L8: =COUNTIFS(温室气体排放!A:A, 2006, 温室气体排放!G:G, "新目标") + COUNTIFS(温室气体排放!A:A, 2006, 温室气体排放!G:G, "强化或放宽目标（气候影响不明确）") + COUNTIFS(温室气体排放!A:A, 2006, 温室气体排放!G:G, "强化或放宽目标（积极气候影响）") + COUNTIFS(温室气体排放!A:A, 2006, 温室气体排放!G:G, "强化或放宽目标（消极气候影响）") + COUNTIFS(污染!A:A, 2006, 污染!G:G, "新目标") + COUNTIFS(污染!A:A, 2006, 污染!G:G, "强化或放宽目标（气候影响不明确）") + COUNTIFS(污染!A:A, 2006, 污染!G:G, "强化或放宽目标（积极气候影响）") + COUNTIFS(污染!A:A, 2006, 污染!G:G, "强化或放宽目标（消极气候影响）") + COUNTIFS('能源|电力'!A:A, 2006, '能源|电力'!G:G, "新目标") + COUNTIFS('能源|电力'!A:A, 2006, '能源|电力'!G:G, "强化或放宽目标（气候影响不明确）") + COUNTIFS('能源|电力'!A:A, 2006, '能源|电力'!G:G, "强化或放宽目标（积极气候影响）") + COUNTIFS('能源|电力'!A:A, 2006, '能源|电力'!G:G, "强化或放宽目标（消极气候影响）") + COUNTIFS(工业!A:A, 2006, 工业!G:G, "新目标") + COUNTIFS(工业!A:A, 2006, 工业!G:G, "强化或放宽目标（气候影响不明确）") + COUNTIFS(工业!A:A, 2006, 工业!G:G, "强化或放宽目标（积极气候影响）") + COUNTIFS(工业!A:A, 2006, 工业!G:G, "强化或放宽目标（消极气候影响）") + COUNTIFS(建筑!A:A, 2006, 建筑!G:G, "新目标") + COUNTIFS(建筑!A:A, 2006, 建筑!G:G, "强化或放宽目标（气候影响不明确）") + COUNTIFS(建筑!A:A, 2006, 建筑!G:G, "强化或放宽目标（积极气候影响）") + COUNTIFS(建筑!A:A, 2006, 建筑!G:G, "强化或放宽目标（消极气候影响）") + COUNTIFS(交通!A:A, 2006, 交通!G:G, "新目标") + COUNTIFS(交通!A:A, 2006, 交通!G:G, "强化或放宽目标（气候影响不明确）") + COUNTIFS(交通!A:A, 2006, 交通!G:G, "强化或放宽目标（积极气候影响）") + COUNTIFS(交通!A:A, 2006, 交通!G:G, "强化或放宽目标（消极气候影响）") + COUNTIFS('土地利用、土地利用变化和林业'!A:A, 2006, '土地利用、土地利用变化和林业'!G:G, "新目标") + COUNTIFS('土地利用、土地利用变化和林业'!A:A, 2006, '土地利用、土地利用变化和林业'!G:G, "强化或放宽目标（气候影响不明确）") + COUNTIFS('土地利用、土地利用变化和林业'!A:A, 2006, '土地利用、土地利用变化和林业'!G:G, "强化或放宽目标（积极气候影响）") + COUNTIFS('土地利用、土地利用变化和林业'!A:A, 2006, '土地利用、土地利用变化和林业'!G:G, "强化或放宽目标（消极气候影响）") + COUNTIFS(循环经济!A:A, 2006, 循环经济!G:G, "新目标") + COUNTIFS(循环经济!A:A, 2006, 循环经济!G:G, "强化或放宽目标（气候影响不明确）") + COUNTIFS(循环经济!A:A, 2006, 循环经济!G:G, "强化或放宽目标（积极气候影响）") + COUNTIFS(循环经济!A:A, 2006, 循环经济!G:G, "强化或放宽目标（消极气候影响）") + COUNTIFS(金融!A:A, 2006, 金融!G:G, "新目标") + COUNTIFS(金融!A:A, 2006, 金融!G:G, "强化或放宽目标（气候影响不明确）") + COUNTIFS(金融!A:A, 2006, 金融!G:G, "强化或放宽目标（积极气候影响）") + COUNTIFS(金融!A:A, 2006, 金融!G:G, "强化或放宽目标（消极气候影响）") | N8: 2010 | O8: =COUNTIFS(温室气体排放!F:F, 2010, 温室气体排放!G:G, "新目标") + COUNTIFS(温室气体排放!F:F, 2010, 温室气体排放!G:G, "强化或放宽目标（气候影响不明确）") + COUNTIFS(温室气体排放!F:F, 2010, 温室气体排放!G:G, "强化或放宽目标（积极气候影响）") + COUNTIFS(温室气体排放!F:F, 2010, 温室气体排放!G:G, "强化或放宽目标（消极气候影响）") + COUNTIFS(污染!F:F, 2010, 污染!G:G, "新目标") + COUNTIFS(污染!F:F, 2010, 污染!G:G, "强化或放宽目标（气候影响不明确）") + COUNTIFS(污染!F:F, 2010, 污染!G:G, "强化或放宽目标（积极气候影响）") + COUNTIFS(污染!F:F, 2010, 污染!G:G, "强化或放宽目标（消极气候影响）") + COUNTIFS('能源|电力'!F:F, 2010, '能源|电力'!G:G, "新目标") + COUNTIFS('能源|电力'!F:F, 2010, '能源|电力'!G:G, "强化或放宽目标（气候影响不明确）") + COUNTIFS('能源|电力'!F:F, 2010, '能源|电力'!G:G, "强化或放宽目标（积极气候影响）") + COUNTIFS('能源|电力'!F:F, 2010, '能源|电力'!G:G, "强化或放宽目标（消极气候影响）") + COUNTIFS(工业!F:F, 2010, 工业!G:G, "新目标") + COUNTIFS(工业!F:F, 2010, 工业!G:G, "强化或放宽目标（气候影响不明确）") + COUNTIFS(工业!F:F, 2010, 工业!G:G, "强化或放宽目标（积极气候影响）") + COUNTIFS(工业!F:F, 2010, 工业!G:G, "强化或放宽目标（消极气候影响）") + COUNTIFS(建筑!F:F, 2010, 建筑!G:G, "新目标") + COUNTIFS(建筑!F:F, 2010, 建筑!G:G, "强化或放宽目标（气候影响不明确）") + COUNTIFS(建筑!F:F, 2010, 建筑!G:G, "强化或放宽目标（积极气候影响）") + COUNTIFS(建筑!F:F, 2010, 建筑!G:G, "强化或放宽目标（消极气候影响）") + COUNTIFS(交通!F:F, 2010, 交通!G:G, "新目标") + COUNTIFS(交通!F:F, 2010, 交通!G:G, "强化或放宽目标（气候影响不明确）") + COUNTIFS(交通!F:F, 2010, 交通!G:G, "强化或放宽目标（积极气候影响）") + COUNTIFS(交通!F:F, 2010, 交通!G:G, "强化或放宽目标（消极气候影响）") + COUNTIFS('土地利用、土地利用变化和林业'!F:F, 2010, '土地利用、土地利用变化和林业'!G:G, "新目标") + COUNTIFS('土地利用、土地利用变化和林业'!F:F, 2010, '土地利用、土地利用变化和林业'!G:G, "强化或放宽目标（气候影响不明确）") + COUNTIFS('土地利用、土地利用变化和林业'!F:F, 2010, '土地利用、土地利用变化和林业'!G:G, "强化或放宽目标（积极气候影响）") + COUNTIFS('土地利用、土地利用变化和林业'!F:F, 2010, '土地利用、土地利用变化和林业'!G:G, "强化或放宽目标（消极气候影响）") + COUNTIFS(循环经济!F:F, 2010, 循环经济!G:G, "新目标") + COUNTIFS(循环经济!F:F, 2010, 循环经济!G:G, "强化或放宽目标（气候影响不明确）") + COUNTIFS(循环经济!F:F, 2010, 循环经济!G:G, "强化或放宽目标（积极气候影响）") + COUNTIFS(循环经济!F:F, 2010, 循环经济!G:G, "强化或放宽目标（消极气候影响）") + COUNTIFS(金融!F:F, 2010, 金融!G:G, "新目标") + COUNTIFS(金融!F:F, 2010, 金融!G:G, "强化或放宽目标（气候影响不明确）") + COUNTIFS(金融!F:F, 2010, 金融!G:G, "强化或放宽目标（积极气候影响）") + COUNTIFS(金融!F:F, 2010, 金融!G:G, "强化或放宽目标（消极气候影响）") | Q8: 碳汇 | R8: =COUNTIFS(温室气体排放!H:H, "碳汇", 温室气体排放!G:G, "新目标") + COUNTIFS(温室气体排放!H:H, "碳汇", 温室气体排放!G:G, "强化或放宽目标（气候影响不明确）") + COUNTIFS(温室气体排放!H:H, "碳汇", 温室气体排放!G:G, "强化或放宽目标（积极气候影响）") + COUNTIFS(温室气体排放!H:H, "碳汇", 温室气体排放!G:G, "强化或放宽目标（消极气候影响）") + COUNTIFS(污染!H:H, "碳汇", 污染!G:G, "新目标") + COUNTIFS(污染!H:H, "碳汇", 污染!G:G, "强化或放宽目标（气候影响不明确）") + COUNTIFS(污染!H:H, "碳汇", 污染!G:G, "强化或放宽目标（积极气候影响）") + COUNTIFS(污染!H:H, "碳汇", 污染!G:G, "强化或放宽目标（消极气候影响）") + COUNTIFS('能源|电力'!H:H, "碳汇", '能源|电力'!G:G, "新目标") + COUNTIFS('能源|电力'!H:H, "碳汇", '能源|电力'!G:G, "强化或放宽目标（气候影响不明确）") + COUNTIFS('能源|电力'!H:H, "碳汇", '能源|电力'!G:G, "强化或放宽目标（积极气候影响）") + COUNTIFS('能源|电力'!H:H, "碳汇", '能源|电力'!G:G, "强化或放宽目标（消极气候影响）") + COUNTIFS(工业!H:H, "碳汇", 工业!G:G, "新目标") + COUNTIFS(工业!H:H, "碳汇", 工业!G:G, "强化或放宽目标（气候影响不明确）") + COUNTIFS(工业!H:H, "碳汇", 工业!G:G, "强化或放宽目标（积极气候影响）") + COUNTIFS(工业!H:H, "碳汇", 工业!G:G, "强化或放宽目标（消极气候影响）") + COUNTIFS(建筑!H:H, "碳汇", 建筑!G:G, "新目标") + COUNTIFS(建筑!H:H, "碳汇", 建筑!G:G, "强化或放宽目标（气候影响不明确）") + COUNTIFS(建筑!H:H, "碳汇", 建筑!G:G, "强化或放宽目标（积极气候影响）") + COUNTIFS(建筑!H:H, "碳汇", 建筑!G:G, "强化或放宽目标（消极气候影响）") + COUNTIFS(交通!H:H, "碳汇", 交通!G:G, "新目标") + COUNTIFS(交通!H:H, "碳汇", 交通!G:G, "强化或放宽目标（气候影响不明确）") + COUNTIFS(交通!H:H, "碳汇", 交通!G:G, "强化或放宽目标（积极气候影响）") + COUNTIFS(交通!H:H, "碳汇", 交通!G:G, "强化或放宽目标（消极气候影响）") + COUNTIFS('土地利用、土地利用变化和林业'!H:H, "碳汇", '土地利用、土地利用变化和林业'!G:G, "新目标") + COUNTIFS('土地利用、土地利用变化和林业'!H:H, "碳汇", '土地利用、土地利用变化和林业'!G:G, "强化或放宽目标（气候影响不明确）") + COUNTIFS('土地利用、土地利用变化和林业'!H:H, "碳汇", '土地利用、土地利用变化和林业'!G:G, "强化或放宽目标（积极气候影响）") + COUNTIFS('土地利用、土地利用变化和林业'!H:H, "碳汇", '土地利用、土地利用变化和林业'!G:G, "强化或放宽目标（消极气候影响）") + COUNTIFS(循环经济!H:H, "碳汇", 循环经济!G:G, "新目标") + COUNTIFS(循环经济!H:H, "碳汇", 循环经济!G:G, "强化或放宽目标（气候影响不明确）") + COUNTIFS(循环经济!H:H, "碳汇", 循环经济!G:G, "强化或放宽目标（积极气候影响）") + COUNTIFS(循环经济!H:H, "碳汇", 循环经济!G:G, "强化或放宽目标（消极气候影响）") + COUNTIFS(金融!H:H, "碳汇", 金融!G:G, "新目标") + COUNTIFS(金融!H:H, "碳汇", 金融!G:G, "强化或放宽目标（气候影响不明确）") + COUNTIFS(金融!H:H, "碳汇", 金融!G:G, "强化或放宽目标（积极气候影响）") + COUNTIFS(金融!H:H, "碳汇", 金融!G:G, "强化或放宽目标（消极气候影响）") | T8: 行业 | U8: =COUNTIFS(温室气体排放!I:I,"行业",温室气体排放!G:G,"新目标") +COUNTIFS(温室气体排放!I:I,"行业",温室气体排放!G:G,"强化或放宽目标（气候影响不明确）") +COUNTIFS(温室气体排放!I:I,"行业",温室气体排放!G:G,"强化或放宽目标（积极气候影响）") +COUNTIFS(温室气体排放!I:I,"行业",温室气体排放!G:G,"强化或放宽目标（消极气候影响）") +COUNTIFS(污染!I:I,"行业",污染!G:G,"新目标") +COUNTIFS(污染!I:I,"行业",污染!G:G,"强化或放宽目标（气候影响不明确）") +COUNTIFS(污染!I:I,"行业",污染!G:G,"强化或放宽目标（积极气候影响）") +COUNTIFS(污染!I:I,"行业",污染!G:G,"强化或放宽目标（消极气候影响）") +COUNTIFS('能源|电力'!I:I,"行业",'能源|电力'!G:G,"新目标") +COUNTIFS('能源|电力'!I:I,"行业",'能源|电力'!G:G,"强化或放宽目标（气候影响不明确）") +COUNTIFS('能源|电力'!I:I,"行业",'能源|电力'!G:G,"强化或放宽目标（积极气候影响）") +COUNTIFS('能源|电力'!I:I,"行业",'能源|电力'!G:G,"强化或放宽目标（消极气候影响）") +COUNTIFS(工业!I:I,"行业",工业!G:G,"新目标") +COUNTIFS(工业!I:I,"行业",工业!G:G,"强化或放宽目标（气候影响不明确）") +COUNTIFS(工业!I:I,"行业",工业!G:G,"强化或放宽目标（积极气候影响）") +COUNTIFS(工业!I:I,"行业",工业!G:G,"强化或放宽目标（消极气候影响）") +COUNTIFS(建筑!I:I,"行业",建筑!G:G,"新目标") +COUNTIFS(建筑!I:I,"行业",建筑!G:G,"强化或放宽目标（气候影响不明确）") +COUNTIFS(建筑!I:I,"行业",建筑!G:G,"强化或放宽目标（积极气候影响）") +COUNTIFS(建筑!I:I,"行业",建筑!G:G,"强化或放宽目标（消极气候影响）") +COUNTIFS(交通!I:I,"行业",交通!G:G,"新目标") +COUNTIFS(交通!I:I,"行业",交通!G:G,"强化或放宽目标（气候影响不明确）") +COUNTIFS(交通!I:I,"行业",交通!G:G,"强化或放宽目标（积极气候影响）") +COUNTIFS(交通!I:I,"行业",交通!G:G,"强化或放宽目标（消极气候影响）") +COUNTIFS('土地利用、土地利用变化和林业'!I:I,"行业",'土地利用、土地利用变化和林业'!G:G,"新目标") +COUNTIFS('土地利用、土地利用变化和林业'!I:I,"行业",'土地利用、土地利用变化和林业'!G:G,"强化或放宽目标（气候影响不明确）") +COUNTIFS('土地利用、土地利用变化和林业'!I:I,"行业",'土地利用、土地利用变化和林业'!G:G,"强化或放宽目标（积极气候影响）") +COUNTIFS('土地利用、土地利用变化和林业'!I:I,"行业",'土地利用、土地利用变化和林业'!G:G,"强化或放宽目标（消极气候影响）") +COUNTIFS(循环经济!I:I,"行业",循环经济!G:G,"新目标") +COUNTIFS(循环经济!I:I,"行业",循环经济!G:G,"强化或放宽目标（气候影响不明确）") +COUNTIFS(循环经济!I:I,"行业",循环经济!G:G,"强化或放宽目标（积极气候影响）") +COUNTIFS(循环经济!I:I,"行业",循环经济!G:G,"强化或放宽目标（消极气候影响）") +COUNTIFS(金融!I:I,"行业",金融!G:G,"新目标") +COUNTIFS(金融!I:I,"行业",金融!G:G,"强化或放宽目标（气候影响不明确）") +COUNTIFS(金融!I:I,"行业",金融!G:G,"强化或放宽目标（积极气候影响）") +COUNTIFS(金融!I:I,"行业",金融!G:G,"强化或放宽目标（消极气候影响）")
B9: 工业 | C9: =COUNTIFS(工业!G:G, "新目标") + COUNTIFS(工业!G:G, "强化或放宽目标（气候影响不明确）") + COUNTIFS(工业!G:G, "强化或放宽目标（积极气候影响）") + COUNTIFS(工业!G:G, "强化或放宽目标（消极气候影响）") | E9: 煤电 | F9: =COUNTIFS('能源|电力'!M:M, "煤电") | H9: 具有消极气候影响的强化或放宽目标 | I9: =COUNTIF(温室气体排放!G:G,"强化或放宽目标（消极气候影响）") +COUNTIF(污染!G:G,"强化或放宽目标（消极气候影响）") +COUNTIF('能源|电力'!G:G,"强化或放宽目标（消极气候影响）") +COUNTIF(工业!G:G,"强化或放宽目标（消极气候影响）") +COUNTIF(建筑!G:G,"强化或放宽目标（消极气候影响）") +COUNTIF(交通!G:G,"强化或放宽目标（消极气候影响）") +COUNTIF('土地利用、土地利用变化和林业'!G:G,"强化或放宽目标（消极气候影响）") +COUNTIF(循环经济!G:G,"强化或放宽目标（消极气候影响）") +COUNTIF(金融!G:G,"强化或放宽目标（消极气候影响）") | K9: 2007 | L9: =COUNTIFS(温室气体排放!A:A, 2007, 温室气体排放!G:G, "新目标") + COUNTIFS(温室气体排放!A:A, 2007, 温室气体排放!G:G, "强化或放宽目标（气候影响不明确）") + COUNTIFS(温室气体排放!A:A, 2007, 温室气体排放!G:G, "强化或放宽目标（积极气候影响）") + COUNTIFS(温室气体排放!A:A, 2007, 温室气体排放!G:G, "强化或放宽目标（消极气候影响）") + COUNTIFS(污染!A:A, 2007, 污染!G:G, "新目标") + COUNTIFS(污染!A:A, 2007, 污染!G:G, "强化或放宽目标（气候影响不明确）") + COUNTIFS(污染!A:A, 2007, 污染!G:G, "强化或放宽目标（积极气候影响）") + COUNTIFS(污染!A:A, 2007, 污染!G:G, "强化或放宽目标（消极气候影响）") + COUNTIFS('能源|电力'!A:A, 2007, '能源|电力'!G:G, "新目标") + COUNTIFS('能源|电力'!A:A, 2007, '能源|电力'!G:G, "强化或放宽目标（气候影响不明确）") + COUNTIFS('能源|电力'!A:A, 2007, '能源|电力'!G:G, "强化或放宽目标（积极气候影响）") + COUNTIFS('能源|电力'!A:A, 2007, '能源|电力'!G:G, "强化或放宽目标（消极气候影响）") + COUNTIFS(工业!A:A, 2007, 工业!G:G, "新目标") + COUNTIFS(工业!A:A, 2007, 工业!G:G, "强化或放宽目标（气候影响不明确）") + COUNTIFS(工业!A:A, 2007, 工业!G:G, "强化或放宽目标（积极气候影响）") + COUNTIFS(工业!A:A, 2007, 工业!G:G, "强化或放宽目标（消极气候影响）") + COUNTIFS(建筑!A:A, 2007, 建筑!G:G, "新目标") + COUNTIFS(建筑!A:A, 2007, 建筑!G:G, "强化或放宽目标（气候影响不明确）") + COUNTIFS(建筑!A:A, 2007, 建筑!G:G, "强化或放宽目标（积极气候影响）") + COUNTIFS(建筑!A:A, 2007, 建筑!G:G, "强化或放宽目标（消极气候影响）") + COUNTIFS(交通!A:A, 2007, 交通!G:G, "新目标") + COUNTIFS(交通!A:A, 2007, 交通!G:G, "强化或放宽目标（气候影响不明确）") + COUNTIFS(交通!A:A, 2007, 交通!G:G, "强化或放宽目标（积极气候影响）") + COUNTIFS(交通!A:A, 2007, 交通!G:G, "强化或放宽目标（消极气候影响）") + COUNTIFS('土地利用、土地利用变化和林业'!A:A, 2007, '土地利用、土地利用变化和林业'!G:G, "新目标") + COUNTIFS('土地利用、土地利用变化和林业'!A:A, 2007, '土地利用、土地利用变化和林业'!G:G, "强化或放宽目标（气候影响不明确）") + COUNTIFS('土地利用、土地利用变化和林业'!A:A, 2007, '土地利用、土地利用变化和林业'!G:G, "强化或放宽目标（积极气候影响）") + COUNTIFS('土地利用、土地利用变化和林业'!A:A, 2007, '土地利用、土地利用变化和林业'!G:G, "强化或放宽目标（消极气候影响）") + COUNTIFS(循环经济!A:A, 2007, 循环经济!G:G, "新目标") + COUNTIFS(循环经济!A:A, 2007, 循环经济!G:G, "强化或放宽目标（气候影响不明确）") + COUNTIFS(循环经济!A:A, 2007, 循环经济!G:G, "强化或放宽目标（积极气候影响）") + COUNTIFS(循环经济!A:A, 2007, 循环经济!G:G, "强化或放宽目标（消极气候影响）") + COUNTIFS(金融!A:A, 2007, 金融!G:G, "新目标") + COUNTIFS(金融!A:A, 2007, 金融!G:G, "强化或放宽目标（气候影响不明确）") + COUNTIFS(金融!A:A, 2007, 金融!G:G, "强化或放宽目标（积极气候影响）") + COUNTIFS(金融!A:A, 2007, 金融!G:G, "强化或放宽目标（消极气候影响）") | N9: 十一五 | O9: =COUNTIFS(温室气体排放!F:F, "十一五", 温室气体排放!G:G, "新目标") + COUNTIFS(温室气体排放!F:F, "十一五", 温室气体排放!G:G, "强化或放宽目标（气候影响不明确）") + COUNTIFS(温室气体排放!F:F, "十一五", 温室气体排放!G:G, "强化或放宽目标（积极气候影响）") + COUNTIFS(温室气体排放!F:F, "十一五", 温室气体排放!G:G, "强化或放宽目标（消极气候影响）") + COUNTIFS(污染!F:F, "十一五", 污染!G:G, "新目标") + COUNTIFS(污染!F:F, "十一五", 污染!G:G, "强化或放宽目标（气候影响不明确）") + COUNTIFS(污染!F:F, "十一五", 污染!G:G, "强化或放宽目标（积极气候影响）") + COUNTIFS(污染!F:F, "十一五", 污染!G:G, "强化或放宽目标（消极气候影响）") + COUNTIFS('能源|电力'!F:F, "十一五", '能源|电力'!G:G, "新目标") + COUNTIFS('能源|电力'!F:F, "十一五", '能源|电力'!G:G, "强化或放宽目标（气候影响不明确）") + COUNTIFS('能源|电力'!F:F, "十一五", '能源|电力'!G:G, "强化或放宽目标（积极气候影响）") + COUNTIFS('能源|电力'!F:F, "十一五", '能源|电力'!G:G, "强化或放宽目标（消极气候影响）") + COUNTIFS(工业!F:F, "十一五", 工业!G:G, "新目标") + COUNTIFS(工业!F:F, "十一五", 工业!G:G, "强化或放宽目标（气候影响不明确）") + COUNTIFS(工业!F:F, "十一五", 工业!G:G, "强化或放宽目标（积极气候影响）") + COUNTIFS(工业!F:F, "十一五", 工业!G:G, "强化或放宽目标（消极气候影响）") + COUNTIFS(建筑!F:F, "十一五", 建筑!G:G, "新目标") + COUNTIFS(建筑!F:F, "十一五", 建筑!G:G, "强化或放宽目标（气候影响不明确）") + COUNTIFS(建筑!F:F, "十一五", 建筑!G:G, "强化或放宽目标（积极气候影响）") + COUNTIFS(建筑!F:F, "十一五", 建筑!G:G, "强化或放宽目标（消极气候影响）") + COUNTIFS(交通!F:F, "十一五", 交通!G:G, "新目标") + COUNTIFS(交通!F:F, "十一五", 交通!G:G, "强化或放宽目标（气候影响不明确）") + COUNTIFS(交通!F:F, "十一五", 交通!G:G, "强化或放宽目标（积极气候影响）") + COUNTIFS(交通!F:F, "十一五", 交通!G:G, "强化或放宽目标（消极气候影响）") + COUNTIFS('土地利用、土地利用变化和林业'!F:F, "十一五", '土地利用、土地利用变化和林业'!G:G, "新目标") + COUNTIFS('土地利用、土地利用变化和林业'!F:F, "十一五", '土地利用、土地利用变化和林业'!G:G, "强化或放宽目标（气候影响不明确）") + COUNTIFS('土地利用、土地利用变化和林业'!F:F, "十一五", '土地利用、土地利用变化和林业'!G:G, "强化或放宽目标（积极气候影响）") + COUNTIFS('土地利用、土地利用变化和林业'!F:F, "十一五", '土地利用、土地利用变化和林业'!G:G, "强化或放宽目标（消极气候影响）") + COUNTIFS(循环经济!F:F, "十一五", 循环经济!G:G, "新目标") + COUNTIFS(循环经济!F:F, "十一五", 循环经济!G:G, "强化或放宽目标（气候影响不明确）") + COUNTIFS(循环经济!F:F, "十一五", 循环经济!G:G, "强化或放宽目标（积极气候影响）") + COUNTIFS(循环经济!F:F, "十一五", 循环经济!G:G, "强化或放宽目标（消极气候影响）") + COUNTIFS(金融!F:F, "十一五", 金融!G:G, "新目标") + COUNTIFS(金融!F:F, "十一五", 金融!G:G, "强化或放宽目标（气候影响不明确）") + COUNTIFS(金融!F:F, "十一五", 金融!G:G, "强化或放宽目标（积极气候影响）") + COUNTIFS(金融!F:F, "十一五", 金融!G:G, "强化或放宽目标（消极气候影响）") | Q9: 污染控制 | R9: =COUNTIFS(温室气体排放!H:H, "污染控制", 温室气体排放!G:G, "新目标") + COUNTIFS(温室气体排放!H:H, "污染控制", 温室气体排放!G:G, "强化或放宽目标（气候影响不明确）") + COUNTIFS(温室气体排放!H:H, "污染控制", 温室气体排放!G:G, "强化或放宽目标（积极气候影响）") + COUNTIFS(温室气体排放!H:H, "污染控制", 温室气体排放!G:G, "强化或放宽目标（消极气候影响）") + COUNTIFS(污染!H:H, "污染控制", 污染!G:G, "新目标") + COUNTIFS(污染!H:H, "污染控制", 污染!G:G, "强化或放宽目标（气候影响不明确）") + COUNTIFS(污染!H:H, "污染控制", 污染!G:G, "强化或放宽目标（积极气候影响）") + COUNTIFS(污染!H:H, "污染控制", 污染!G:G, "强化或放宽目标（消极气候影响）") + COUNTIFS('能源|电力'!H:H, "污染控制", '能源|电力'!G:G, "新目标") + COUNTIFS('能源|电力'!H:H, "污染控制", '能源|电力'!G:G, "强化或放宽目标（气候影响不明确）") + COUNTIFS('能源|电力'!H:H, "污染控制", '能源|电力'!G:G, "强化或放宽目标（积极气候影响）") + COUNTIFS('能源|电力'!H:H, "污染控制", '能源|电力'!G:G, "强化或放宽目标（消极气候影响）") + COUNTIFS(工业!H:H, "污染控制", 工业!G:G, "新目标") + COUNTIFS(工业!H:H, "污染控制", 工业!G:G, "强化或放宽目标（气候影响不明确）") + COUNTIFS(工业!H:H, "污染控制", 工业!G:G, "强化或放宽目标（积极气候影响）") + COUNTIFS(工业!H:H, "污染控制", 工业!G:G, "强化或放宽目标（消极气候影响）") + COUNTIFS(建筑!H:H, "污染控制", 建筑!G:G, "新目标") + COUNTIFS(建筑!H:H, "污染控制", 建筑!G:G, "强化或放宽目标（气候影响不明确）") + COUNTIFS(建筑!H:H, "污染控制", 建筑!G:G, "强化或放宽目标（积极气候影响）") + COUNTIFS(建筑!H:H, "污染控制", 建筑!G:G, "强化或放宽目标（消极气候影响）") + COUNTIFS(交通!H:H, "污染控制", 交通!G:G, "新目标") + COUNTIFS(交通!H:H, "污染控制", 交通!G:G, "强化或放宽目标（气候影响不明确）") + COUNTIFS(交通!H:H, "污染控制", 交通!G:G, "强化或放宽目标（积极气候影响）") + COUNTIFS(交通!H:H, "污染控制", 交通!G:G, "强化或放宽目标（消极气候影响）") + COUNTIFS('土地利用、土地利用变化和林业'!H:H, "污染控制", '土地利用、土地利用变化和林业'!G:G, "新目标") + COUNTIFS('土地利用、土地利用变化和林业'!H:H, "污染控制", '土地利用、土地利用变化和林业'!G:G, "强化或放宽目标（气候影响不明确）") + COUNTIFS('土地利用、土地利用变化和林业'!H:H, "污染控制", '土地利用、土地利用变化和林业'!G:G, "强化或放宽目标（积极气候影响）") + COUNTIFS('土地利用、土地利用变化和林业'!H:H, "污染控制", '土地利用、土地利用变化和林业'!G:G, "强化或放宽目标（消极气候影响）") + COUNTIFS(循环经济!H:H, "污染控制", 循环经济!G:G, "新目标") + COUNTIFS(循环经济!H:H, "污染控制", 循环经济!G:G, "强化或放宽目标（气候影响不明确）") + COUNTIFS(循环经济!H:H, "污染控制", 循环经济!G:G, "强化或放宽目标（积极气候影响）") + COUNTIFS(循环经济!H:H, "污染控制", 循环经济!G:G, "强化或放宽目标（消极气候影响）") + COUNTIFS(金融!H:H, "污染控制", 金融!G:G, "新目标") + COUNTIFS(金融!H:H, "污染控制", 金融!G:G, "强化或放宽目标（气候影响不明确）") + COUNTIFS(金融!H:H, "污染控制", 金融!G:G, "强化或放宽目标（积极气候影响）") + COUNTIFS(金融!H:H, "污染控制", 金融!G:G, "强化或放宽目标（消极气候影响）") | T9: 全社会经济 | U9: =COUNTIFS(温室气体排放!I:I,"全社会经济",温室气体排放!G:G,"新目标") +COUNTIFS(温室气体排放!I:I,"全社会经济",温室气体排放!G:G,"强化或放宽目标（气候影响不明确）") +COUNTIFS(温室气体排放!I:I,"全社会经济",温室气体排放!G:G,"强化或放宽目标（积极气候影响）") +COUNTIFS(温室气体排放!I:I,"全社会经济",温室气体排放!G:G,"强化或放宽目标（消极气候影响）") +COUNTIFS(污染!I:I,"全社会经济",污染!G:G,"新目标") +COUNTIFS(污染!I:I,"全社会经济",污染!G:G,"强化或放宽目标（气候影响不明确）") +COUNTIFS(污染!I:I,"全社会经济",污染!G:G,"强化或放宽目标（积极气候影响）") +COUNTIFS(污染!I:I,"全社会经济",污染!G:G,"强化或放宽目标（消极气候影响）") +COUNTIFS('能源|电力'!I:I,"全社会经济",'能源|电力'!G:G,"新目标") +COUNTIFS('能源|电力'!I:I,"全社会经济",'能源|电力'!G:G,"强化或放宽目标（气候影响不明确）") +COUNTIFS('能源|电力'!I:I,"全社会经济",'能源|电力'!G:G,"强化或放宽目标（积极气候影响）") +COUNTIFS('能源|电力'!I:I,"全社会经济",'能源|电力'!G:G,"强化或放宽目标（消极气候影响）") +COUNTIFS(工业!I:I,"全社会经济",工业!G:G,"新目标") +COUNTIFS(工业!I:I,"全社会经济",工业!G:G,"强化或放宽目标（气候影响不明确）") +COUNTIFS(工业!I:I,"全社会经济",工业!G:G,"强化或放宽目标（积极气候影响）") +COUNTIFS(工业!I:I,"全社会经济",工业!G:G,"强化或放宽目标（消极气候影响）") +COUNTIFS(建筑!I:I,"全社会经济",建筑!G:G,"新目标") +COUNTIFS(建筑!I:I,"全社会经济",建筑!G:G,"强化或放宽目标（气候影响不明确）") +COUNTIFS(建筑!I:I,"全社会经济",建筑!G:G,"强化或放宽目标（积极气候影响）") +COUNTIFS(建筑!I:I,"全社会经济",建筑!G:G,"强化或放宽目标（消极气候影响）") +COUNTIFS(交通!I:I,"全社会经济",交通!G:G,"新目标") +COUNTIFS(交通!I:I,"全社会经济",交通!G:G,"强化或放宽目标（气候影响不明确）") +COUNTIFS(交通!I:I,"全社会经济",交通!G:G,"强化或放宽目标（积极气候影响）") +COUNTIFS(交通!I:I,"全社会经济",交通!G:G,"强化或放宽目标（消极气候影响）") +COUNTIFS('土地利用、土地利用变化和林业'!I:I,"全社会经济",'土地利用、土地利用变化和林业'!G:G,"新目标") +COUNTIFS('土地利用、土地利用变化和林业'!I:I,"全社会经济",'土地利用、土地利用变化和林业'!G:G,"强化或放宽目标（气候影响不明确）") +COUNTIFS('土地利用、土地利用变化和林业'!I:I,"全社会经济",'土地利用、土地利用变化和林业'!G:G,"强化或放宽目标（积极气候影响）") +COUNTIFS('土地利用、土地利用变化和林业'!I:I,"全社会经济",'土地利用、土地利用变化和林业'!G:G,"强化或放宽目标（消极气候影响）") +COUNTIFS(循环经济!I:I,"全社会经济",循环经济!G:G,"新目标") +COUNTIFS(循环经济!I:I,"全社会经济",循环经济!G:G,"强化或放宽目标（气候影响不明确）") +COUNTIFS(循环经济!I:I,"全社会经济",循环经济!G:G,"强化或放宽目标（积极气候影响）") +COUNTIFS(循环经济!I:I,"全社会经济",循环经济!G:G,"强化或放宽目标（消极气候影响）") +COUNTIFS(金融!I:I,"全社会经济",金融!G:G,"新目标") +COUNTIFS(金融!I:I,"全社会经济",金融!G:G,"强化或放宽目标（气候影响不明确）") +COUNTIFS(金融!I:I,"全社会经济",金融!G:G,"强化或放宽目标（积极气候影响）") +COUNTIFS(金融!I:I,"全社会经济",金融!G:G,"强化或放宽目标（消极气候影响）")
B10: 建筑 | C10: =COUNTIFS(建筑!G:G, "新目标") + COUNTIFS(建筑!G:G, "强化或放宽目标（气候影响不明确）") + COUNTIFS(建筑!G:G, "强化或放宽目标（积极气候影响）") + COUNTIFS(建筑!G:G, "强化或放宽目标（消极气候影响）") | E10: 化石燃料储量 | F10: =COUNTIFS('能源|电力'!M:M, "化石燃料储量") | K10: 2008 | L10: =COUNTIFS(温室气体排放!A:A, 2008, 温室气体排放!G:G, "新目标") + COUNTIFS(温室气体排放!A:A, 2008, 温室气体排放!G:G, "强化或放宽目标（气候影响不明确）") + COUNTIFS(温室气体排放!A:A, 2008, 温室气体排放!G:G, "强化或放宽目标（积极气候影响）") + COUNTIFS(温室气体排放!A:A, 2008, 温室气体排放!G:G, "强化或放宽目标（消极气候影响）") + COUNTIFS(污染!A:A, 2008, 污染!G:G, "新目标") + COUNTIFS(污染!A:A, 2008, 污染!G:G, "强化或放宽目标（气候影响不明确）") + COUNTIFS(污染!A:A, 2008, 污染!G:G, "强化或放宽目标（积极气候影响）") + COUNTIFS(污染!A:A, 2008, 污染!G:G, "强化或放宽目标（消极气候影响）") + COUNTIFS('能源|电力'!A:A, 2008, '能源|电力'!G:G, "新目标") + COUNTIFS('能源|电力'!A:A, 2008, '能源|电力'!G:G, "强化或放宽目标（气候影响不明确）") + COUNTIFS('能源|电力'!A:A, 2008, '能源|电力'!G:G, "强化或放宽目标（积极气候影响）") + COUNTIFS('能源|电力'!A:A, 2008, '能源|电力'!G:G, "强化或放宽目标（消极气候影响）") + COUNTIFS(工业!A:A, 2008, 工业!G:G, "新目标") + COUNTIFS(工业!A:A, 2008, 工业!G:G, "强化或放宽目标（气候影响不明确）") + COUNTIFS(工业!A:A, 2008, 工业!G:G, "强化或放宽目标（积极气候影响）") + COUNTIFS(工业!A:A, 2008, 工业!G:G, "强化或放宽目标（消极气候影响）") + COUNTIFS(建筑!A:A, 2008, 建筑!G:G, "新目标") + COUNTIFS(建筑!A:A, 2008, 建筑!G:G, "强化或放宽目标（气候影响不明确）") + COUNTIFS(建筑!A:A, 2008, 建筑!G:G, "强化或放宽目标（积极气候影响）") + COUNTIFS(建筑!A:A, 2008, 建筑!G:G, "强化或放宽目标（消极气候影响）") + COUNTIFS(交通!A:A, 2008, 交通!G:G, "新目标") + COUNTIFS(交通!A:A, 2008, 交通!G:G, "强化或放宽目标（气候影响不明确）") + COUNTIFS(交通!A:A, 2008, 交通!G:G, "强化或放宽目标（积极气候影响）") + COUNTIFS(交通!A:A, 2008, 交通!G:G, "强化或放宽目标（消极气候影响）") + COUNTIFS('土地利用、土地利用变化和林业'!A:A, 2008, '土地利用、土地利用变化和林业'!G:G, "新目标") + COUNTIFS('土地利用、土地利用变化和林业'!A:A, 2008, '土地利用、土地利用变化和林业'!G:G, "强化或放宽目标（气候影响不明确）") + COUNTIFS('土地利用、土地利用变化和林业'!A:A, 2008, '土地利用、土地利用变化和林业'!G:G, "强化或放宽目标（积极气候影响）") + COUNTIFS('土地利用、土地利用变化和林业'!A:A, 2008, '土地利用、土地利用变化和林业'!G:G, "强化或放宽目标（消极气候影响）") + COUNTIFS(循环经济!A:A, 2008, 循环经济!G:G, "新目标") + COUNTIFS(循环经济!A:A, 2008, 循环经济!G:G, "强化或放宽目标（气候影响不明确）") + COUNTIFS(循环经济!A:A, 2008, 循环经济!G:G, "强化或放宽目标（积极气候影响）") + COUNTIFS(循环经济!A:A, 2008, 循环经济!G:G, "强化或放宽目标（消极气候影响）") + COUNTIFS(金融!A:A, 2008, 金融!G:G, "新目标") + COUNTIFS(金融!A:A, 2008, 金融!G:G, "强化或放宽目标（气候影响不明确）") + COUNTIFS(金融!A:A, 2008, 金融!G:G, "强化或放宽目标（积极气候影响）") + COUNTIFS(金融!A:A, 2008, 金融!G:G, "强化或放宽目标（消极气候影响）") | N10: 2011 | O10: =COUNTIFS(温室气体排放!F:F, 2011, 温室气体排放!G:G, "新目标") + COUNTIFS(温室气体排放!F:F, 2011, 温室气体排放!G:G, "强化或放宽目标（气候影响不明确）") + COUNTIFS(温室气体排放!F:F, 2011, 温室气体排放!G:G, "强化或放宽目标（积极气候影响）") + COUNTIFS(温室气体排放!F:F, 2011, 温室气体排放!G:G, "强化或放宽目标（消极气候影响）") + COUNTIFS(污染!F:F, 2011, 污染!G:G, "新目标") + COUNTIFS(污染!F:F, 2011, 污染!G:G, "强化或放宽目标（气候影响不明确）") + COUNTIFS(污染!F:F, 2011, 污染!G:G, "强化或放宽目标（积极气候影响）") + COUNTIFS(污染!F:F, 2011, 污染!G:G, "强化或放宽目标（消极气候影响）") + COUNTIFS('能源|电力'!F:F, 2011, '能源|电力'!G:G, "新目标") + COUNTIFS('能源|电力'!F:F, 2011, '能源|电力'!G:G, "强化或放宽目标（气候影响不明确）") + COUNTIFS('能源|电力'!F:F, 2011, '能源|电力'!G:G, "强化或放宽目标（积极气候影响）") + COUNTIFS('能源|电力'!F:F, 2011, '能源|电力'!G:G, "强化或放宽目标（消极气候影响）") + COUNTIFS(工业!F:F, 2011, 工业!G:G, "新目标") + COUNTIFS(工业!F:F, 2011, 工业!G:G, "强化或放宽目标（气候影响不明确）") + COUNTIFS(工业!F:F, 2011, 工业!G:G, "强化或放宽目标（积极气候影响）") + COUNTIFS(工业!F:F, 2011, 工业!G:G, "强化或放宽目标（消极气候影响）") + COUNTIFS(建筑!F:F, 2011, 建筑!G:G, "新目标") + COUNTIFS(建筑!F:F, 2011, 建筑!G:G, "强化或放宽目标（气候影响不明确）") + COUNTIFS(建筑!F:F, 2011, 建筑!G:G, "强化或放宽目标（积极气候影响）") + COUNTIFS(建筑!F:F, 2011, 建筑!G:G, "强化或放宽目标（消极气候影响）") + COUNTIFS(交通!F:F, 2011, 交通!G:G, "新目标") + COUNTIFS(交通!F:F, 2011, 交通!G:G, "强化或放宽目标（气候影响不明确）") + COUNTIFS(交通!F:F, 2011, 交通!G:G, "强化或放宽目标（积极气候影响）") + COUNTIFS(交通!F:F, 2011, 交通!G:G, "强化或放宽目标（消极气候影响）") + COUNTIFS('土地利用、土地利用变化和林业'!F:F, 2011, '土地利用、土地利用变化和林业'!G:G, "新目标") + COUNTIFS('土地利用、土地利用变化和林业'!F:F, 2011, '土地利用、土地利用变化和林业'!G:G, "强化或放宽目标（气候影响不明确）") + COUNTIFS('土地利用、土地利用变化和林业'!F:F, 2011, '土地利用、土地利用变化和林业'!G:G, "强化或放宽目标（积极气候影响）") + COUNTIFS('土地利用、土地利用变化和林业'!F:F, 2011, '土地利用、土地利用变化和林业'!G:G, "强化或放宽目标（消极气候影响）") + COUNTIFS(循环经济!F:F, 2011, 循环经济!G:G, "新目标") + COUNTIFS(循环经济!F:F, 2011, 循环经济!G:G, "强化或放宽目标（气候影响不明确）") + COUNTIFS(循环经济!F:F, 2011, 循环经济!G:G, "强化或放宽目标（积极气候影响）") + COUNTIFS(循环经济!F:F, 2011, 循环经济!G:G, "强化或放宽目标（消极气候影响）") + COUNTIFS(金融!F:F, 2011, 金融!G:G, "新目标") + COUNTIFS(金融!F:F, 2011, 金融!G:G, "强化或放宽目标（气候影响不明确）") + COUNTIFS(金融!F:F, 2011, 金融!G:G, "强化或放宽目标（积极气候影响）") + COUNTIFS(金融!F:F, 2011, 金融!G:G, "强化或放宽目标（消极气候影响）") | Q10: 节能 | R10: =COUNTIFS(温室气体排放!H:H, "节能", 温室气体排放!G:G, "新目标") + COUNTIFS(温室气体排放!H:H, "节能", 温室气体排放!G:G, "强化或放宽目标（气候影响不明确）") + COUNTIFS(温室气体排放!H:H, "节能", 温室气体排放!G:G, "强化或放宽目标（积极气候影响）") + COUNTIFS(温室气体排放!H:H, "节能", 温室气体排放!G:G, "强化或放宽目标（消极气候影响）") + COUNTIFS(污染!H:H, "节能", 污染!G:G, "新目标") + COUNTIFS(污染!H:H, "节能", 污染!G:G, "强化或放宽目标（气候影响不明确）") + COUNTIFS(污染!H:H, "节能", 污染!G:G, "强化或放宽目标（积极气候影响）") + COUNTIFS(污染!H:H, "节能", 污染!G:G, "强化或放宽目标（消极气候影响）") + COUNTIFS('能源|电力'!H:H, "节能", '能源|电力'!G:G, "新目标") + COUNTIFS('能源|电力'!H:H, "节能", '能源|电力'!G:G, "强化或放宽目标（气候影响不明确）") + COUNTIFS('能源|电力'!H:H, "节能", '能源|电力'!G:G, "强化或放宽目标（积极气候影响）") + COUNTIFS('能源|电力'!H:H, "节能", '能源|电力'!G:G, "强化或放宽目标（消极气候影响）") + COUNTIFS(工业!H:H, "节能", 工业!G:G, "新目标") + COUNTIFS(工业!H:H, "节能", 工业!G:G, "强化或放宽目标（气候影响不明确）") + COUNTIFS(工业!H:H, "节能", 工业!G:G, "强化或放宽目标（积极气候影响）") + COUNTIFS(工业!H:H, "节能", 工业!G:G, "强化或放宽目标（消极气候影响）") + COUNTIFS(建筑!H:H, "节能", 建筑!G:G, "新目标") + COUNTIFS(建筑!H:H, "节能", 建筑!G:G, "强化或放宽目标（气候影响不明确）") + COUNTIFS(建筑!H:H, "节能", 建筑!G:G, "强化或放宽目标（积极气候影响）") + COUNTIFS(建筑!H:H, "节能", 建筑!G:G, "强化或放宽目标（消极气候影响）") + COUNTIFS(交通!H:H, "节能", 交通!G:G, "新目标") + COUNTIFS(交通!H:H, "节能", 交通!G:G, "强化或放宽目标（气候影响不明确）") + COUNTIFS(交通!H:H, "节能", 交通!G:G, "强化或放宽目标（积极气候影响）") + COUNTIFS(交通!H:H, "节能", 交通!G:G, "强化或放宽目标（消极气候影响）") + COUNTIFS('土地利用、土地利用变化和林业'!H:H, "节能", '土地利用、土地利用变化和林业'!G:G, "新目标") + COUNTIFS('土地利用、土地利用变化和林业'!H:H, "节能", '土地利用、土地利用变化和林业'!G:G, "强化或放宽目标（气候影响不明确）") + COUNTIFS('土地利用、土地利用变化和林业'!H:H, "节能", '土地利用、土地利用变化和林业'!G:G, "强化或放宽目标（积极气候影响）") + COUNTIFS('土地利用、土地利用变化和林业'!H:H, "节能", '土地利用、土地利用变化和林业'!G:G, "强化或放宽目标（消极气候影响）") + COUNTIFS(循环经济!H:H, "节能", 循环经济!G:G, "新目标") + COUNTIFS(循环经济!H:H, "节能", 循环经济!G:G, "强化或放宽目标（气候影响不明确）") + COUNTIFS(循环经济!H:H, "节能", 循环经济!G:G, "强化或放宽目标（积极气候影响）") + COUNTIFS(循环经济!H:H, "节能", 循环经济!G:G, "强化或放宽目标（消极气候影响）") + COUNTIFS(金融!H:H, "节能", 金融!G:G, "新目标") + COUNTIFS(金融!H:H, "节能", 金融!G:G, "强化或放宽目标（气候影响不明确）") + COUNTIFS(金融!H:H, "节能", 金融!G:G, "强化或放宽目标（积极气候影响）") + COUNTIFS(金融!H:H, "节能", 金融!G:G, "强化或放宽目标（消极气候影响）") | T10: 不明确 | U10: =COUNTIFS(温室气体排放!I:I,"不明确",温室气体排放!G:G,"新目标") +COUNTIFS(温室气体排放!I:I,"不明确",温室气体排放!G:G,"强化或放宽目标（气候影响不明确）") +COUNTIFS(温室气体排放!I:I,"不明确",温室气体排放!G:G,"强化或放宽目标（积极气候影响）") +COUNTIFS(温室气体排放!I:I,"不明确",温室气体排放!G:G,"强化或放宽目标（消极气候影响）") +COUNTIFS(污染!I:I,"不明确",污染!G:G,"新目标") +COUNTIFS(污染!I:I,"不明确",污染!G:G,"强化或放宽目标（气候影响不明确）") +COUNTIFS(污染!I:I,"不明确",污染!G:G,"强化或放宽目标（积极气候影响）") +COUNTIFS(污染!I:I,"不明确",污染!G:G,"强化或放宽目标（消极气候影响）") +COUNTIFS('能源|电力'!I:I,"不明确",'能源|电力'!G:G,"新目标") +COUNTIFS('能源|电力'!I:I,"不明确",'能源|电力'!G:G,"强化或放宽目标（气候影响不明确）") +COUNTIFS('能源|电力'!I:I,"不明确",'能源|电力'!G:G,"强化或放宽目标（积极气候影响）") +COUNTIFS('能源|电力'!I:I,"不明确",'能源|电力'!G:G,"强化或放宽目标（消极气候影响）") +COUNTIFS(工业!I:I,"不明确",工业!G:G,"新目标") +COUNTIFS(工业!I:I,"不明确",工业!G:G,"强化或放宽目标（气候影响不明确）") +COUNTIFS(工业!I:I,"不明确",工业!G:G,"强化或放宽目标（积极气候影响）") +COUNTIFS(工业!I:I,"不明确",工业!G:G,"强化或放宽目标（消极气候影响）") +COUNTIFS(建筑!I:I,"不明确",建筑!G:G,"新目标") +COUNTIFS(建筑!I:I,"不明确",建筑!G:G,"强化或放宽目标（气候影响不明确）") +COUNTIFS(建筑!I:I,"不明确",建筑!G:G,"强化或放宽目标（积极气候影响）") +COUNTIFS(建筑!I:I,"不明确",建筑!G:G,"强化或放宽目标（消极气候影响）") +COUNTIFS(交通!I:I,"不明确",交通!G:G,"新目标") +COUNTIFS(交通!I:I,"不明确",交通!G:G,"强化或放宽目标（气候影响不明确）") +COUNTIFS(交通!I:I,"不明确",交通!G:G,"强化或放宽目标（积极气候影响）") +COUNTIFS(交通!I:I,"不明确",交通!G:G,"强化或放宽目标（消极气候影响）") +COUNTIFS('土地利用、土地利用变化和林业'!I:I,"不明确",'土地利用、土地利用变化和林业'!G:G,"新目标") +COUNTIFS('土地利用、土地利用变化和林业'!I:I,"不明确",'土地利用、土地利用变化和林业'!G:G,"强化或放宽目标（气候影响不明确）") +COUNTIFS('土地利用、土地利用变化和林业'!I:I,"不明确",'土地利用、土地利用变化和林业'!G:G,"强化或放宽目标（积极气候影响）") +COUNTIFS('土地利用、土地利用变化和林业'!I:I,"不明确",'土地利用、土地利用变化和林业'!G:G,"强化或放宽目标（消极气候影响）") +COUNTIFS(循环经济!I:I,"不明确",循环经济!G:G,"新目标") +COUNTIFS(循环经济!I:I,"不明确",循环经济!G:G,"强化或放宽目标（气候影响不明确）") +COUNTIFS(循环经济!I:I,"不明确",循环经济!G:G,"强化或放宽目标（积极气候影响）") +COUNTIFS(循环经济!I:I,"不明确",循环经济!G:G,"强化或放宽目标（消极气候影响）") +COUNTIFS(金融!I:I,"不明确",金融!G:G,"新目标") +COUNTIFS(金融!I:I,"不明确",金融!G:G,"强化或放宽目标（气候影响不明确）") +COUNTIFS(金融!I:I,"不明确",金融!G:G,"强化或放宽目标（积极气候影响）") +COUNTIFS(金融!I:I,"不明确",金融!G:G,"强化或放宽目标（消极气候影响）")
B11: 交通 | C11: =COUNTIFS(交通!G:G, "新目标") + COUNTIFS(交通!G:G, "强化或放宽目标（气候影响不明确）") + COUNTIFS(交通!G:G, "强化或放宽目标（积极气候影响）") + COUNTIFS(交通!G:G, "强化或放宽目标（消极气候影响）") | E11: 其他 | F11: =COUNTIFS('能源|电力'!M:M, "其他") | K11: 2009 | L11: =COUNTIFS(温室气体排放!A:A, 2009, 温室气体排放!G:G, "新目标") + COUNTIFS(温室气体排放!A:A, 2009, 温室气体排放!G:G, "强化或放宽目标（气候影响不明确）") + COUNTIFS(温室气体排放!A:A, 2009, 温室气体排放!G:G, "强化或放宽目标（积极气候影响）") + COUNTIFS(温室气体排放!A:A, 2009, 温室气体排放!G:G, "强化或放宽目标（消极气候影响）") + COUNTIFS(污染!A:A, 2009, 污染!G:G, "新目标") + COUNTIFS(污染!A:A, 2009, 污染!G:G, "强化或放宽目标（气候影响不明确）") + COUNTIFS(污染!A:A, 2009, 污染!G:G, "强化或放宽目标（积极气候影响）") + COUNTIFS(污染!A:A, 2009, 污染!G:G, "强化或放宽目标（消极气候影响）") + COUNTIFS('能源|电力'!A:A, 2009, '能源|电力'!G:G, "新目标") + COUNTIFS('能源|电力'!A:A, 2009, '能源|电力'!G:G, "强化或放宽目标（气候影响不明确）") + COUNTIFS('能源|电力'!A:A, 2009, '能源|电力'!G:G, "强化或放宽目标（积极气候影响）") + COUNTIFS('能源|电力'!A:A, 2009, '能源|电力'!G:G, "强化或放宽目标（消极气候影响）") + COUNTIFS(工业!A:A, 2009, 工业!G:G, "新目标") + COUNTIFS(工业!A:A, 2009, 工业!G:G, "强化或放宽目标（气候影响不明确）") + COUNTIFS(工业!A:A, 2009, 工业!G:G, "强化或放宽目标（积极气候影响）") + COUNTIFS(工业!A:A, 2009, 工业!G:G, "强化或放宽目标（消极气候影响）") + COUNTIFS(建筑!A:A, 2009, 建筑!G:G, "新目标") + COUNTIFS(建筑!A:A, 2009, 建筑!G:G, "强化或放宽目标（气候影响不明确）") + COUNTIFS(建筑!A:A, 2009, 建筑!G:G, "强化或放宽目标（积极气候影响）") + COUNTIFS(建筑!A:A, 2009, 建筑!G:G, "强化或放宽目标（消极气候影响）") + COUNTIFS(交通!A:A, 2009, 交通!G:G, "新目标") + COUNTIFS(交通!A:A, 2009, 交通!G:G, "强化或放宽目标（气候影响不明确）") + COUNTIFS(交通!A:A, 2009, 交通!G:G, "强化或放宽目标（积极气候影响）") + COUNTIFS(交通!A:A, 2009, 交通!G:G, "强化或放宽目标（消极气候影响）") + COUNTIFS('土地利用、土地利用变化和林业'!A:A, 2009, '土地利用、土地利用变化和林业'!G:G, "新目标") + COUNTIFS('土地利用、土地利用变化和林业'!A:A, 2009, '土地利用、土地利用变化和林业'!G:G, "强化或放宽目标（气候影响不明确）") + COUNTIFS('土地利用、土地利用变化和林业'!A:A, 2009, '土地利用、土地利用变化和林业'!G:G, "强化或放宽目标（积极气候影响）") + COUNTIFS('土地利用、土地利用变化和林业'!A:A, 2009, '土地利用、土地利用变化和林业'!G:G, "强化或放宽目标（消极气候影响）") + COUNTIFS(循环经济!A:A, 2009, 循环经济!G:G, "新目标") + COUNTIFS(循环经济!A:A, 2009, 循环经济!G:G, "强化或放宽目标（气候影响不明确）") + COUNTIFS(循环经济!A:A, 2009, 循环经济!G:G, "强化或放宽目标（积极气候影响）") + COUNTIFS(循环经济!A:A, 2009, 循环经济!G:G, "强化或放宽目标（消极气候影响）") + COUNTIFS(金融!A:A, 2009, 金融!G:G, "新目标") + COUNTIFS(金融!A:A, 2009, 金融!G:G, "强化或放宽目标（气候影响不明确）") + COUNTIFS(金融!A:A, 2009, 金融!G:G, "强化或放宽目标（积极气候影响）") + COUNTIFS(金融!A:A, 2009, 金融!G:G, "强化或放宽目标（消极气候影响）") | N11: 2014 | O11: =COUNTIFS(温室气体排放!F:F, 2014, 温室气体排放!G:G, "新目标") + COUNTIFS(温室气体排放!F:F, 2014, 温室气体排放!G:G, "强化或放宽目标（气候影响不明确）") + COUNTIFS(温室气体排放!F:F, 2014, 温室气体排放!G:G, "强化或放宽目标（积极气候影响）") + COUNTIFS(温室气体排放!F:F, 2014, 温室气体排放!G:G, "强化或放宽目标（消极气候影响）") + COUNTIFS(污染!F:F, 2014, 污染!G:G, "新目标") + COUNTIFS(污染!F:F, 2014, 污染!G:G, "强化或放宽目标（气候影响不明确）") + COUNTIFS(污染!F:F, 2014, 污染!G:G, "强化或放宽目标（积极气候影响）") + COUNTIFS(污染!F:F, 2014, 污染!G:G, "强化或放宽目标（消极气候影响）") + COUNTIFS('能源|电力'!F:F, 2014, '能源|电力'!G:G, "新目标") + COUNTIFS('能源|电力'!F:F, 2014, '能源|电力'!G:G, "强化或放宽目标（气候影响不明确）") + COUNTIFS('能源|电力'!F:F, 2014, '能源|电力'!G:G, "强化或放宽目标（积极气候影响）") + COUNTIFS('能源|电力'!F:F, 2014, '能源|电力'!G:G, "强化或放宽目标（消极气候影响）") + COUNTIFS(工业!F:F, 2014, 工业!G:G, "新目标") + COUNTIFS(工业!F:F, 2014, 工业!G:G, "强化或放宽目标（气候影响不明确）") + COUNTIFS(工业!F:F, 2014, 工业!G:G, "强化或放宽目标（积极气候影响）") + COUNTIFS(工业!F:F, 2014, 工业!G:G, "强化或放宽目标（消极气候影响）") + COUNTIFS(建筑!F:F, 2014, 建筑!G:G, "新目标") + COUNTIFS(建筑!F:F, 2014, 建筑!G:G, "强化或放宽目标（气候影响不明确）") + COUNTIFS(建筑!F:F, 2014, 建筑!G:G, "强化或放宽目标（积极气候影响）") + COUNTIFS(建筑!F:F, 2014, 建筑!G:G, "强化或放宽目标（消极气候影响）") + COUNTIFS(交通!F:F, 2014, 交通!G:G, "新目标") + COUNTIFS(交通!F:F, 2014, 交通!G:G, "强化或放宽目标（气候影响不明确）") + COUNTIFS(交通!F:F, 2014, 交通!G:G, "强化或放宽目标（积极气候影响）") + COUNTIFS(交通!F:F, 2014, 交通!G:G, "强化或放宽目标（消极气候影响）") + COUNTIFS('土地利用、土地利用变化和林业'!F:F, 2014, '土地利用、土地利用变化和林业'!G:G, "新目标") + COUNTIFS('土地利用、土地利用变化和林业'!F:F, 2014, '土地利用、土地利用变化和林业'!G:G, "强化或放宽目标（气候影响不明确）") + COUNTIFS('土地利用、土地利用变化和林业'!F:F, 2014, '土地利用、土地利用变化和林业'!G:G, "强化或放宽目标（积极气候影响）") + COUNTIFS('土地利用、土地利用变化和林业'!F:F, 2014, '土地利用、土地利用变化和林业'!G:G, "强化或放宽目标（消极气候影响）") + COUNTIFS(循环经济!F:F, 2014, 循环经济!G:G, "新目标") + COUNTIFS(循环经济!F:F, 2014, 循环经济!G:G, "强化或放宽目标（气候影响不明确）") + COUNTIFS(循环经济!F:F, 2014, 循环经济!G:G, "强化或放宽目标（积极气候影响）") + COUNTIFS(循环经济!F:F, 2014, 循环经济!G:G, "强化或放宽目标（消极气候影响）") + COUNTIFS(金融!F:F, 2014, 金融!G:G, "新目标") + COUNTIFS(金融!F:F, 2014, 金融!G:G, "强化或放宽目标（气候影响不明确）") + COUNTIFS(金融!F:F, 2014, 金融!G:G, "强化或放宽目标（积极气候影响）") + COUNTIFS(金融!F:F, 2014, 金融!G:G, "强化或放宽目标（消极气候影响）") | Q11: 能源效率 | R11: =COUNTIFS(温室气体排放!H:H, "能源效率", 温室气体排放!G:G, "新目标") + COUNTIFS(温室气体排放!H:H, "能源效率", 温室气体排放!G:G, "强化或放宽目标（气候影响不明确）") + COUNTIFS(温室气体排放!H:H, "能源效率", 温室气体排放!G:G, "强化或放宽目标（积极气候影响）") + COUNTIFS(温室气体排放!H:H, "能源效率", 温室气体排放!G:G, "强化或放宽目标（消极气候影响）") + COUNTIFS(污染!H:H, "能源效率", 污染!G:G, "新目标") + COUNTIFS(污染!H:H, "能源效率", 污染!G:G, "强化或放宽目标（气候影响不明确）") + COUNTIFS(污染!H:H, "能源效率", 污染!G:G, "强化或放宽目标（积极气候影响）") + COUNTIFS(污染!H:H, "能源效率", 污染!G:G, "强化或放宽目标（消极气候影响）") + COUNTIFS('能源|电力'!H:H, "能源效率", '能源|电力'!G:G, "新目标") + COUNTIFS('能源|电力'!H:H, "能源效率", '能源|电力'!G:G, "强化或放宽目标（气候影响不明确）") + COUNTIFS('能源|电力'!H:H, "能源效率", '能源|电力'!G:G, "强化或放宽目标（积极气候影响）") + COUNTIFS('能源|电力'!H:H, "能源效率", '能源|电力'!G:G, "强化或放宽目标（消极气候影响）") + COUNTIFS(工业!H:H, "能源效率", 工业!G:G, "新目标") + COUNTIFS(工业!H:H, "能源效率", 工业!G:G, "强化或放宽目标（气候影响不明确）") + COUNTIFS(工业!H:H, "能源效率", 工业!G:G, "强化或放宽目标（积极气候影响）") + COUNTIFS(工业!H:H, "能源效率", 工业!G:G, "强化或放宽目标（消极气候影响）") + COUNTIFS(建筑!H:H, "能源效率", 建筑!G:G, "新目标") + COUNTIFS(建筑!H:H, "能源效率", 建筑!G:G, "强化或放宽目标（气候影响不明确）") + COUNTIFS(建筑!H:H, "能源效率", 建筑!G:G, "强化或放宽目标（积极气候影响）") + COUNTIFS(建筑!H:H, "能源效率", 建筑!G:G, "强化或放宽目标（消极气候影响）") + COUNTIFS(交通!H:H, "能源效率", 交通!G:G, "新目标") + COUNTIFS(交通!H:H, "能源效率", 交通!G:G, "强化或放宽目标（气候影响不明确）") + COUNTIFS(交通!H:H, "能源效率", 交通!G:G, "强化或放宽目标（积极气候影响）") + COUNTIFS(交通!H:H, "能源效率", 交通!G:G, "强化或放宽目标（消极气候影响）") + COUNTIFS('土地利用、土地利用变化和林业'!H:H, "能源效率", '土地利用、土地利用变化和林业'!G:G, "新目标") + COUNTIFS('土地利用、土地利用变化和林业'!H:H, "能源效率", '土地利用、土地利用变化和林业'!G:G, "强化或放宽目标（气候影响不明确）") + COUNTIFS('土地利用、土地利用变化和林业'!H:H, "能源效率", '土地利用、土地利用变化和林业'!G:G, "强化或放宽目标（积极气候影响）") + COUNTIFS('土地利用、土地利用变化和林业'!H:H, "能源效率", '土地利用、土地利用变化和林业'!G:G, "强化或放宽目标（消极气候影响）") + COUNTIFS(循环经济!H:H, "能源效率", 循环经济!G:G, "新目标") + COUNTIFS(循环经济!H:H, "能源效率", 循环经济!G:G, "强化或放宽目标（气候影响不明确）") + COUNTIFS(循环经济!H:H, "能源效率", 循环经济!G:G, "强化或放宽目标（积极气候影响）") + COUNTIFS(循环经济!H:H, "能源效率", 循环经济!G:G, "强化或放宽目标（消极气候影响）") + COUNTIFS(金融!H:H, "能源效率", 金融!G:G, "新目标") + COUNTIFS(金融!H:H, "能源效率", 金融!G:G, "强化或放宽目标（气候影响不明确）") + COUNTIFS(金融!H:H, "能源效率", 金融!G:G, "强化或放宽目标（积极气候影响）") + COUNTIFS(金融!H:H, "能源效率", 金融!G:G, "强化或放宽目标（消极气候影响）")
B12: 土地利用、土地利用变化和林业 | C12: =COUNTIFS('土地利用、土地利用变化和林业'!G:G, "新目标") + COUNTIFS('土地利用、土地利用变化和林业'!G:G, "强化或放宽目标（气候影响不明确）") + COUNTIFS('土地利用、土地利用变化和林业'!G:G, "强化或放宽目标（积极气候影响）") + COUNTIFS('土地利用、土地利用变化和林业'!G:G, "强化或放宽目标（消极气候影响）") | K12: 2010 | L12: =COUNTIFS(温室气体排放!A:A, 2010, 温室气体排放!G:G, "新目标") + COUNTIFS(温室气体排放!A:A, 2010, 温室气体排放!G:G, "强化或放宽目标（气候影响不明确）") + COUNTIFS(温室气体排放!A:A, 2010, 温室气体排放!G:G, "强化或放宽目标（积极气候影响）") + COUNTIFS(温室气体排放!A:A, 2010, 温室气体排放!G:G, "强化或放宽目标（消极气候影响）") + COUNTIFS(污染!A:A, 2010, 污染!G:G, "新目标") + COUNTIFS(污染!A:A, 2010, 污染!G:G, "强化或放宽目标（气候影响不明确）") + COUNTIFS(污染!A:A, 2010, 污染!G:G, "强化或放宽目标（积极气候影响）") + COUNTIFS(污染!A:A, 2010, 污染!G:G, "强化或放宽目标（消极气候影响）") + COUNTIFS('能源|电力'!A:A, 2010, '能源|电力'!G:G, "新目标") + COUNTIFS('能源|电力'!A:A, 2010, '能源|电力'!G:G, "强化或放宽目标（气候影响不明确）") + COUNTIFS('能源|电力'!A:A, 2010, '能源|电力'!G:G, "强化或放宽目标（积极气候影响）") + COUNTIFS('能源|电力'!A:A, 2010, '能源|电力'!G:G, "强化或放宽目标（消极气候影响）") + COUNTIFS(工业!A:A, 2010, 工业!G:G, "新目标") + COUNTIFS(工业!A:A, 2010, 工业!G:G, "强化或放宽目标（气候影响不明确）") + COUNTIFS(工业!A:A, 2010, 工业!G:G, "强化或放宽目标（积极气候影响）") + COUNTIFS(工业!A:A, 2010, 工业!G:G, "强化或放宽目标（消极气候影响）") + COUNTIFS(建筑!A:A, 2010, 建筑!G:G, "新目标") + COUNTIFS(建筑!A:A, 2010, 建筑!G:G, "强化或放宽目标（气候影响不明确）") + COUNTIFS(建筑!A:A, 2010, 建筑!G:G, "强化或放宽目标（积极气候影响）") + COUNTIFS(建筑!A:A, 2010, 建筑!G:G, "强化或放宽目标（消极气候影响）") + COUNTIFS(交通!A:A, 2010, 交通!G:G, "新目标") + COUNTIFS(交通!A:A, 2010, 交通!G:G, "强化或放宽目标（气候影响不明确）") + COUNTIFS(交通!A:A, 2010, 交通!G:G, "强化或放宽目标（积极气候影响）") + COUNTIFS(交通!A:A, 2010, 交通!G:G, "强化或放宽目标（消极气候影响）") + COUNTIFS('土地利用、土地利用变化和林业'!A:A, 2010, '土地利用、土地利用变化和林业'!G:G, "新目标") + COUNTIFS('土地利用、土地利用变化和林业'!A:A, 2010, '土地利用、土地利用变化和林业'!G:G, "强化或放宽目标（气候影响不明确）") + COUNTIFS('土地利用、土地利用变化和林业'!A:A, 2010, '土地利用、土地利用变化和林业'!G:G, "强化或放宽目标（积极气候影响）") + COUNTIFS('土地利用、土地利用变化和林业'!A:A, 2010, '土地利用、土地利用变化和林业'!G:G, "强化或放宽目标（消极气候影响）") + COUNTIFS(循环经济!A:A, 2010, 循环经济!G:G, "新目标") + COUNTIFS(循环经济!A:A, 2010, 循环经济!G:G, "强化或放宽目标（气候影响不明确）") + COUNTIFS(循环经济!A:A, 2010, 循环经济!G:G, "强化或放宽目标（积极气候影响）") + COUNTIFS(循环经济!A:A, 2010, 循环经济!G:G, "强化或放宽目标（消极气候影响）") + COUNTIFS(金融!A:A, 2010, 金融!G:G, "新目标") + COUNTIFS(金融!A:A, 2010, 金融!G:G, "强化或放宽目标（气候影响不明确）") + COUNTIFS(金融!A:A, 2010, 金融!G:G, "强化或放宽目标（积极气候影响）") + COUNTIFS(金融!A:A, 2010, 金融!G:G, "强化或放宽目标（消极气候影响）") | N12: 2015 | O12: =COUNTIFS(温室气体排放!F:F, 2015, 温室气体排放!G:G, "新目标") + COUNTIFS(温室气体排放!F:F, 2015, 温室气体排放!G:G, "强化或放宽目标（气候影响不明确）") + COUNTIFS(温室气体排放!F:F, 2015, 温室气体排放!G:G, "强化或放宽目标（积极气候影响）") + COUNTIFS(温室气体排放!F:F, 2015, 温室气体排放!G:G, "强化或放宽目标（消极气候影响）") + COUNTIFS(污染!F:F, 2015, 污染!G:G, "新目标") + COUNTIFS(污染!F:F, 2015, 污染!G:G, "强化或放宽目标（气候影响不明确）") + COUNTIFS(污染!F:F, 2015, 污染!G:G, "强化或放宽目标（积极气候影响）") + COUNTIFS(污染!F:F, 2015, 污染!G:G, "强化或放宽目标（消极气候影响）") + COUNTIFS('能源|电力'!F:F, 2015, '能源|电力'!G:G, "新目标") + COUNTIFS('能源|电力'!F:F, 2015, '能源|电力'!G:G, "强化或放宽目标（气候影响不明确）") + COUNTIFS('能源|电力'!F:F, 2015, '能源|电力'!G:G, "强化或放宽目标（积极气候影响）") + COUNTIFS('能源|电力'!F:F, 2015, '能源|电力'!G:G, "强化或放宽目标（消极气候影响）") + COUNTIFS(工业!F:F, 2015, 工业!G:G, "新目标") + COUNTIFS(工业!F:F, 2015, 工业!G:G, "强化或放宽目标（气候影响不明确）") + COUNTIFS(工业!F:F, 2015, 工业!G:G, "强化或放宽目标（积极气候影响）") + COUNTIFS(工业!F:F, 2015, 工业!G:G, "强化或放宽目标（消极气候影响）") + COUNTIFS(建筑!F:F, 2015, 建筑!G:G, "新目标") + COUNTIFS(建筑!F:F, 2015, 建筑!G:G, "强化或放宽目标（气候影响不明确）") + COUNTIFS(建筑!F:F, 2015, 建筑!G:G, "强化或放宽目标（积极气候影响）") + COUNTIFS(建筑!F:F, 2015, 建筑!G:G, "强化或放宽目标（消极气候影响）") + COUNTIFS(交通!F:F, 2015, 交通!G:G, "新目标") + COUNTIFS(交通!F:F, 2015, 交通!G:G, "强化或放宽目标（气候影响不明确）") + COUNTIFS(交通!F:F, 2015, 交通!G:G, "强化或放宽目标（积极气候影响）") + COUNTIFS(交通!F:F, 2015, 交通!G:G, "强化或放宽目标（消极气候影响）") + COUNTIFS('土地利用、土地利用变化和林业'!F:F, 2015, '土地利用、土地利用变化和林业'!G:G, "新目标") + COUNTIFS('土地利用、土地利用变化和林业'!F:F, 2015, '土地利用、土地利用变化和林业'!G:G, "强化或放宽目标（气候影响不明确）") + COUNTIFS('土地利用、土地利用变化和林业'!F:F, 2015, '土地利用、土地利用变化和林业'!G:G, "强化或放宽目标（积极气候影响）") + COUNTIFS('土地利用、土地利用变化和林业'!F:F, 2015, '土地利用、土地利用变化和林业'!G:G, "强化或放宽目标（消极气候影响）") + COUNTIFS(循环经济!F:F, 2015, 循环经济!G:G, "新目标") + COUNTIFS(循环经济!F:F, 2015, 循环经济!G:G, "强化或放宽目标（气候影响不明确）") + COUNTIFS(循环经济!F:F, 2015, 循环经济!G:G, "强化或放宽目标（积极气候影响）") + COUNTIFS(循环经济!F:F, 2015, 循环经济!G:G, "强化或放宽目标（消极气候影响）") + COUNTIFS(金融!F:F, 2015, 金融!G:G, "新目标") + COUNTIFS(金融!F:F, 2015, 金融!G:G, "强化或放宽目标（气候影响不明确）") + COUNTIFS(金融!F:F, 2015, 金融!G:G, "强化或放宽目标（积极气候影响）") + COUNTIFS(金融!F:F, 2015, 金融!G:G, "强化或放宽目标（消极气候影响）") | Q12: 资源效率 | R12: =COUNTIFS(温室气体排放!H:H, "资源效率", 温室气体排放!G:G, "新目标") + COUNTIFS(温室气体排放!H:H, "资源效率", 温室气体排放!G:G, "强化或放宽目标（气候影响不明确）") + COUNTIFS(温室气体排放!H:H, "资源效率", 温室气体排放!G:G, "强化或放宽目标（积极气候影响）") + COUNTIFS(温室气体排放!H:H, "资源效率", 温室气体排放!G:G, "强化或放宽目标（消极气候影响）") + COUNTIFS(污染!H:H, "资源效率", 污染!G:G, "新目标") + COUNTIFS(污染!H:H, "资源效率", 污染!G:G, "强化或放宽目标（气候影响不明确）") + COUNTIFS(污染!H:H, "资源效率", 污染!G:G, "强化或放宽目标（积极气候影响）") + COUNTIFS(污染!H:H, "资源效率", 污染!G:G, "强化或放宽目标（消极气候影响）") + COUNTIFS('能源|电力'!H:H, "资源效率", '能源|电力'!G:G, "新目标") + COUNTIFS('能源|电力'!H:H, "资源效率", '能源|电力'!G:G, "强化或放宽目标（气候影响不明确）") + COUNTIFS('能源|电力'!H:H, "资源效率", '能源|电力'!G:G, "强化或放宽目标（积极气候影响）") + COUNTIFS('能源|电力'!H:H, "资源效率", '能源|电力'!G:G, "强化或放宽目标（消极气候影响）") + COUNTIFS(工业!H:H, "资源效率", 工业!G:G, "新目标") + COUNTIFS(工业!H:H, "资源效率", 工业!G:G, "强化或放宽目标（气候影响不明确）") + COUNTIFS(工业!H:H, "资源效率", 工业!G:G, "强化或放宽目标（积极气候影响）") + COUNTIFS(工业!H:H, "资源效率", 工业!G:G, "强化或放宽目标（消极气候影响）") + COUNTIFS(建筑!H:H, "资源效率", 建筑!G:G, "新目标") + COUNTIFS(建筑!H:H, "资源效率", 建筑!G:G, "强化或放宽目标（气候影响不明确）") + COUNTIFS(建筑!H:H, "资源效率", 建筑!G:G, "强化或放宽目标（积极气候影响）") + COUNTIFS(建筑!H:H, "资源效率", 建筑!G:G, "强化或放宽目标（消极气候影响）") + COUNTIFS(交通!H:H, "资源效率", 交通!G:G, "新目标") + COUNTIFS(交通!H:H, "资源效率", 交通!G:G, "强化或放宽目标（气候影响不明确）") + COUNTIFS(交通!H:H, "资源效率", 交通!G:G, "强化或放宽目标（积极气候影响）") + COUNTIFS(交通!H:H, "资源效率", 交通!G:G, "强化或放宽目标（消极气候影响）") + COUNTIFS('土地利用、土地利用变化和林业'!H:H, "资源效率", '土地利用、土地利用变化和林业'!G:G, "新目标") + COUNTIFS('土地利用、土地利用变化和林业'!H:H, "资源效率", '土地利用、土地利用变化和林业'!G:G, "强化或放宽目标（气候影响不明确）") + COUNTIFS('土地利用、土地利用变化和林业'!H:H, "资源效率", '土地利用、土地利用变化和林业'!G:G, "强化或放宽目标（积极气候影响）") + COUNTIFS('土地利用、土地利用变化和林业'!H:H, "资源效率", '土地利用、土地利用变化和林业'!G:G, "强化或放宽目标（消极气候影响）") + COUNTIFS(循环经济!H:H, "资源效率", 循环经济!G:G, "新目标") + COUNTIFS(循环经济!H:H, "资源效率", 循环经济!G:G, "强化或放宽目标（气候影响不明确）") + COUNTIFS(循环经济!H:H, "资源效率", 循环经济!G:G, "强化或放宽目标（积极气候影响）") + COUNTIFS(循环经济!H:H, "资源效率", 循环经济!G:G, "强化或放宽目标（消极气候影响）") + COUNTIFS(金融!H:H, "资源效率", 金融!G:G, "新目标") + COUNTIFS(金融!H:H, "资源效率", 金融!G:G, "强化或放宽目标（气候影响不明确）") + COUNTIFS(金融!H:H, "资源效率", 金融!G:G, "强化或放宽目标（积极气候影响）") + COUNTIFS(金融!H:H, "资源效率", 金融!G:G, "强化或放宽目标（消极气候影响）")
